Workbook

Sheet Summary
G5: Week Ending | H5: =TODAY() -> 45968
B8: To. | C8: RACHEL GAO, PHIL HARDIE and MALCOLM PUGH,
B9: From. | C9: MALCOLM COHEN, SABINA BATHURST, GREG HUTCHENSON and CRISTINA CIMPOESU
B10: cc. | C10: PETER MORDEN, LAURA OWEN, PERRY LINCH, HOWARD ROSEN, TOM HURLEY, SHANIE HENDERSON, CARA DYETT, CHERYL MASON, JOSEPH MANNU, WILLIAM SPENCER, ELIZABETH TAYLOR, SEAN COLLINS, RUTH SHAVE, GRAEME NOOT,
B12: Ref. | C12: New Lettings Progress
B14: Sections | G14: No. Of Deals | H14: Total Rental Value/Year
B16: A | C16: (i) New deals in solicitors hands | G16: =COUNTIFS('Letting Progress'!$D5:$D72, "NL", 'Letting Progress'!$Q5:$Q72, "No") -> 6 | H16: =SUMIFS('Letting Progress'!$I5:$I72, 'Letting Progress'!$Q5:$Q72, "no", 'Letting Progress'!$D5:$D72, "NL") -> 385381
C18: (ii) Deals in Solicitors’ Hands: Temporary Lettings | G18: =COUNTIFS('Letting Progress'!$D5:$D72, "TL", 'Letting Progress'!$Q5:$Q72, "No") -> 0 | H18: =SUMIFS('Letting Progress'!$I5:$I72, 'Letting Progress'!$Q5:$Q72, "no", 'Letting Progress'!$D5:$D72, "TL") -> 0
C20: (iii) Lease Renewals - Agreed Rental Uplift | G20: =COUNTIFS('Letting Progress'!$D5:$D72, "LR", 'Letting Progress'!$Q5:$Q72, "No") -> 6 | H20: =SUMIFS('Letting Progress'!$K5:$K72, 'Letting Progress'!$Q5:$Q72, "no", 'Letting Progress'!$D5:$D72, "LR") -> 117492
C21: TOTAL (EXCLUDING DEAD DUCKS) | G21: =SUM(G16:G20) -> 12 | H21: =SUM(H16:H20) -> 502873
B23: B | C23: (i) Deals completed this week | G23: =SUM(COUNTIF('Letting Progress'!$Q$5:$Q$14,"Yes")) -> 1 | H23: =SUM(SUMIF('Letting Progress'!$Q$5:$Q$34,"Yes",'Letting Progress'!$K$5:$K$34)) -> 335016
C25: (ii) Total deals complete 1st Jan to date
D27: New Lets | G27: =MAX(Income!$5:$5) -> 41 | H27: =Income!AX14 -> 5510541
D28: Temporary Lets | G28: =MAX(Income!$6:$6) -> 3 | H28: =Income!AX15 -> 48300
C29: Lease Renewals (Rental Uplift) | G29: =MAX(Income!$7:$7) -> 24 | H29: =Income!AX16 -> 487239.5
F30: Total | G30: =SUM(G27:G29) -> 68 | H30: =SUM(H27:H29) -> 6046080.5
C32: (iii) Dead Ducks | G32: ='Dead Ducks'!$E7 -> 0 | H32: =SUM('Dead Ducks'!$F10:$F12) -> 0
A41: Malcolm Cohen

Sheet Letting Progress
J1: LETTING PROGRESS
N2: Week Ending: | O2: =TODAY() -> 45968
A4: No. | B4: Address | C4: Floor | D4: Type of Letting | E4: Area to be Demised sq ft | F4: Date Solicitors Instructed | G4: Name of Tenant | H4: Lease Terms | I4: New Rent | J4: Existing Rent | K4: Rental Uplift | L4: Average psf (NEW) | M4: Average psf (OLD) | N4: ERV psf | O4: Solicitors for Tenant | P4: Solicitor | Q4: Completed | R4: Action | S4: Surveyor
A5: {=_xlfn.SEQUENCE(COUNTIF(B:B,"?*"))} -> 1 | B5: 9 Little Portland St | C5: Ground and Basement | D5: LR | E5: 747 | F5: 45327 | G5: Order Line Limited | H5: 4 years | I5: 45000 | J5: 45000 | K5: =I5-J5 -> 0 | L5: =I5/E5 -> 60.240964 | M5: =J5/E5 -> 60.240964 | N5: =I5/E5 -> 60.240964 | O5: Tenant acting on their behalf. | P5: SH | Q5: No | R5: Tenant lease renewal is on hold while the landlord prepares a retail strategy with KLM. Existing tenants may no longer meet the requirements under the new strategy. 26.09.25 | S5: CD
A6: 2 | B6: 56 Great Titchfield Street | C6: Whole | D6: LR | E6: 2692 | F6: 45665 | G6: Morplan Ltd | H6: 5 years from 01/02.2025 with 4 weeks rent free period | I6: 97996 | J6: 104500 | K6: =I6-J6 -> -6504 | L6: =I6/E6 -> 36.402675 | M6: =J6/E6 -> 38.818722 | N6: =I6/E6 -> 36.402675 | O6: Glovers Solicitors | P6: SH | Q6: No | R6: Tenant's AML checks have ceen ompleted. The tenant is based in France and is now awaiting confirmation that they have completed the Statutory Declaration for the 1st-3rd Floor, 58 Great Titchfield Street, before proceeding with the lease of the protected tenancies. 29/10/25b | S6: CD
A7: 3 | B7: 58 Great Titchfield Street | C7: Ground and Basement | D7: LR | E7: 1172 | F7: 45665 | G7: Morplan Ltd | H7: 5 years from 01/02.2025 with 4 weeks rent free period | I7: 43393.5 | J7: 41000 | K7: =I7-J7 -> 2393.5 | L7: =I7/E7 -> 37.025171 | M7: =J7/E7 -> 34.982935 | N7: =I7/E7 -> 37.025171 | O7: Glovers Solicitors | P7: SH | Q7: No | R7: Tenant's AML checks have completed. Tenant is based in France and now awaiting confirmation that tenant has completed the Statutory Declaration on the 1st-3rd Floor 58 Great Titchfield Street, before completing the lease of the protected tenancies. 29/10/25 | S7: CD
A8: 4 | B8: Floors, 58 Great Titchfield Street | C8: 1st 2nd & 3rd | D8: LR | E8: 1159 | F8: 45665 | G8: Morplan Ltd | H8: 5 year from 01/02.25 with 4 weeks rent free period | I8: 58610.5 | J8: 61575 | K8: =I8-J8 -> -2964.5 | L8: =I8/E8 -> 50.569888 | M8: =J8/E8 -> 53.127696 | N8: =I8/E8 -> 50.569888 | O8: Glovers Solicitors | P8: SH | Q8: No | R8: Tenant's AML checks have completed. Tenant is based in France and is now awaiting confirmation that the tenant has completed the Statutory Declaration in France. 29/10/25 | S8: CD
A9: 5 | B9: 4 Winsley Street | C9: Ground and Basement | D9: LR | E9: 7079 | F9: 45642 | G9: VNK Limited | H9: 10-year renewal from 28 Sep 2027, Rent £499,600, Rent Review 5th Year. | I9: 499600 | J9: 425033 | K9: =I9-J9 -> 74567 | L9: =I9/E9 -> 70.57494 | M9: =J9/E9 -> 60.04139 | N9: =I9/E9 -> 70.57494 | O9: Memery Crystal | P9: Wedlake Bell | Q9: No | R9: Draft documents in the agreed-upon format to reflect the existing lease. Target completion for Jan 2026. AML Passed. JM is happy with the Licence to Alter docs. Awaiting bank consent. 09/05/2025. Breach of planning application. Awaiting resolution from the tenant. The lease will be completed once the breach is rectified on 13/06/2025. The tenant has agreed to rectify the breach, and completion is expected in Q4. | S9: JM
A10: 6 | B10: 36-38 Mortimer Street, Radiant House | C10: 2nd | D10: NL | E10: 1255 | F10: 45846 | G10: Arya Douge Ltd | H10: 5 years with t/b 3rd year | I10: 74000 | J10: 0 | K10: =I10-J10 -> 74000 | L10: =I10/E10 -> 58.964143 | M10: =J10/E10 -> 0 | N10: =I10/E10 -> 58.964143 | O10: TBC | P10: SH | Q10: No | R10: Draft Documents in final form. Lease plans are being amended. Works are close to completion. 03/10/2025 | S10: WS / ET
A11: 7 | B11: Circus House | C11: 2nd & 3rd | D11: NL | E11: 4653 | F11: 45877 | G11: New Era Cap Company | H11: 10 years with t/b 5th year | I11: 335016 | J11: 0 | K11: =I11-J11 -> 335016 | L11: =I11/E11 -> 72 | M11: =J11/E11 -> 0 | N11: =I11/E11 -> 72 | O11: TBC | P11: SH | Q11: Yes | R11: Stephenson Harwood has answered all the queries raised by the tenant's solicitors and has returned all documents to them. 30/10/2025 - ET has instructed Hot Water Works, which will deliver an electrified and degassed floor, allowing EPC B to be achieved. These are likely to be completed just after the lease does, but a side letter will be required, and Stephen Laud will deal with this. Completion is expected by either Friday, 31 October, or early next week. | S11: ET
A12: 8 | B12: Circus House, 21 Great Titchfield Street | C12: Ground Floor, (West) | D12: NL | E12: 1946 | F12: 45869 | G12: Lege Aetis Ltd | H12: 15 years with t/b 10th yr on 6 months notice | I12: 118500 | J12: 0 | K12: =I12-J12 -> 118500 | L12: =I12/E12 -> 60.894142 | M12: =J12/E12 -> 0 | N12: =I12/E12 -> 60.894142 | O12: SA Law | P12: SH | Q12: No | R12: Tenant's solicitors to get back to Stephenson Harwood with their comments on the legal documents shortly. 10/10/2025: 30/10/2025 Lege Atris team undertaking surveys and investigations into how drainage provision can be delivered for use as dentists surgery. | S12: ET
A13: 9 | B13: 158 Oxford Street | C13: Ground Floor | D13: LR | E13: 1690 | F13: 45905 | G13: VF Northern Europe (T/A Timberland) | H13: 10 Years Leae. TOB Year 5. 3m RF. £615 Zone A (Gross) / £600 Zone A (Net) | I13: 550000 | J13: 500000 | K13: =I13-J13 -> 50000 | L13: =I13/E13 -> 325.44379 | M13: =J13/E13 -> 295.85799 | N13: =I13/E13 -> 325.44379 | O13: TBC | P13: SH | Q13: No | R13: SH to circulate first draft to to tenant. Lease to commence on 19 January 2026. | S13: JM
A14: 10 | B14: Golderbrock House | C14: 1st Floor (Rear) | D14: NL | E14: 533 | F14: 45904 | G14: NMHL Ltd (T/A Natalino) | H14: 5 year lease T/o break end of yr 2. | I14: 28889 | J14: 0 | K14: =I14-J14 -> 28889 | L14: =I14/E14 -> 54.20075 | M14: =J14/E14 -> 0 | N14: =I14/E14 -> 54.20075 | O14: TBC | P14: SH | Q14: No | R14: Draft documents with the other side. Tenant pack sent to SH. 03/10/2025 | S14: WS
A15: 11 | B15: 85 Mortimer Street | C15: 1st-3rd floors | D15: NL | E15: 1248 | F15: 45918 | G15: Sindhu Immigration Services | H15: 5 years with a mutail break at the end of the 3rd year | I15: 68640 | J15: 0 | K15: =I15-J15 -> 68640 | L15: =I15/E15 -> 55 | M15: =J15/E15 -> 0 | N15: =I15/E15 -> 55 | O15: TBC | P15: SH | Q15: No | R15: Fee Quote accepted, tenant pack being put together. ARES Works is now underway. 10/10/2025 Stephenson Harwood requested further details from Langham, and Elizabeth Taylor provided them over the course of the week. 30/10/2025 - each side's solicitors dealing. | S15: WS / ET
A16: 12 | B16: 53 Great Portland Street | C16: Kiosk | D16: NL | E16: 60 | F16: 45916 | G16: Mr Yogesh Brahmbhatt | H16: 5 Years With break at end of 3rd &4th Year | I16: 13500 | J16: 0 | K16: =I16-J16 -> 13500 | L16: =I16/E16 -> 225 | M16: =J16/E16 -> 0 | N16: =J16/E16 -> 0 | O16: Markand & Co Solicitors LLP | P16: SH | Q16: No | R16: Draft documents still with tenant to review. SH have chased. 15/10/2025 | S16: WS
A17: 13 | B17: 15/16 Margaret Street | C17: 3rd floor | D17: NL | E17: 1129 | F17: 45954 | G17: Termgrid Limited | H17: 5 years with tenant break 3rd year | I17: 81852 | J17: 0 | K17: =I17-J17 -> 81852 | L17: =I17/E17 -> 72.499557 | M17: =J17/E17 -> 0 | N17: 66.5 | O17: TBC | P17: SH | Q17: NO | R17: Stephenson Harwood instructed. Pack being put together. 29/10/2025 | S17: WS
A18: 14 | K18: =I18-J18 -> 0 | L18: =I18/E18 -> #DIV/0! | M18: =J18/E18 -> #DIV/0!
J19: 0 | K19: =I19-J19 -> 0 | L19: =I19/E19 -> #DIV/0! | M19: =J19/E19 -> #DIV/0!

Sheet Dead Ducks
B1: B | E1: LETTING PROGRESS
E2: Dead Ducks
G4: Week Ending | H4: =Summary!#REF! -> #REF!
B7: No. of 'dead ducks' this week: | E7: =COUNT(F10:F12) -> 0
B9: No. | C9: Address | D9: Company | E9: Lease Terms | F9: Rent | G9: Rent psf | H9: Reason | I9: Surveyor
B10: 1
B11: 2
B12: 3
B15: END
C24: Address | D24: Company | E24: Lease Terms | F24: Rent | G24: Rent psf | H24: Reason | I24: Surveyor
C25: 15/16 Margaret Street Basement 2,161sq.ft | D25: Canis (marylebone)Ltd | E25: 5 Years With M/B year 3 | F25: 55000 | G25: 25 | H25: It was felt this was not the right operator with the refurbishedunits above | I25: TH
C26: 67 Wells street, Welbeck House | D26: World Chess | E26: 5 years T/O break at end of 3yr | F26: 150000 | G26: 45 | H26: Shifting focus to online operations due to uncertain | I26: YS
C27: Great Titchfield House, 14-18 Great Titchfield Street | D27: True Green Capital | E27: 5 yr lease | F27: 135456 | G27: 68 | H27: Tenant looking t ostay put during economic uncertantiy. | I27: YS
C28: 2nd Floor, 14-18 Great Titchfield Street, | D28: Infront Sports & Media UK Ltd | E28: 3 year lease | F28: 152250 | G28: 78.56 | H28: Tenant has found alternative accomadation in a different area. | I28: YS
C29: 47-50 Margaret Street | D29: 77 Diamonds | E29: 5 years T/O break at end of 3yr | F29: 155496 | G29: 62 | H29: Tenant believed that buildin common parts were too much of security threat depsite proposed improvements | I29: SH
C30: 47-50 Margaret Street 4th Floor East | D30: Dolor Medical Supplies | E30: 5years with mutual break in year 3 | F30: 39387 | G30: 57 | H30: Isses relating to plannign change of use delayed deal too long | I30: SH

Sheet Viewing Schedule
C1: Viewing Schedule
F2: Week Ending | G2: =TODAY() -> 45968
A4: No. | B4: Date | C4: Address | D4: Floor/Suite | E4: Potential Tenant | F4: Agent/Broker | G4: Proposed Terms | H4: Remarks | I4: Agent
A5: 1 | B5: 45964 | C5: Moray House | D5: 1st floor (2 suites) | E5: Media Tech agony | F5: LEM | G5: NYD | H5: 1st inspection with London director. 2nd inspection to be arranged for US director to inspect. | I5: MAC
A6: 2 | B6: 45964 | C6: 75/77 Margaret Street | D6: entire 2nd floor Front & rear) | E6: Media Tech agency | F6: LEM | G6: NYD | H6: 1st inspection with London director. 2nd inspection to be arranged for US director to inspect. | I6: MAC
A7: 3 | B7: 45964 | C7: 30 Market Place | D7: 3rd floor | E7: Tech company | F7: ECP | G7: NYD | H7: 1st inspection. Waiting for update report from our agent. | I7: MAC
A8: 4 | B8: 45964 | C8: 15/16 Margaret Street | D8: 3rd floor | E8: Termgrid Limited | F8: RIB | G8: See letting progress | H8: Inspection by their design team | I8: MAC
A9: 5 | B9: 45964 | C9: 9 Little Portland House | D9: Ground floor & Basement | E9: Fabrique (Bakery) | F9: KLM | G9: NYD | H9: 1st Inspection. Awaiting feedback. | I9: KLM
A10: 6 | B10: 45965 | C10: 22-23 Eastcastle Street | D10: 3rd Floor (East) | E10: Media 15 | F10: N/A | G10: NYD | H10: Liked unit but didn't like the metal wall as couldn't understand what it was for and don't want to wait for works to be done. | I10: SB
A11: 7 | B11: 45965 | C11: 47-50 Margaret Street | D11: 3rd Floor (West) | E11: Media 15 | F11: N/A | G11: NYD | H11: Didn't like the unit as no kitchenette and they didn't want the hassle of having to put one in. | I11: SB
A12: 8 | B12: 45965 | C12: 51-53 Margaret Street | D12: 1st Floor (West) | E12: Media 15 | F12: N/A | G12: NYD | H12: They liked the unit a lot, but I didn't like that it had no fridge or blinds (which I mentioned we could supply if needed). | I12: SB
A13: 9 | B13: 45966 | C13: 32-36 Great Portland Street | D13: 1st Floor | E13: Orphalan UK | F13: LEM | G13: NYD | H13: 1st Inspection. Like unit but has no meeting rooms and they don't want to put them in. | I13: SB
A14: 11 | B14: 45966 | C14: 47-50 Margaret Street | D14: 3rd East | E14: Wal G | F14: LDG | G14: £63 psf /5 yr lease | H14: Several inspections. Offer made and we are running cash flows between this offer and another offer made by Binocular Productions. | I14: MAC
A15: 12 | B15: 45966 | C15: 47-50 Margaret Street | D15: 3rd Floor (East) | E15: Orphalan UK | F15: LEM | G15: NYD | H15: 1st Inspection. Really liked this unit due to it's glass partioned meeting rooms but the unit is about to go under offer to someone else. | I15: SB
B16: 45966 | C16: 19-21 Great Portland Street | D16: 3rd Floor | E16: Orphalan UK | F16: LEM | G16: NYD | H16: 1st Inspection. Liked unit and the meeting rooms. Will look at plan and come back to us. | I16: SB
B17: 45967 | C17: 51/53 Eastcastle Street | D17: Ground floor & Basement | E17: Passyunk Avenue | F17: OVH | G17: NYD | H17: 1st inspection. They appeared to like the site and felt that it would work well as a competitive socialising venue. | I17: MAC
A18: 13 | B18: 45967 | C18: Moray House | D18: 1st floor (2 suites) | E18: TGR1.618 Limited | F18: LEM | G18: NYD | H18: 1st inspection. Did not like the configuration. | I18: MAC
A19: 14 | B19: 45967 | C19: 75/77 Margaret Street | D19: entire 2nd floor Front & rear) | E19: TGR1.618 Limited | F19: LEM | G19: NYD | H19: 1st inspection. Liked the configuration and has requested further info. | I19: MAC
A20: 15 | B20: 45967 | C20: 23-25 Eastcastle Street | D20: 2nd & 3rd floors | E20: Unknown | F20: Bluebook | G20: NYD | H20: 1st Inspection. Awaiting feedback | I20: BB
A21: 16 | B21: 45967 | C21: 32-36 Great Portland Street | D21: 3rd & 4th Floors | E21: Lonic | F21: Bluebook | G21: NYD | H21: 1st Inspection. Awaiting feedback | I21: BB
A22: 17 | B22: 45967 | C22: 51 Great Portland Street | D22: 3rd Floor | E22: CLYX | F22: LEM | G22: NYD | H22: 1st Inspection. Awaiting feedback. | I22: SB
A23: 18 | B23: 45967 | C23: 53 Great Portland Street | D23: 1st Floor | E23: CLYX | F23: LEM | G23: NYD | H23: 1st Inspection. Awaiting feedback. | I23: SB
A24: 19 | B24: 45967 | C24: 53 Great Portland Street | D24: 3rd Floor | E24: CLYX | F24: LEM | G24: NYD | H24: 1st Inspection. Awaiting feedback. | I24: SB
A25: 20 | B25: 45967 | C25: 47-50 Margaret Street | D25: 3rd Floor (West) | E25: CLYX | F25: LEM | G25: NYD | H25: 1st Inspection. Awaiting feedback although clearly liked this one the best due to having a lift. Will need to look at finances. | I25: SB
A26: 21 | B26: 45967 | C26: 39 Great Portland Street | D26: Ground floor & Basement | E26: SCRT | F26: KLM | G26: NYD | H26: 1st Inspection. Awaiting feedback | I26: KLM
A27: 22 | B27: 45967 | C27: 41 Great Portland Street | D27: Whole Building | E27: SCRT | F27: KLM | G27: NYD | H27: 1st Inspection. Awaiting feedback | I27: KLM
A28: 23 | B28: 45968 | C28: 75/77 Margaret Street | D28: entire 2nd floor Front & rear) | E28: Wal G | F28: LEM | G28: NYD | H28: 1st viewing. We have blown them out the 47/50 Margaret Street =3rd floor deal to go with another party. Looking at alternative options | I28: MAC
A29: 24 | B29: 45968 | C29: 32/36 Great Portland Street | D29: 1st floor | E29: Wal G | F29: LEM | G29: NYD | H29: See above comment. | I29: MAC
... A37: 32 | B37: 45968 | C37: 42-48 Great Portland Street | D37: 5th Floor | E37: Media.Work | F37: LEM | G37: NYD | H37: 1st Inspection. Awaiting feedback | I37: SB
A38: 33
A39: 34
A40: 35
A41: 36
A42: 37
A43: 38
A44: 39
A45: 40
A46: 41
A47: 42
A48: 43
...

Sheet Income
B3: Total Number of Deals | F3: Actual | G3: Actual | H3: Actual | I3: Actual | J3: Actual | K3: Actual | L3: Actual | M3: Actual | N3: Actual | O3: Actual | P3: Actual | Q3: Actual | R3: Actual | S3: Actual | T3: Actual | U3: Actual | V3: Actual | W3: Actual | X3: Actual | Y3: Actual | Z3: Actual | AA3: Actual | AB3: Actual | AC3: Actual | AD3: Actual | AE3: Actual | AF3: Actual | AG3: Actual | AH3: Actual | AI3: Actual | AJ3: Actual | AK3: Actual | AL3: Actual | AM3: Actual | AN3: Actual | AO3: Actual | AP3: Actual | AQ3: Actual | AR3: Actual | AS3: Actual | AT3: Actual | AU3: Actual | AV3: Actual | AW3: Actual | AX3: Running
F4: 45660 | G4: =F4+7 -> 45667 | H4: =G4+7 -> 45674 | I4: =H4+7 -> 45681 | J4: =I4+7 -> 45688 | K4: =J4+7 -> 45695 | L4: =K4+7 -> 45702 | M4: =L4+7 -> 45709 | N4: =M4+7 -> 45716 | ... AK4: =AJ4+7 -> 45877 | AL4: 45884 | AM4: =AL4+7 -> 45891 | AN4: =AM4+7 -> 45898 | AO4: =AN4+7 -> 45905 | AP4: =AO4+7 -> 45912 | AQ4: =AP4+7 -> 45919 | AR4: =AQ4+7 -> 45926 | AS4: =AR4+7 -> 45933 | AT4: =AS4+7 -> 45940 | ... AX4: =AW4+7 -> 45968
B5: Permanent Lets | F5: 0 | G5: 4 | H5: 4 | I5: 5 | J5: 7 | K5: 7 | L5: 10 | M5: 12 | N5: 15 | O5: 15 | P5: 15 | Q5: 16 | R5: 17 | S5: 18 | T5: 18 | U5: 19 | V5: 20 | W5: 20 | X5: 20 | Y5: 21 | Z5: 21 | AA5: 23 | AB5: 23 | AC5: 23 | AD5: 24 | AE5: 25 | AF5: 25 | AG5: 25 | AH5: 27 | AI5: 27 | AJ5: 27 | AK5: 27 | AL5: 29 | AM5: 31 | AN5: 31 | AO5: 32 | AP5: 32 | AQ5: 34 | AR5: 34 | AS5: 34 | AT5: 35 | AU5: 35 | AV5: 36 | AW5: 40 | AX5: =AW5 + COUNTIFS('Letting Progress'!$D5:$D72, "NL", 'Letting Progress'!$Q5:$Q72, "Yes") -> 41
B6: Temporary Lets | F6: 0 | G6: 0 | H6: 0 | I6: 1 | J6: 2 | K6: 2 | L6: 2 | M6: 2 | N6: 2 | O6: 2 | P6: 2 | Q6: 2 | R6: 2 | S6: 2 | T6: 2 | U6: 2 | V6: =U6 + COUNTIFS('Letting Progress'!$D5:$D72, "TL", 'Letting Progress'!$Q5:$Q72, "Yes") -> 2 | W6: 2 | X6: 2 | Y6: 2 | Z6: 2 | AA6: 2 | AB6: 2 | AC6: 2 | AD6: 2 | AE6: 2 | AF6: 2 | AG6: 2 | AH6: 2 | AI6: 2 | AJ6: 2 | AK6: 2 | AL6: 2 | AM6: 2 | AN6: 2 | AO6: 2 | AP6: 2 | AQ6: 3 | AR6: 3 | AS6: 3 | AT6: 3 | AU6: 3 | AV6: 3 | AW6: 3 | AX6: =AW6 + COUNTIFS('Letting Progress'!$D6:$D72, "STL", 'Letting Progress'!$Q6:$Q72, "Yes") -> 3
B7: Lease Renewals (Rental Uplift) | F7: 0 | G7: 1 | H7: 2 | I7: 2 | J7: 2 | K7: 3 | L7: 4 | M7: 4 | N7: 4 | O7: 4 | P7: 4 | Q7: 4 | R7: 4 | S7: 4 | T7: 5 | U7: 8 | V7: 8 | W7: 11 | X7: 11 | Y7: 12 | Z7: 14 | AA7: 14 | AB7: 14 | AC7: 14 | AD7: 14 | AE7: 14 | AF7: 14 | AG7: 14 | AH7: 15 | AI7: 17 | AJ7: 17 | AK7: 17 | AL7: 18 | AM7: 18 | AN7: 19 | AO7: 19 | AP7: 21 | AQ7: 23 | AR7: 23 | AS7: 24 | AT7: 24 | AU7: 24 | AV7: 24 | AW7: 24 | AX7: =AW7 + COUNTIFS('Letting Progress'!$D7:$D72, "LR", 'Letting Progress'!$Q7:$Q72, "Yes") -> 24
B8: Total | F8: =SUM(F5:F7) -> 0 | G8: =SUM(G5:G7) -> 5 | H8: =SUM(H5:H7) -> 6 | I8: =SUM(I5:I7) -> 8 | J8: =SUM(J5:J7) -> 11 | K8: =SUM(K5:K7) -> 12 | L8: =SUM(L5:L7) -> 16 | M8: =SUM(M5:M7) -> 18 | ... AX8: =SUM(AX5:AX7) -> 68
B11: Total Rental Value/Year | F11: Actual | G11: Actual | H11: Actual | I11: Actual | J11: Actual | K11: Actual | L11: Actual | M11: Actual | N11: Actual | O11: Actual | P11: Actual | Q11: Actual | R11: Actual | S11: Actual | T11: Actual | U11: Actual | V11: Actual | W11: Actual | X11: Actual | Y11: Actual | Z11: Actual | AA11: Actual | AB11: Actual | AC11: Actual | AD11: Actual | AE11: Actual | AF11: Actual | AG11: Actual | AH11: Actual | AI11: Actual | AJ11: Actual | AK11: Actual | AL11: Actual | AM11: Actual | AN11: Actual | AO11: Actual | AP11: Actual | AQ11: Actual | AR11: Actual | AS11: Actual | AT11: Actual | AU11: Actual | AV11: Actual | AW11: Actual | AX11: Running
F12: 45660 | G12: =F12+7 -> 45667 | H12: =G12+7 -> 45674 | I12: =H12+7 -> 45681 | J12: =I12+7 -> 45688 | K12: =J12+7 -> 45695 | L12: =K12+7 -> 45702 | M12: =L12+7 -> 45709 | N12: =M12+7 -> 45716 | ... AK12: =AJ12+7 -> 45877 | AL12: 45884 | AM12: =AL12+7 -> 45891 | AN12: =AM12+7 -> 45898 | AO12: =AN12+7 -> 45905 | AP12: =AO12+7 -> 45912 | AQ12: =AP12+7 -> 45919 | AR12: =AQ12+7 -> 45926 | AS12: =AR12+7 -> 45933 | AT12: =AS12+7 -> 45940 | ... AX12: =AW12+7 -> 45968
B14: Permanent Lets | F14: 0 | G14: 332971 | H14: 332971 | I14: 332971 | J14: 592971 | K14: 592971 | L14: 1005040 | M14: 1725040 | N14: 2145480 | O14: 2145480 | P14: 2145480 | Q14: 2273480 | R14: 2273480 | S14: 2453480 | T14: 2453480 | U14: 2539930 | V14: 2568537 | W14: 2568537 | X14: 2568537 | Y14: 2929787 | Z14: 2929787 | AA14: 3865787 | AB14: 3865787 | AC14: 3865787 | AD14: 3920787 | AE14: 4011387 | AF14: 4011387 | AG14: 4011387 | AH14: 4295347 | AI14: 4295347 | AJ14: 4295347 | AK14: 4295347 | AL14: 4365347 | AM14: 4365347 | AN14: 4435347 | AO14: 4435347 | AP14: 4435347 | AQ14: 4519072 | AR14: 4519072 | AS14: 4519072 | AT14: 4625857 | AU14: 4625857 | AV14: 4735857 | AW14: 5175525 | AX14: =AW14 + SUMIFS('Letting Progress'!$K5:$K74, 'Letting Progress'!$D5:$D74, "NL", 'Letting Progress'!$Q5:$Q74, "Yes") -> 5510541
B15: Temporary Lets | F15: 0 | G15: 0 | H15: 0 | I15: 0 | J15: 48300 | K15: 48300 | L15: 48300 | M15: 48300 | N15: 48300 | O15: 48300 | P15: 48300 | Q15: 48300 | R15: 48300 | S15: 48300 | T15: 48300 | U15: 48300 | V15: 48300 | W15: 48300 | X15: 48300 | Y15: 48300 | Z15: 48300 | AA15: 48300 | AB15: 48300 | AC15: 48300 | AD15: 48300 | AE15: 48300 | AF15: 48300 | AG15: 48300 | AH15: 48300 | AI15: 48300 | AJ15: 48300 | AK15: 48300 | AL15: 48300 | AM15: 48300 | AN15: 48300 | AO15: 48300 | AP15: 48300 | AQ15: 48300 | AR15: 48300 | AS15: 48300 | AT15: 48300 | AU15: 48300 | AV15: 48300 | AW15: 48300 | AX15: =AW15 + SUMIFS('Letting Progress'!$K5:$K72, 'Letting Progress'!$D5:$D72, "TL", 'Letting Progress'!$Q5:$Q72, "Yes") -> 48300
B16: Lease Renewals (Rental Uplift) | F16: 0 | G16: 130000 | H16: 130000 | I16: =H16+SUMIF('Letting Progress'!$Q5:$Q14, "Yes",'Letting Progress'!$K5:$K9) -> 465016 | J16: 130000 | K16: 130000 | L16: 137848 | M16: 137848 | N16: 137848 | O16: 137848 | P16: 137848 | Q16: 137848 | R16: 137848 | S16: 137848 | T16: 138298 | U16: 139600 | V16: 139600 | W16: 153100 | X16: 153100 | Y16: 155100 | Z16: 156000 | AA16: 156000 | AB16: 156000 | AC16: 156000 | AD16: 156000 | AE16: 156000 | AF16: 156000 | AG16: 156000 | AH16: 376000 | AI16: 376000 | AJ16: 376000 | AK16: 390100 | AL16: 390100 | AM16: 390100 | AN16: 398560 | AO16: 454882 | AP16: 473402 | AQ16: 487239.5 | AR16: 487239.5 | AS16: 487239.5 | AT16: 487239.5 | AU16: 487239.5 | AV16: 487239.5 | AW16: 487239.5 | AX16: =AW16 + SUMIFS('Letting Progress'!$K5:$K77, 'Letting Progress'!$D5:$D77, "LR", 'Letting Progress'!$Q5:$Q77, "Yes") -> 487239.5
B17: Total | F17: =SUM(F14:F16) -> 0 | G17: =SUM(G14:G16) -> 462971 | H17: =SUM(H14:H16) -> 462971 | I17: =SUM(I14:I16) -> 797987 | J17: =SUM(J14:J16) -> 771271 | K17: =SUM(K14:K16) -> 771271 | L17: =SUM(L14:L16) -> 1191188 | M17: =SUM(M14:M16) -> 1911188 | ... AX17: =SUM(AX14:AX16) -> 6046080.5

Sheet Completed Deals
B2: Completed Deals
B5: New Lettings
B6: Address | C6: Address | D6: Floor | E6: Type of Letting | F6: Area to be Demised sq ft | G6: Date Solicitors Instructed | H6: Name of Tenant | I6: Lease Terms | J6: New Rent | K6: Existing Rent | L6: Rental Uplift | M6: Average psf (NEW) | N6: Average psf (OLD) | O6: ERV psf | P6: Solicitors for Tenant | Q6: Solicitor | R6: Completed | S6: Action | T6: Surveyor | U6: Actual
B7: 1 | C7: 22-25 Eastcastle Street | D7: 1st floor East 1,050 sq ft | G7: 45499 | H7: Peter Alexander UK Limited | I7: 5 years with a t/b 3rd year | J7: 61425 | K7: 55700 | L7: =J7-K7 -> 5725 | M7: 58.5 | P7: TBC | Q7: TBC | R7: Yes | S7: COMPLETED | T7: SH | U7: 45555
B8: 2 | C8: 20 Margaret Street | D8: 5th Floor 750 sq ft | G8: 45538 | H8: Moods beauty Limited | I8: 2 years | J8: 41250 | K8: 39200 | L8: =J8-K8 -> 2050 | M8: 55 | P8: Withers LLP | Q8: SH | R8: Yes | S8: COMPLETED | T8: YS | U8: 45555
B9: 3 | C9: Moray House, 23-35 Great Titchfield Street | D9: 6th floor Flat 2 bed | G9: 45541 | H9: Mr Marc Versteegh & William Alex Mikael Antell | I9: 1 year | J9: 42000 | K9: 26496 | M9: 72.41 | P9: NA | Q9: NA | R9: Yes | S9: COMPLETED | T9: CM | U9: 45548
B10: 4 | C10: 63-64 Margaret Street | D10: 1st Floor West 688 sq ft | G10: 45510 | H10: Staybrook Capital Limited | I10: 3 years t/b 2nd year | J10: 47250 | K10: 35000 | M10: 68.67 | P10: TBC | Q10: SH | R10: Yes | S10: Completed | T10: CM | U10: 45562
B11: 5 | C11: Portland House, 4 Great Portland Street | D11: Ground floor and Basement , East, 5,667 sq ft | G11: 45464 | H11: Future Maxx Limited | I11: 15 years with a landord break at the end of the 8th year for redevolpement | J11: 300000 | K11: 255000 | M11: 53 | P11: Fladgates | Q11: SH | R11: Yes | S11: Draft lease being prepared Rent agreed is yr1 £300,000 yr2 £300,000; yr3 £305,000 yr4 £310,000; yr5 £320,000 | T11: SH | U11: 45569
B12: 6 | C12: 3-4 Bywell Place | D12: Ground Floor and Basement 1,167 sq ft | G12: 45274 | H12: Solo60 Ltd | I12: 5 years with landlord break (conditional on noise complaints) | J12: 46800 | K12: 37700 | M12: 40.48 | P12: TBC | Q12: SH | R12: Yes | T12: TH | U12: 45575
B13: 7 | C13: Moray House | D13: Ground Floor (A & B) 1,452 sq ft | G13: 45499 | H13: Media lab Group Limited | I13: For a term to expiring 15/03/28 | J13: 117500 | K13: 115000 | M13: 68 | P13: TBC | Q13: SH | R13: Yes | S13: Completed | T13: TH | U13: 45590
B14: 8 | C14: 51-53 Margaret Street | D14: 3rd Floor (west) 504 sq ft | G14: 45562 | H14: Reishi Clinic Ltd | I14: 5 year lease t/b 2nd yr | J14: 28050 | K14: 26500 | M14: 55 | P14: TBC | Q14: SH | R14: Yes | S14: Completed - Not completed. | T14: SH | U14: 45591
B15: 9 | C15: 146-148 Oxford Street | D15: Ground Floor and Basement 3,348 sq ft | G15: 45303 | H15: Holland & Barrett Retail Limited | I15: 10 years with t/b 6th year | J15: 520000 | K15: 522500 | M15: 160 | P15: In House | Q15: SH | R15: Yes | S15: Exchanged | T15: JM | U15: Completion 08/11/2024
B16: 10 | C16: 27-28 Eastcastle Street | D16: 3rd Floor 665 sq ft | G16: 45534 | H16: Principle Estate Management Limited | I16: 5 year lease with a t/b 2 years & 6 months | J16: 41875 | K16: 36600 | M16: 62.5 | P16: TBC | Q16: SH | R16: YES | S16: Completed. | T16: SH | U16: 45618
B17: 11 | C17: 23-25 Eastcastle Street | D17: 2nd Floor (East) 1,124 sq ft | G17: 45581 | H17: Cord Technologies Ltd | I17: Co-terminus with current lease on 1st Floor West (Expiring 08/06/26 | J17: 71875 | K17: 60400 | M17: 63.95 | P17: Stephenson's LLP | Q17: SH | R17: Yes | S17: Completed | T17: SH | U17: 45618
B18: 12 | C18: Golderbrock House, 15/19 Great Titchfield Street | D18: 1st Floor Front 1,335 sq ft | G18: 45427 | H18: Space Workplace Limited | I18: 5 years with a tb 3rd year | J18: 80400 | K18: 73700 | M18: 60 | P18: BPE | Q18: SH | R18: Yes | S18: Completed 29/11/2024 | T18: TH | U18: 45624
B19: 13 | C19: Portland House, 4 Great Portland Street | D19: 5th Floor (West) 1,528 sq ft | G19: 45539 | H19: Rios Design Studio Limited | I19: 5 year lease with a t/b 3rd year | J19: 108680 | K19: N/A | M19: 71.5 | P19: In House | Q19: SH | R19: YES | S19: Completed 26/11/2024 | T19: SH | U19: 45621
B20: 14 | C20: Flat 1, 2 Little Portland Street | D20: 1st Floor (1 bed / 420 sq ft) | G20: n/a | H20: Miss Julia Tressler | I20: 1 Year | J20: 25200 | K20: 27000 | M20: 58.65 | P20: n/a | Q20: n/a | R20: Yes | S20: Completed. 12/12/2024 | T20: CM | U20: 45639
B21: 9 | C21: 20 Great Portland street | D21: 2 Margaret Court 265sq.ft | G21: 45583 | H21: Express Alteration and Tailoring Limited | I21: 5 year lease | J21: 18000 | K21: 11700 | M21: 68 | P21: TBC | Q21: SH | R21: YES | S21: Solicitors instructed. Tenant made additional requests for lease documents. 12/12/2024 | T21: YS | U21: 45646
B22: 2025 | C22: 2025 | D22: 2025 | G22: 2025 | H22: 2025 | I22: 2025 | J22: 2025 | K22: 2025 | M22: 2025 | P22: 2025 | Q22: 2025 | R22: 2025 | S22: 2025 | T22: 2025 | U22: 2025
B23: 1 | C23: Portland House, 4 Great Portland Street | D23: 4th Floor, (East) 1,957sq.ft | E23: NL | G23: 45540 | H23: Racoon Media Services Ltd | I23: 5 years lease with a break option in year 3 on | J23: 114253 | K23: 115800 | L23: =J23-K23 -> -1547 | M23: 58.38 | P23: SMB London | Q23: SH | R23: Yes | S23: Completed | T23: SH | U23: 45667
B24: 2 | C24: Portland House, 4 Great Portland Street | D24: 4th Floor, (West) 1,548sq.ft | E24: NL | G24: 45540 | H24: Racoon Media Services Ltd | I24: 5 years lease with a break option in year 3 on 6 months notice. Rent free period of 3 months & 16 days | J24: 90090 | K24: 90100 | L24: =J24-K24 -> -10 | M24: 58.19 | P24: SMB London | Q24: SH | R24: Yes | S24: Completed | T24: SH | U24: 45667
B25: 3 | C25: Portland House, 4 Great Portland Street | D25: 6th Floor, (West) 1,253sq.ft | E25: NL | G25: 45540 | H25: Directors Cut Films West Ltd | I25: 5 year lease with a break option in year 3 on 6 months & 16 days. | J25: 66700 | K25: 66.7 | L25: =J25-K25 -> 66633.3 | M25: 53.23 | P25: Ronald Fletcher Baker | Q25: SH | R25: Yes | S25: Completed | T25: SH | U25: 45667
B26: 4 | C26: 6-10 Great Portland Street | D26: 5th Floor - 995sq.ft | E26: NL | G26: 45540 | H26: Racoon Media Services Ltd | I26: 5 year lease with a break option in year 3 on 6 months & 16 days. | J26: 61928 | K26: 61200 | L26: =J26-K26 -> 728 | M26: 62.24 | P26: SMB London | Q26: SH | R26: Yes | S26: Completed | T26: SH | U26: 45667
B27: 5 | C27: 47-50 Margaret Street | D27: 4th Floor (West) 390sq.ft | E27: NL | G27: 45593 | H27: Sen Yoga Ltd | I27: 5 years with t/b year 3 | J27: 21060 | K27: 19500 | L27: =J27-K27 -> 1560 | M27: 54 | P27: Lisa's Law LLP | Q27: SH | R27: Yes | S27: Completed | T27: SH | U27: 45681
B28: 6 | C28: Moray House | D28: Ground Floor Centre 1,949sq.ft | E28: NL | G28: 45590 | H28: H Illume Limited T/A LAPO | I28: 10 years | J28: 118000 | K28: 91000 | L28: =J28-K28 -> 27000 | M28: 60.5 | P28: TBC | Q28: SH | R28: YES | S28: Compled | T28: TH | U28: 45687
B29: 7 | C29: Store Room A, 50 Eastcastle Street | D29: Basement 454 sq ft | E29: NL | G29: 45670 | H29: Hope 93 Ltd | I29: 4 Years 7 Months / TB on 28/08/27 / RR on 28/08/27 | J29: 12000 | K29: 10000 | L29: =J29-K29 -> 2000 | M29: =55000/2161 -> 25.45118 | P29: SH | Q29: SH | R29: YES | S29: Completed 28th 27/01 | T29: JM | U29: 45684
B30: 8 | C30: 51 Great Portland Street | D30: 2nd Floor 325sq.ft | E30: NL | G30: 45593 | H30: Learn Lab Language School Ltd | I30: 2 years with t/b yr 1 (Inclusive deal) | J30: 22069 | K30: 17100 | L30: =J30-K30 -> 4969 | M30: 56 | P30: TBC | Q30: SH | R30: YES | S30: Completed 11/02/2025 | T30: YS | U30: 45702
B31: 9 | C31: 50 Eastcastle Street | D31: Suite 398 416sq.ft | E31: NL | G31: 45635 | H31: Pixi Beauty | I31: Co terminus with lease at 395 13/11/2027 | J31: 15000 | K31: 23900 | L31: =J31-K31 -> -8900 | M31: 36 | P31: Inhouse | Q31: SH | R31: YES | S31: Awaiting for completion documents from Pixi. Internal Red Tape and time difference is the given reason for the delay. 24/01/2025 | T31: JM | U31: 45702
B32: 10 | C32: 6/10 Great Portland Street | D32: Basement, Ground & Mezz 4,958 sq ft | E32: NL | G32: 45646 | H32: PrettyLittleThing.com Limited | I32: 5 years with t/b year 3 | J32: 375000 | K32: 337100 | L32: =J32-K32 -> 37900 | M32: 75.63 | P32: Pannone Corporate LLP | Q32: SH | R32: YES | S32: Completed 11/02/2025.14.02.25 | T32: SH | U32: 45702
B33: 11 | C33: 93 Mortimer Street / 43 Gt Portland Street | D33: Whole Building 10,112 sq ft | E33: NL | G33: 45464 | H33: Kamel Lazaar Foundation | I33: 15 years with t/b 6th & 10th years | J33: 700000 | K33: 750000 | L33: =J33-K33 -> -50000 | M33: 71 | P33: TBC | Q33: SH | R33: YES | S33: Completed 20/02/2025 | T33: YS | U33: 45709
B34: 12 | C34: Golderbrock House, 15/19 Great Titchfield Street | D34: Ground Floor Rear 325 sq ft | E34: NL | G34: 45625 | H34: Arlettie | I34: 3 years | J34: 20000 | K34: 17073 | L34: =J34-K34 -> 2927 | M34: 61.54 | P34: Wedlake Bell | Q34: SH | R34: YES | S34: Due to complete 20/21 Feb. 20/02/25 | T34: TH | U34: 45709
B35: 13 | C35: Princess House, 50 Eastcastle Street | D35: Suite 375 797 sq.ft | E35: NL | G35: 45678 | H35: Jewells Retail Limited | I35: A term to expire on 07/03/26 | J35: 59583 | K35: 45800 | L35: =J35-K35 -> 13783 | M35: 58.5 | P35: Inhouse | Q35: Wallace | R35: Yes | S35: all inclusive deal completed 25/02/2025 | T35: JM | U35: 45716
B36: 14 | C36: Princess House, 50 Eastcastle Street | D36: Suite 380 480 sq.ft | E36: NL | G36: 45678 | H36: Jewells Retail Limited | I36: A term to expire on 07/03/26 | J36: 35857 | K36: 27600 | L36: =J36-K36 -> 8257 | M36: 58.5 | P36: Inhouse | Q36: Wallace | R36: Yes | S36: all inclusive deal completed 25/02/2025 | T36: JM | U36: 45716
B37: 15 | C37: 23-25 Eastcastle Street | D37: Ground Floor and Basement 6,092 sq ft | E37: NL | G37: 45510 | H37: Sisters Grimm Limited | I37: 5 years with a t/b 3rd year | J37: 325000 | K37: 225000 | L37: =J37-K37 -> 100000 | M37: 56.32 | P37: TBC | Q37: SH | R37: Yes | S37: Completed. 28.02.25 | T37: SH | U37: 45716
B38: 16 | C38: 22 Eastcastle Street | D38: Ground Floor 2,333 sq ft | E38: NL | G38: 45553 | H38: Top Bridal Ltd | I38: 5 year Lease t/b 3rd year | J38: 128000 | K38: 110000 | L38: =J38-K38 -> 18000 | M38: =J38/2333 -> 54.864981 | P38: TBC | Q38: SH | R38: YES | S38: Completion 20.03.25 | T38: SH | U38: 45736
B39: 17 | C39: 65 Margaret Street | D39: 5th Floor 350 sq ft | E39: NL | G39: 45674 | H39: Mercury Creations Limited | I39: 5 years with t/b year 3 | J39: 19950 | K39: 17500 | L39: =J39-K39 -> 2450 | M39: 57 | P39: Inhouse | Q39: SH | R39: Yes | S39: COMPLETED | T39: CM | U39: 45744
B40: 18 | C40: 1 Great Titchfield street | D40: Whole Building 1,425 sq ft | E40: NL | G40: 45624 | H40: Tikkas | I40: 10 years | J40: 90000 | K40: 90000 | L40: =J40-K40 -> 0 | M40: 63 | P40: Optima Law Solicitors | Q40: SH | R40: Yes | S40: Engrossments all signed. Awaiting completion money - 28/03/2025 | T40: YS | U40: 45749
B41: 19 | C41: Golderbrock House, 15/19 Great Titchfield Street | D41: 4th Floor 1,330 sq.ft. | E41: NL | G41: 45700 | H41: Autonomous UK Ltd | I41: 5 year lease with t/b year 3 | J41: 86450 | K41: 78200 | L41: =J41-K41 -> 8250 | M41: 65 | P41: Clarke Wilmott | Q41: SH | R41: Yes | S41: Completed 15/04/2025 | T41: TH | U41: 45762
B42: 20 | C42: Priness House, 50 Eastcastle Street | D42: Suite 350, 3rd Floor 489 sq ft | E42: NL | G42: 45744 | H42: Jewells Retail Ltd | I42: A term to expire on 07/03/2026 | J42: 28607 | K42: 28100 | L42: =J42-K42 -> 507 | M42: 58.5 | P42: TBC | Q42: Wallace | R42: Yes | S42: Completed 23/04/2025 | T42: JM | U42: 45770
B43: 21 | C43: 30 Market Place | D43: 4th Floor 4,250 sq.ft | E43: NL | G43: 45733 | H43: Ascot Lloyd | I43: 10 year lease T/0 Break 5yr | J43: 361250 | K43: 358600 | L43: =J43-K43 -> 2650 | M43: =J43/4250 -> 85 | P43: Murrell Associates | Q43: SH | R43: YES | S43: Completed 09/05/2025 | T43: YS | U43: 45791
...
