Workbook

Sheet Buildings
C1: Hide | D1: Hide | E1: Hide
C2: Hide | D2: Hide | E2: Hide | I2: Hide | J2: Hide | R2: Hide | S2: Hide | U2: Hide | W2: Hide | AD2: Hide | AE2: Hide | AF2: Hide | AG2: Hide
B3: Surveyor | C3: Client | D3: Property Number | E3: Property | F3: Unit Demise | G3: Unit Type | H3: Net Area | I3: . | J3: Agency Area group | K3: Tenant Name | L3: Start Date | M3: Expiry Date | N3: Vacant Since? | O3: RRs | P3: Break Date | Q3: Rent PA (£) | R3: check 1 | S3: check 2 | T3: 2023 ERV (£) | U3: check 3 | V3: 2024 ERV (£) | W3: check 4 | X3: ERV 2023 £.Sq.ft | Y3: EPC | Z3: * | AA3: 2024 Cap Valn. (£) | AB3: 1954 Act Protected | AC3: Remarks | AD3: Agency Quoting Rent £.sq.ft | AE3: Monthly Viewings | AF3: Total Viewings | AG3: Marketing Agent
G5: 5-6 Bywell Place
B7: TH | C7: MEL | D7: 550020 | E7: 5-6 Bywell Place | F7: Whole Building | G7: Office | H7: 2011 | I7: =H7 -> 2011 | J7: 2000 | K7: 111 Skin Limited | L7: 45365 | M7: 47190 | P7: 46459 | Q7: 115500 | R7: =Q7 -> 115500 | S7: =R7 -> 115500 | T7: 100600 | U7: =T7 -> 100600 | V7: 115000 | W7: =V7 -> 115000 | X7: =T7/H7 -> 50.024863 | Y7: C | AA7: 1825000 | AB7: No | AC7: Tenant break on 6 months notice. Break penalty of £28,875 if exercised.
F8: 5/6 Bywell Place | H8: =SUM(H7:H7) -> 2011
G9: 22 and 23-25 Eastcastle Street
B11: SH | C11: MEL | D11: 550910 | E11: 22 and 23-25 Eastcastle Street | F11: Lower Ground & Ground (22) | G11: Retail | H11: 2333 | I11: =H11 -> 2333 | J11: 2000 | K11: Top Bridal Ltd | L11: 45736 | M11: 47561 | P11: 46831 | Q11: 0 | R11: =Q11 -> 0 | T11: 110000 | U11: =T11 -> 110000 | V11: 108100 | W11: =V11 -> 108100 | X11: =T11/H11 -> 47.149593 | Y11: C | AB11: No | AC11: Stepped rent. £128,000 wef 20/06/25 increasing to £130,000 wef 20/03/27. Tenant break on 6 months notice. | AE11: 1 | AF11: 3
C12: MEL
C13: MEL | F13: 22, 23 & 25 Eastcastle St | H13: =SUM(H11:H11) -> 2333 | Q13: =SUM(Q11:Q11) -> 0 | S13: =SUM(R10:R11) -> 0 | T13: =SUM(T11:T11) -> 110000 | V13: =SUM(V11:V11) -> 108100 | AA13: 14850000
C14: MEL
C15: MEL | G15: 26 Eastcastle Street
C16: MEL
B17: SH | C17: MEL | D17: 550920 | E17: 26 Eastcastle Street | F17: Lower Ground & Ground | G17: Showroom/ Offices | H17: 2940 | I17: =H17 -> 2940 | J17: 3000 | K17: Hela Brands Ltd | L17: 45649 | M17: 46743 | P17: 46013 | Q17: 132000 | R17: =Q17 -> 132000 | T17: 114600 | U17: =T17 -> 114600 | V17: 124500 | W17: =V17 -> 124500 | X17: =T17/H17 -> 38.979592 | Y17: C | AB17: No | AC17: Tenant rolling break from 22/12/25 on 4 months notice.
C18: MEL
C19: MEL | G19: 27 - 28 Eastcastle Street
C20: MEL
B21: SH | C21: MEL | D21: 550930 | E21: 27 - 28 Eastcastle Street | F21: Lower Ground & Ground | G21: Showroom / Offices | H21: 3668 | I21: =H21 -> 3668 | J21: 3500 | K21: The London Hair Clinic Ltd | L21: 44757 | M21: 48409 | O21: 46583 | Q21: 170000 | R21: =Q21 -> 170000 | T21: 170000 | U21: =T21 -> 170000 | V21: 170000 | W21: =V21 -> 170000 | X21: =T21/H21 -> 46.346783 | Y21: B | AB21: No
C22: MEL
C23: MEL | G23: 10 Great Castle Street
C24: MEL
B25: YS | C25: MEL | D25: 550560 | E25: 10 Great Castle Street | F25: Basmt. Ground - 1 to 4 Floors | G25: Office | H25: 12578 | I25: =H25 -> 12578 | J25: 12500 | K25: Guaranty Trust Bank (UK) Ltd | L25: 44771 | M25: 50249 | O25: 46597 | P25: 48423 | Q25: 633334 | R25: =Q25 -> 633334 | S25: =R25 -> 633334 | T25: 950000 | U25: =T25 -> 950000 | V25: 950000 | W25: =V25 -> 950000 | X25: =T25/H25 -> 75.528701 | Y25: C | AA25: 17050000 | AB25: No | AC25: Fixed increase to £950,000 on 29/07/26. 5 yearly rent reviews. Tenant break on 9 months notice. Rent reduces by 20% for 12 months if break not activated.
C26: MEL | F26: 8-11 Great Castle Street | H26: =SUM(H25:H25) -> 12578 | Q26: =SUM(Q25:Q25) -> 633334 | T26: =SUM(T25:T25) -> 950000 | V26: =SUM(V25:V25) -> 950000
C27: MEL | G27: Windsor House, 40-41 Great Castle Street
C28: MEL
B29: SH | C29: MEL | D29: 550070 | E29: Windsor House, 40-41 Great Castle Street | F29: Basement & Ground Floor | G29: Retail/Café | H29: 2235 | I29: =H29 -> 2235 | J29: 2000 | K29: Vacant | N29: 45754 | Q29: 0 | R29: =Q29 -> 0 | T29: 143000 | U29: =T29 -> 143000 | V29: 145000 | W29: =V29 -> 145000 | X29: =T29/H29 -> 63.982103 | Y29: D | AB29: No | AC29: Lease forfeited on 07/04/25 (Al Falamanki Raoucche Ltd)
C30: MEL
C31: MEL | F31: 40/41 Great Castle Street | H31: =SUM(H29:H29) -> 2235 | Q31: =SUM(Q29:Q29) -> 0 | S31: =SUM(R29:R29) -> 0 | T31: =SUM(T29:T29) -> 143000 | V31: =SUM(V29:V29) -> 145000 | AA31: 4750000
C32: MEL
C33: MEL | G33: Portland House, 4 Great Portland Street
C34: MEL
B35: SH | C35: MEL | D35: 550470 | E35: Portland House, 4 Great Portland Street | F35: Basement (West) | G35: Restaurant/Bar | H35: 2945 | I35: =H35 -> 2945 | J35: 3000 | K35: The London Cocktail Club Ltd | L35: 41457 | M35: 46935 | O35: 45109 | Q35: 147500 | R35: =Q35 -> 147500 | T35: 147500 | U35: =T35 -> 147500 | V35: 147500 | W35: =V35 -> 147500 | X35: =T35/H35 -> 50.08489 | Y35: E | AB35: No | AC35: 5 year reversionary lease from 02/07/28 with day one rent review. Rent review to be documented at passing rent.
B36: SH | C36: MEL | D36: 550470 | E36: Portland House, 4 Great Portland Street | F36: Ground Floor | G36: Retail/Cafe | H36: 2103 | I36: =H36 -> 2103 | J36: 2000 | K36: Costa Ltd | L36: 45669 | M36: 51146 | O36: 47495 | P36: 49320 | Q36: 220000 | R36: =Q36 -> 220000 | T36: 176200 | U36: =T36 -> 176200 | V36: 220000 | W36: =V36 -> 220000 | X36: =T36/H36 -> 83.785069 | Y36: B | AB36: No | AC36: Mutual break on 6 months notice.
B37: SH | C37: MEL | D37: 550470 | E37: Portland House, 4 Great Portland Street | F37: Ground Floor & Basement (East) & Basement Vaults | G37: Restaurant | H37: 5667 | I37: =H37 -> 5667 | J37: 5500 | K37: Futuremaxx Ltd | L37: 45567 | M37: 51044 | O37: 47393 | Q37: 150000 | R37: =Q37 -> 150000 | T37: 255000 | U37: =T37 -> 255000 | V37: 300000 | W37: =V37 -> 300000 | X37: =T37/H37 -> 44.997353 | Y37: B | AB37: No | AC37: Stepped rent. £300,000 wef 02/10/25, £305,000 wef 02/10/26, £310,000 wef 02/10/27 and £320,000 wef 02/10/28. Min rent on review £330,000. Landlord redevelopment break option on 01/07/33 on 6 months notice.
C38: MEL
C39: MEL | G39: 6-10a Great Portland Street
C40: MEL
B41: SH | C41: MEL | D41: 550480 | E41: 6-10a Great Portland Street | F41: Basement & Ground | G41: Retail | H41: 4958 | I41: =H41 -> 4958 | J41: 5000 | K41: PrettyLittleThing.com | L41: 45699 | M41: 47524 | P41: 46793 | Q41: 0 | R41: =Q41 -> 0 | T41: 337100 | U41: =T41 -> 337100 | V41: 380000 | W41: =V41 -> 380000 | X41: =T41/H41 -> 67.991125 | Y41: B | AB41: No | AC41: Rent £187,500 wef 11/05/25 increasing to £375,000 wef 11/09/25. Tenant break on 6 months notice. 3 months rent free if not exercised. | AD41: 68 | AE41: 1 | AF41: 13 | AG41: LEM / Colliers
C42: MEL
C43: MEL | G43: 15-17 Great Portland Street & 6-7 Great Castle Street
...

Sheet Sheet2
B2: 5-6 Bywell Place
A4: Whole Building | B4: Office | C4: 2011 | D4: =C4 -> 2011 | E4: 2000 | F4: 111 Skin Limited
A5: 5/6 Bywell Place | C5: =SUM(C4:C4) -> 2011
B6: 22 and 23-25 Eastcastle Street
A8: Lower Ground & Ground (22) | B8: Retail | C8: 2333 | D8: =C8 -> 2333 | E8: 2000 | F8: Top Bridal Ltd
A10: 22, 23 & 25 Eastcastle St | C10: =SUM(C8:C8) -> 2333
B12: 26 Eastcastle Street
A14: Lower Ground & Ground | B14: Showroom/ Offices | C14: 2940 | D14: =C14 -> 2940 | E14: 3000 | F14: Hela Brands Ltd
B16: 27 - 28 Eastcastle Street
A18: Lower Ground & Ground | B18: Showroom / Offices | C18: 3668 | D18: =C18 -> 3668 | E18: 3500 | F18: The London Hair Clinic Ltd
B20: 10 Great Castle Street
A22: Basmt. Ground - 1 to 4 Floors | B22: Office | C22: 12578 | D22: =C22 -> 12578 | E22: 12500 | F22: Guaranty Trust Bank (UK) Ltd
A23: 8-11 Great Castle Street | C23: =SUM(C22:C22) -> 12578
B24: Windsor House, 40-41 Great Castle Street
A26: Basement & Ground Floor | B26: Retail/Café | C26: 2235 | D26: =C26 -> 2235 | E26: 2000 | F26: Vacant
A28: 40/41 Great Castle Street | C28: =SUM(C26:C26) -> 2235
B30: Portland House, 4 Great Portland Street
A32: Basement (West) | B32: Restaurant/Bar | C32: 2945 | D32: =C32 -> 2945 | E32: 3000 | F32: The London Cocktail Club Ltd
A33: Ground Floor | B33: Retail/Cafe | C33: 2103 | D33: =C33 -> 2103 | E33: 2000 | F33: Costa Ltd
A34: Ground Floor & Basement (East) & Basement Vaults | B34: Restaurant | C34: 5667 | D34: =C34 -> 5667 | E34: 5500 | F34: Futuremaxx Ltd
B36: 6-10a Great Portland Street
A38: Basement & Ground | B38: Retail | C38: 4958 | D38: =C38 -> 4958 | E38: 5000 | F38: PrettyLittleThing.com
B40: 15-17 Great Portland Street & 6-7 Great Castle Street
A42: Whole Building | B42: Office/Bank | C42: 9884 | D42: =C42 -> 9884 | E42: 10000 | F42: Barclays Bank UK Plc
A43: 15/17 Great Portland Street | C43: =SUM(C42:C42) -> 9884
B45: 19-21 Great Portland Street
A47: Basement, Ground & First Floors | B47: Restaurant | C47: 11225 | D47: =C47 -> 11225 | E47: 10000 | F47: UK VAP GPS
B49: 20 Great Portland Street
A51: Basement | B51: Studio | C51: 1330 | D51: =C51 -> 1330 | F51: Vacant / Landlord
A52: Ground Floor Rear | B52: Retail | C52: 260 | D52: =C52 -> 260 | E52: 250 | F52: Express Alteration and Tailoring Ltd
A53: Ground Floor Front | B53: Retail | C53: 652 | D53: =C53 -> 652 | E53: 750 | F53: Explore Global Limited
B55: Highlight House, 22-24 Great Portland Street
A57: Basement & Ground Floor | B57: Restaurant | C57: 3626 | D57: =C57 -> 3626 | E57: 3500 | F57: Mamaye UK Limited.
B59: 23-25 Great Portland Street & 54-55 Margaret Street
A61: Basement & Ground Floor | B61: Shop/Cafe | C61: 2164 | D61: =C61 -> 2164 | E61: 2000 | F61: Florian James Limited
B63: 39 Great Portland Street
A65: Basement & Ground Floor | B65: Showroom | C65: 1524 | D65: =C65 -> 1524 | E65: 1500 | F65: Fads Boutique Limited
B67: 41 Great Portland Street
A69: Basement to Fourth | B69: Offices | C69: 2313 | D69: =C69 -> 2313 | E69: 2250 | F69: S.Hardwick & L.Morris (t/a Hardwick & Morris Chartered Accountants)
B71: 42-48 Great Portland Street
...

Sheet Bank Schedule
D1: Hide | E1: Hide | F1: Hide
D2: Hide | E2: Hide | F2: Hide | J2: Hide | K2: Hide | S2: Hide | T2: Hide | V2: Hide | X2: Hide | AE2: Hide | AF2: Hide | AG2: Hide | AH2: Hide
A3: Record_Type | C3: Surveyor | D3: Client | E3: Property Number | F3: Property | G3: Unit Demise | H3: Unit Type | I3: Net Area | J3: . | K3: Agency Area group | L3: Tenant Name | M3: Start Date | N3: Expiry Date | O3: Vacant Since? | P3: RRs | Q3: Break Date | R3: Rent PA (£) | S3: check 1 | T3: check 2 | U3: 2023 ERV (£) | V3: check 3 | W3: 2024 ERV (£) | X3: check 4 | Y3: ERV 2023 £.Sq.ft | Z3: EPC | AA3: * | AB3: 2024 Cap Valn. (£) | AC3: 1954 Act Protected | AD3: Remarks | AE3: Agency Quoting Rent £.sq.ft | AF3: Monthly Viewings | AG3: Total Viewings | AH3: Marketing Agent
A5: BUILD | H5: 5-6 Bywell Place
A7: UNIT | C7: TH | D7: MEL | E7: 550020 | F7: 5-6 Bywell Place | G7: Whole Building | H7: Office | I7: 2011 | J7: =H7 -> Office | K7: 2000 | L7: 111 Skin Limited | M7: 45365 | N7: 47190 | Q7: 46459 | R7: 115500 | S7: =Q7 -> 46459 | T7: =R7 -> 115500 | U7: 100600 | V7: =T7 -> 115500 | W7: 115000 | X7: =V7 -> 115500 | Y7: =T7/H7 -> #VALUE! | Z7: C | AB7: 1825000 | AC7: No | AD7: Tenant break on 6 months notice. Break penalty of £28,875 if exercised.
G8: 5/6 Bywell Place | I8: =SUM(H7:H7) -> 0
A9: BUILD | H9: 22 and 23-25 Eastcastle Street
A11: UNIT | C11: SH | D11: MEL | E11: 550910 | F11: 22 and 23-25 Eastcastle Street | G11: Lower Ground & Ground (22) | H11: Retail | I11: 2333 | J11: =H11 -> Retail | K11: 2000 | L11: Top Bridal Ltd | M11: 45736 | N11: 47561 | Q11: 46831 | R11: 0 | S11: =Q11 -> 46831 | U11: 110000 | V11: =T11 -> 0 | W11: 108100 | X11: =V11 -> 0 | Y11: =T11/H11 -> #VALUE! | Z11: C | AC11: No | AD11: Stepped rent. £128,000 wef 20/06/25 increasing to £130,000 wef 20/03/27. Tenant break on 6 months notice. | AF11: 1 | AG11: 3
A12: UNIT | C12: SH | D12: MEL | E12: 550910 | F12: 22 and 23-25 Eastcastle Street | G12: Lower Ground & Ground (23-25) | H12: Gallery | I12: 6092 | J12: =H12 -> Gallery | K12: 6000 | L12: Sisters Grimm Ltd | M12: 45712 | N12: 47537 | Q12: 46806 | R12: 0 | S12: =Q12 -> 46806 | U12: 225000 | V12: =T12 -> 0 | W12: 226100 | X12: =V12 -> 0 | Y12: =T12/H12 -> #VALUE! | Z12: C | AC12: No | AD12: Rent £325,000 wef 24/05/25. Tenant break on 6 months notice. 1 month rent free from 24/02/28 if break not excerised. | AG12: 3 | AH12: LEM
A13: UNIT | C13: SH | D13: MEL | E13: 550910 | F13: 22 and 23-25 Eastcastle Street | G13: First Floor (22) | H13: Office | I13: 1063 | J13: =H13 -> Office | K13: 1000 | L13: Peter Alexander UK Ltd | M13: 45551 | N13: 47376 | Q13: 46645 | R13: 61425 | S13: =Q13 -> 46645 | U13: 55700 | V13: =T13 -> 0 | W13: 61100 | X13: =V13 -> 0 | Y13: =T13/H13 -> #VALUE! | Z13: D | AC13: No | AD13: Tenant break on 3 months notice. Additional 3 months rent free if not exercised. | AH13: LEM
A14: UNIT | C14: SH | D14: MEL | E14: 550910 | F14: 22 and 23-25 Eastcastle Street | G14: First Floor (23-25) | H14: Office | I14: 2220 | J14: =H14 -> Office | K14: 2000 | L14: Cord Technologies Ltd | M14: 45086 | N14: 46181 | Q14: 45816 | R14: 131400 | S14: =Q14 -> 45816 | U14: 131100 | V14: =T14 -> 0 | W14: 133200 | X14: =V14 -> 0 | Y14: =T14/H14 -> #VALUE! | Z14: D | AC14: No | AD14: Tenant break on 6 months notice.
A15: UNIT | C15: SH | D15: MEL | E15: 550910 | F15: 22 and 23-25 Eastcastle Street | G15: Second Floor (22) | H15: Office | I15: 1124 | J15: =H15 -> Office | K15: 1000 | L15: Cord Technologies Ltd | M15: 45614 | N15: 46181 | Q15: 45816 | R15: 71875 | S15: =Q15 -> 45816 | U15: 60400 | V15: =T15 -> 0 | W15: 61800 | X15: =V15 -> 0 | Y15: =T15/H15 -> #VALUE! | Z15: B | AC15: No | AD15: Tenant break on 6 months notice.
A16: UNIT | C16: SH | D16: MEL | E16: 550910 | F16: 22 and 23-25 Eastcastle Street | G16: Second Floor (23-25) | H16: Office | I16: 2238 | J16: =H16 -> Office | K16: 2000 | L16: Vacant | O16: 45636 | R16: 0 | S16: =Q16 -> 0 | U16: 134300 | V16: =T16 -> 0 | W16: 134300 | X16: =V16 -> 0 | Y16: =T16/H16 -> #VALUE! | Z16: D | AC16: No | AD16: LEM marketing.
A17: UNIT | C17: SH | D17: MEL | E17: 550910 | F17: 22 and 23-25 Eastcastle Street | G17: Third Floor (22) | H17: Office | I17: 400 | J17: =H17 -> Office | K17: 500 | L17: Vacant | O17: 45771 | R17: 0 | S17: =Q17 -> 0 | U17: 20600 | V17: =T17 -> 0 | W17: 23000 | X17: =V17 -> 0 | Y17: =T17/H17 -> #VALUE! | Z17: D | AC17: No | AD17: LEM marketing.
A18: UNIT | C18: SH | D18: MEL | E18: 550910 | F18: 22 and 23-25 Eastcastle Street | G18: Third Floor (23-25) | H18: Office | I18: 1938 | J18: =H18 -> Office | K18: 2000 | L18: Vacant | O18: 45217 | R18: 0 | S18: =Q18 -> 0 | U18: 109000 | V18: =T18 -> 0 | W18: 111400 | X18: =V18 -> 0 | Y18: =T18/H18 -> #VALUE! | Z18: D | AC18: No | AD18: LEM marketing. | AE18: 65 | AF18: 1 | AG18: 3
A19: UNIT | C19: SH | D19: MEL | E19: 550910 | F19: 22 and 23-25 Eastcastle Street | G19: Fourth Floor (22) | H19: Office | I19: 419 | J19: =H19 -> Office | K19: 500 | L19: Element Pictures UK Ltd. | M19: 44539 | N19: 46364 | R19: 23940 | S19: =Q19 -> 0 | U19: 21000 | V19: =T19 -> 0 | W19: 24100 | X19: =V19 -> 0 | Y19: =T19/H19 -> #VALUE! | Z19: D | AC19: No
A20: UNIT | C20: SH | D20: MEL | E20: 550910 | F20: 22 and 23-25 Eastcastle Street | G20: Fourth Floor (23-25) | H20: Office | I20: 972 | J20: =H20 -> Office | K20: 1000 | L20: Encore Search (Newburgh Street) Ltd. | M20: 45100 | N20: 46926 | Q20: 46195 | R20: 58560 | S20: =Q20 -> 46195 | U20: 49400 | V20: =T20 -> 0 | W20: 58300 | X20: =V20 -> 0 | Y20: =T20/H20 -> #VALUE! | Z20: D | AC20: No | AD20: Tenant break on 6 months notice. 3 months rent free if not exercised.
A21: UNIT | C21: SH | D21: MEL | E21: 550910 | F21: 22 and 23-25 Eastcastle Street | G21: Fifth Floor (23-25) | H21: Office | I21: 977 | J21: =H21 -> Office | K21: 1000 | L21: Element Pictures UK Ltd. | M21: 45476 | N21: 47301 | Q21: 46364 | R21: 58496 | S21: =Q21 -> 46364 | U21: 47400 | V21: =T21 -> 0 | W21: 58600 | X21: =V21 -> 0 | Y21: =T21/H21 -> #VALUE! | Z21: B | AC21: No | AD21: Tenant break on 6 months notice.
A22: UNIT | C22: SH | D22: MEL | E22: 550910 | F22: 22 and 23-25 Eastcastle Street | G22: Sixth Floor (23-25) | H22: Office | I22: 744 | J22: =H22 -> Office | K22: 750 | L22: Vacant | O22: 45182 | R22: 0 | S22: =Q22 -> 0 | U22: 34400 | V22: =T22 -> 0 | W22: 42800 | X22: =V22 -> 0 | Y22: =T22/H22 -> #VALUE! | Z22: D | AC22: No | AD22: LEM marketing. | AE22: 63.5 | AF22: 1 | AG22: 3 | AH22: LEM
A23: UNIT | C23: SH | D23: MEL | E23: 550910 | F23: 22 and 23-25 Eastcastle Street | G23: Garage | H23: Parking | I23: 185 | J23: =H23 -> Parking | K23: 200 | L23: Vacant / Landlord | O23: N/A | R23: 0 | S23: =Q23 -> 0 | U23: 3000 | V23: =T23 -> 0 | W23: 4500 | X23: =V23 -> 0 | Y23: =T23/H23 -> #VALUE! | AC23: No
D24: MEL
D25: MEL | G25: 22, 23 & 25 Eastcastle St | I25: =SUM(H11:H23) -> 0 | R25: =SUM(Q11:Q23) -> 324473 | T25: =SUM(R10:R23) -> 405696 | U25: =SUM(T11:T23) -> 0 | W25: =SUM(V11:V23) -> 0 | AB25: 14850000
D26: MEL
A27: BUILD | D27: MEL | H27: 26 Eastcastle Street
D28: MEL
A29: UNIT | C29: SH | D29: MEL | E29: 550920 | F29: 26 Eastcastle Street | G29: Lower Ground & Ground | H29: Showroom/ Offices | I29: 2940 | J29: =H29 -> Showroom/ Offices | K29: 3000 | L29: Hela Brands Ltd | M29: 45649 | N29: 46743 | Q29: 46013 | R29: 132000 | S29: =Q29 -> 46013 | U29: 114600 | V29: =T29 -> 0 | W29: 124500 | X29: =V29 -> 0 | Y29: =T29/H29 -> #VALUE! | Z29: C | AC29: No | AD29: Tenant rolling break from 22/12/25 on 4 months notice.
A30: UNIT | C30: SH | D30: MEL | E30: 550920 | F30: 26 Eastcastle Street | G30: First Floor | H30: Offices | I30: 1398 | J30: =H30 -> Offices | K30: 1000 | L30: Alternative Real Estate Advisors Ltd | M30: 45470 | N30: 47295 | Q30: 46564 | R30: 89833 | S30: =Q30 -> 46564 | U30: 76900 | V30: =T30 -> 0 | W30: 97900 | X30: =V30 -> 0 | Y30: =T30/H30 -> #VALUE! | Z30: D | AC30: No | AD30: Rent increases to £98,000 @ 27/06/27. Tenant break on 6 months notice.
A31: UNIT | C31: SH | D31: MEL | E31: 550920 | F31: 26 Eastcastle Street | G31: Second Floor | H31: Offices | I31: 1110 | J31: =H31 -> Offices | K31: 1000 | L31: Vacant | O31: 43273 | R31: 0 | S31: =Q31 -> 0 | U31: 61100 | V31: =T31 -> 0 | W31: 69400 | X31: =V31 -> 0 | Y31: =T31/H31 -> #VALUE! | Z31: C | AC31: No | AD31: LEM marketing. | AE31: 63.5 | AG31: 1
A32: UNIT | C32: SH | D32: MEL | E32: 550920 | F32: 26 Eastcastle Street | G32: Third Floor | H32: Offices | I32: 481 | J32: =H32 -> Offices | K32: 500 | L32: Mr. A. Park | M32: 45541 | N32: 47366 | Q32: 46635 | R32: 26000 | S32: =Q32 -> 46635 | U32: 25300 | V32: =T32 -> 0 | W32: 25300 | X32: =V32 -> 0 | Y32: =T32/H32 -> #VALUE! | Z32: D | AC32: No | AD32: Tenant break on 6 months notice.
D33: MEL
D34: MEL | G34: 26 Eastcastle Street | I34: =SUM(H29:H32) -> 0 | R34: =SUM(Q29:Q32) -> 139212 | T34: =SUM(R29:R32) -> 247833 | U34: =SUM(T29:T32) -> 0 | W34: =SUM(V29:V32) -> 0 | AB34: 4725000
D35: MEL
A36: BUILD | D36: MEL | H36: 27 - 28 Eastcastle Street
D37: MEL
A38: UNIT | C38: SH | D38: MEL | E38: 550930 | F38: 27 - 28 Eastcastle Street | G38: Lower Ground & Ground | H38: Showroom / Offices | I38: 3668 | J38: =H38 -> Showroom / Offices | K38: 3500 | L38: The London Hair Clinic Ltd | M38: 44757 | N38: 48409 | P38: 46583 | R38: 170000 | S38: =Q38 -> 0 | U38: 170000 | V38: =T38 -> 0 | W38: 170000 | X38: =V38 -> 0 | Y38: =T38/H38 -> #VALUE! | Z38: B | AC38: No
A39: UNIT | C39: SH | D39: MEL | E39: 550930 | F39: 27 - 28 Eastcastle Street | G39: First Floor | H39: Offices | I39: 1418 | J39: =H39 -> Offices | K39: 1500 | L39: Feldberg Capital UK Limited | M39: 45231 | N39: 46326 | R39: 174500 | S39: =Q39 -> 0 | U39: 78000 | V39: =T39 -> 0 | W39: 99300 | X39: =V39 -> 0 | Y39: =T39/H39 -> #VALUE! | Z39: B | AC39: No | AD39: All inclusive including rates and furniture.
A40: UNIT | C40: SH | D40: MEL | E40: 550930 | F40: 27 - 28 Eastcastle Street | G40: Second Floor | H40: Offices | I40: 716 | J40: =H40 -> Offices | K40: 750 | L40: MSP Secretaries Ltd. | M40: 44384 | N40: 46209 | R40: 41000 | S40: =Q40 -> 0 | U40: 39400 | V40: =T40 -> 0 | W40: 41200 | X40: =V40 -> 0 | Y40: =T40/H40 -> #VALUE! | Z40: B | AC40: No
A41: UNIT | C41: SH | D41: MEL | E41: 550930 | F41: 27 - 28 Eastcastle Street | G41: Third Floor | H41: Offices | I41: 665 | J41: =H41 -> Offices | K41: 750 | L41: Principle Estate Management LLP | M41: 45617 | N41: 47442 | Q41: 46527 | R41: 41875 | S41: =Q41 -> 46527 | U41: 36600 | V41: =T41 -> 0 | W41: 38200 | X41: =V41 -> 0 | Y41: =T41/H41 -> #VALUE! | Z41: B | AC41: No | AD41: Tenant break on 6 months notice. 2 months rent free if break not exercised.
D42: MEL
D43: MEL | G43: 27/28 Eastcastle Street | I43: =SUM(H38:H41) -> 0 | R43: =SUM(Q36:Q41) -> 46527 | T43: =SUM(R38:R41) -> 427375 | U43: =SUM(T38:T41) -> 0 | W43: =SUM(V38:V41) -> 0 | AB43: 5675000
...

Sheet Voids Tab
B3: Surveyor | C3: Client | D3: Property Number | E3: Property | F3: Unit Demise | G3: Unit Type | H3: Net Area | I3: . | J3: Tenant Name | K3: Start Date | L3: Expiry Date | M3: Vacant Since? | N3: RRs | O3: Break Date | P3: Rent PA (£) | Q3: check 1 | R3: check 2 | S3: 2023 ERV (£) | T3: check 3 | U3: 2024 ERV (£) | V3: check 4 | W3: ERV 2023 £.Sq.ft | X3: EPC | Y3: * | Z3: 2024 Cap Valn. (£) | AA3: 1954 Act Protected | AB3: Remarks | AC3: Agency Quoting Rent £.sq.ft | AD3: Monthly Viewings | AE3: Total Viewings | AF3: Marketing Agent
A4: {=IFERROR(INDEX('Bank Schedule'!A:A, SMALL(IF('Bank Schedule'!$K$2:$K$825="Vacant", ROW('Bank Schedule'!$K$2:$K$825)), ROW(1:1))), "")} | B4: {=IFERROR(INDEX('Bank Schedule'!B:B, SMALL(IF('Bank Schedule'!$K$2:$K$825="Vacant", ROW('Bank Schedule'!$K$2:$K$825)), ROW(1:1))), "")} | C4: {=IFERROR(INDEX('Bank Schedule'!C:C, SMALL(IF('Bank Schedule'!$K$2:$K$825="Vacant", ROW('Bank Schedule'!$K$2:$K$825)), ROW(1:1))), "")} | D4: {=IFERROR(INDEX('Bank Schedule'!D:D, SMALL(IF('Bank Schedule'!$K$2:$K$825="Vacant", ROW('Bank Schedule'!$K$2:$K$825)), ROW(1:1))), "")} | E4: {=IFERROR(INDEX('Bank Schedule'!E:E, SMALL(IF('Bank Schedule'!$K$2:$K$825="Vacant", ROW('Bank Schedule'!$K$2:$K$825)), ROW(1:1))), "")} | F4: {=IFERROR(INDEX('Bank Schedule'!F:F, SMALL(IF('Bank Schedule'!$K$2:$K$825="Vacant", ROW('Bank Schedule'!$K$2:$K$825)), ROW(1:1))), "")} | G4: {=IFERROR(INDEX('Bank Schedule'!G:G, SMALL(IF('Bank Schedule'!$K$2:$K$825="Vacant", ROW('Bank Schedule'!$K$2:$K$825)), ROW(1:1))), "")} | H4: {=IFERROR(INDEX('Bank Schedule'!H:H, SMALL(IF('Bank Schedule'!$K$2:$K$825="Vacant", ROW('Bank Schedule'!$K$2:$K$825)), ROW(1:1))), "")} | I4: {=IFERROR(INDEX('Bank Schedule'!I:I, SMALL(IF('Bank Schedule'!$K$2:$K$825="Vacant", ROW('Bank Schedule'!$K$2:$K$825)), ROW(1:1))), "")} | J4: {=IFERROR(INDEX('Bank Schedule'!K:K, SMALL(IF('Bank Schedule'!$K$2:$K$825="Vacant", ROW('Bank Schedule'!$K$2:$K$825)), ROW(1:1))), "")} | K4: {=IFERROR(INDEX('Bank Schedule'!L:L, SMALL(IF('Bank Schedule'!$K$2:$K$825="Vacant", ROW('Bank Schedule'!$K$2:$K$825)), ROW(1:1))), "")} | L4: {=IFERROR(INDEX('Bank Schedule'!M:M, SMALL(IF('Bank Schedule'!$K$2:$K$825="Vacant", ROW('Bank Schedule'!$K$2:$K$825)), ROW(1:1))), "")} | M4: {=IFERROR(INDEX('Bank Schedule'!N:N, SMALL(IF('Bank Schedule'!$K$2:$K$825="Vacant", ROW('Bank Schedule'!$K$2:$K$825)), ROW(1:1))), "")} | N4: {=IFERROR(INDEX('Bank Schedule'!O:O, SMALL(IF('Bank Schedule'!$K$2:$K$825="Vacant", ROW('Bank Schedule'!$K$2:$K$825)), ROW(1:1))), "")} | O4: {=IFERROR(INDEX('Bank Schedule'!P:P, SMALL(IF('Bank Schedule'!$K$2:$K$825="Vacant", ROW('Bank Schedule'!$K$2:$K$825)), ROW(1:1))), "")} | P4: {=IFERROR(INDEX('Bank Schedule'!Q:Q, SMALL(IF('Bank Schedule'!$K$2:$K$825="Vacant", ROW('Bank Schedule'!$K$2:$K$825)), ROW(1:1))), "")} | Q4: {=IFERROR(INDEX('Bank Schedule'!R:R, SMALL(IF('Bank Schedule'!$K$2:$K$825="Vacant", ROW('Bank Schedule'!$K$2:$K$825)), ROW(1:1))), "")} | R4: {=IFERROR(INDEX('Bank Schedule'!S:S, SMALL(IF('Bank Schedule'!$K$2:$K$825="Vacant", ROW('Bank Schedule'!$K$2:$K$825)), ROW(1:1))), "")} | S4: {=IFERROR(INDEX('Bank Schedule'!T:T, SMALL(IF('Bank Schedule'!$K$2:$K$825="Vacant", ROW('Bank Schedule'!$K$2:$K$825)), ROW(1:1))), "")} | T4: {=IFERROR(INDEX('Bank Schedule'!U:U, SMALL(IF('Bank Schedule'!$K$2:$K$825="Vacant", ROW('Bank Schedule'!$K$2:$K$825)), ROW(1:1))), "")} | U4: {=IFERROR(INDEX('Bank Schedule'!V:V, SMALL(IF('Bank Schedule'!$K$2:$K$825="Vacant", ROW('Bank Schedule'!$K$2:$K$825)), ROW(1:1))), "")} | V4: {=IFERROR(INDEX('Bank Schedule'!W:W, SMALL(IF('Bank Schedule'!$K$2:$K$825="Vacant", ROW('Bank Schedule'!$K$2:$K$825)), ROW(1:1))), "")} | W4: {=IFERROR(INDEX('Bank Schedule'!X:X, SMALL(IF('Bank Schedule'!$K$2:$K$825="Vacant", ROW('Bank Schedule'!$K$2:$K$825)), ROW(1:1))), "")} | X4: {=IFERROR(INDEX('Bank Schedule'!Y:Y, SMALL(IF('Bank Schedule'!$K$2:$K$825="Vacant", ROW('Bank Schedule'!$K$2:$K$825)), ROW(1:1))), "")} | Y4: {=IFERROR(INDEX('Bank Schedule'!Z:Z, SMALL(IF('Bank Schedule'!$K$2:$K$825="Vacant", ROW('Bank Schedule'!$K$2:$K$825)), ROW(1:1))), "")} | Z4: {=IFERROR(INDEX('Bank Schedule'!AA:AA, SMALL(IF('Bank Schedule'!$K$2:$K$825="Vacant", ROW('Bank Schedule'!$K$2:$K$825)), ROW(1:1))), "")} | AA4: {=IFERROR(INDEX('Bank Schedule'!AB:AB, SMALL(IF('Bank Schedule'!$K$2:$K$825="Vacant", ROW('Bank Schedule'!$K$2:$K$825)), ROW(1:1))), "")} | AB4: {=IFERROR(INDEX('Bank Schedule'!AC:AC, SMALL(IF('Bank Schedule'!$K$2:$K$825="Vacant", ROW('Bank Schedule'!$K$2:$K$825)), ROW(1:1))), "")} | AC4: {=IFERROR(INDEX('Bank Schedule'!AD:AD, SMALL(IF('Bank Schedule'!$K$2:$K$825="Vacant", ROW('Bank Schedule'!$K$2:$K$825)), ROW(1:1))), "")} | AD4: {=IFERROR(INDEX('Bank Schedule'!AE:AE, SMALL(IF('Bank Schedule'!$K$2:$K$825="Vacant", ROW('Bank Schedule'!$K$2:$K$825)), ROW(1:1))), "")} | AE4: {=IFERROR(INDEX('Bank Schedule'!AF:AF, SMALL(IF('Bank Schedule'!$K$2:$K$825="Vacant", ROW('Bank Schedule'!$K$2:$K$825)), ROW(1:1))), "")}
A5: {=IFERROR(INDEX('Bank Schedule'!A:A, SMALL(IF('Bank Schedule'!$K$2:$K$825="Vacant", ROW('Bank Schedule'!$K$2:$K$825)), ROW(2:2))), "")} | B5: {=IFERROR(INDEX('Bank Schedule'!B:B, SMALL(IF('Bank Schedule'!$K$2:$K$825="Vacant", ROW('Bank Schedule'!$K$2:$K$825)), ROW(2:2))), "")} | C5: {=IFERROR(INDEX('Bank Schedule'!C:C, SMALL(IF('Bank Schedule'!$K$2:$K$825="Vacant", ROW('Bank Schedule'!$K$2:$K$825)), ROW(2:2))), "")} | D5: {=IFERROR(INDEX('Bank Schedule'!D:D, SMALL(IF('Bank Schedule'!$K$2:$K$825="Vacant", ROW('Bank Schedule'!$K$2:$K$825)), ROW(2:2))), "")} | E5: {=IFERROR(INDEX('Bank Schedule'!E:E, SMALL(IF('Bank Schedule'!$K$2:$K$825="Vacant", ROW('Bank Schedule'!$K$2:$K$825)), ROW(2:2))), "")} | F5: {=IFERROR(INDEX('Bank Schedule'!F:F, SMALL(IF('Bank Schedule'!$K$2:$K$825="Vacant", ROW('Bank Schedule'!$K$2:$K$825)), ROW(2:2))), "")} | G5: {=IFERROR(INDEX('Bank Schedule'!G:G, SMALL(IF('Bank Schedule'!$K$2:$K$825="Vacant", ROW('Bank Schedule'!$K$2:$K$825)), ROW(2:2))), "")} | H5: {=IFERROR(INDEX('Bank Schedule'!H:H, SMALL(IF('Bank Schedule'!$K$2:$K$825="Vacant", ROW('Bank Schedule'!$K$2:$K$825)), ROW(2:2))), "")} | I5: {=IFERROR(INDEX('Bank Schedule'!I:I, SMALL(IF('Bank Schedule'!$K$2:$K$825="Vacant", ROW('Bank Schedule'!$K$2:$K$825)), ROW(2:2))), "")} | J5: {=IFERROR(INDEX('Bank Schedule'!K:K, SMALL(IF('Bank Schedule'!$K$2:$K$825="Vacant", ROW('Bank Schedule'!$K$2:$K$825)), ROW(2:2))), "")} | K5: {=IFERROR(INDEX('Bank Schedule'!L:L, SMALL(IF('Bank Schedule'!$K$2:$K$825="Vacant", ROW('Bank Schedule'!$K$2:$K$825)), ROW(2:2))), "")} | L5: {=IFERROR(INDEX('Bank Schedule'!M:M, SMALL(IF('Bank Schedule'!$K$2:$K$825="Vacant", ROW('Bank Schedule'!$K$2:$K$825)), ROW(2:2))), "")} | M5: {=IFERROR(INDEX('Bank Schedule'!N:N, SMALL(IF('Bank Schedule'!$K$2:$K$825="Vacant", ROW('Bank Schedule'!$K$2:$K$825)), ROW(2:2))), "")} | N5: {=IFERROR(INDEX('Bank Schedule'!O:O, SMALL(IF('Bank Schedule'!$K$2:$K$825="Vacant", ROW('Bank Schedule'!$K$2:$K$825)), ROW(2:2))), "")} | O5: {=IFERROR(INDEX('Bank Schedule'!P:P, SMALL(IF('Bank Schedule'!$K$2:$K$825="Vacant", ROW('Bank Schedule'!$K$2:$K$825)), ROW(2:2))), "")} | P5: {=IFERROR(INDEX('Bank Schedule'!Q:Q, SMALL(IF('Bank Schedule'!$K$2:$K$825="Vacant", ROW('Bank Schedule'!$K$2:$K$825)), ROW(2:2))), "")} | Q5: {=IFERROR(INDEX('Bank Schedule'!R:R, SMALL(IF('Bank Schedule'!$K$2:$K$825="Vacant", ROW('Bank Schedule'!$K$2:$K$825)), ROW(2:2))), "")} | R5: {=IFERROR(INDEX('Bank Schedule'!S:S, SMALL(IF('Bank Schedule'!$K$2:$K$825="Vacant", ROW('Bank Schedule'!$K$2:$K$825)), ROW(2:2))), "")} | S5: {=IFERROR(INDEX('Bank Schedule'!T:T, SMALL(IF('Bank Schedule'!$K$2:$K$825="Vacant", ROW('Bank Schedule'!$K$2:$K$825)), ROW(2:2))), "")} | T5: {=IFERROR(INDEX('Bank Schedule'!U:U, SMALL(IF('Bank Schedule'!$K$2:$K$825="Vacant", ROW('Bank Schedule'!$K$2:$K$825)), ROW(2:2))), "")} | U5: {=IFERROR(INDEX('Bank Schedule'!V:V, SMALL(IF('Bank Schedule'!$K$2:$K$825="Vacant", ROW('Bank Schedule'!$K$2:$K$825)), ROW(2:2))), "")} | V5: {=IFERROR(INDEX('Bank Schedule'!W:W, SMALL(IF('Bank Schedule'!$K$2:$K$825="Vacant", ROW('Bank Schedule'!$K$2:$K$825)), ROW(2:2))), "")} | W5: {=IFERROR(INDEX('Bank Schedule'!X:X, SMALL(IF('Bank Schedule'!$K$2:$K$825="Vacant", ROW('Bank Schedule'!$K$2:$K$825)), ROW(2:2))), "")} | X5: {=IFERROR(INDEX('Bank Schedule'!Y:Y, SMALL(IF('Bank Schedule'!$K$2:$K$825="Vacant", ROW('Bank Schedule'!$K$2:$K$825)), ROW(2:2))), "")} | Y5: {=IFERROR(INDEX('Bank Schedule'!Z:Z, SMALL(IF('Bank Schedule'!$K$2:$K$825="Vacant", ROW('Bank Schedule'!$K$2:$K$825)), ROW(2:2))), "")} | Z5: {=IFERROR(INDEX('Bank Schedule'!AA:AA, SMALL(IF('Bank Schedule'!$K$2:$K$825="Vacant", ROW('Bank Schedule'!$K$2:$K$825)), ROW(2:2))), "")} | AA5: {=IFERROR(INDEX('Bank Schedule'!AB:AB, SMALL(IF('Bank Schedule'!$K$2:$K$825="Vacant", ROW('Bank Schedule'!$K$2:$K$825)), ROW(2:2))), "")} | AB5: {=IFERROR(INDEX('Bank Schedule'!AC:AC, SMALL(IF('Bank Schedule'!$K$2:$K$825="Vacant", ROW('Bank Schedule'!$K$2:$K$825)), ROW(2:2))), "")} | AC5: {=IFERROR(INDEX('Bank Schedule'!AD:AD, SMALL(IF('Bank Schedule'!$K$2:$K$825="Vacant", ROW('Bank Schedule'!$K$2:$K$825)), ROW(2:2))), "")} | AD5: {=IFERROR(INDEX('Bank Schedule'!AE:AE, SMALL(IF('Bank Schedule'!$K$2:$K$825="Vacant", ROW('Bank Schedule'!$K$2:$K$825)), ROW(2:2))), "")} | AE5: {=IFERROR(INDEX('Bank Schedule'!AF:AF, SMALL(IF('Bank Schedule'!$K$2:$K$825="Vacant", ROW('Bank Schedule'!$K$2:$K$825)), ROW(2:2))), "")} | AF5: {=IFERROR(INDEX('Bank Schedule'!AG:AG, SMALL(IF('Bank Schedule'!$K$2:$K$825="Vacant", ROW('Bank Schedule'!$K$2:$K$825)), ROW(2:2))), "")}
A6: {=IFERROR(INDEX('Bank Schedule'!A:A, SMALL(IF('Bank Schedule'!$K$2:$K$825="Vacant", ROW('Bank Schedule'!$K$2:$K$825)), ROW(3:3))), "")} | B6: {=IFERROR(INDEX('Bank Schedule'!B:B, SMALL(IF('Bank Schedule'!$K$2:$K$825="Vacant", ROW('Bank Schedule'!$K$2:$K$825)), ROW(3:3))), "")} | C6: {=IFERROR(INDEX('Bank Schedule'!C:C, SMALL(IF('Bank Schedule'!$K$2:$K$825="Vacant", ROW('Bank Schedule'!$K$2:$K$825)), ROW(3:3))), "")} | D6: {=IFERROR(INDEX('Bank Schedule'!D:D, SMALL(IF('Bank Schedule'!$K$2:$K$825="Vacant", ROW('Bank Schedule'!$K$2:$K$825)), ROW(3:3))), "")} | E6: {=IFERROR(INDEX('Bank Schedule'!E:E, SMALL(IF('Bank Schedule'!$K$2:$K$825="Vacant", ROW('Bank Schedule'!$K$2:$K$825)), ROW(3:3))), "")} | F6: {=IFERROR(INDEX('Bank Schedule'!F:F, SMALL(IF('Bank Schedule'!$K$2:$K$825="Vacant", ROW('Bank Schedule'!$K$2:$K$825)), ROW(3:3))), "")} | G6: {=IFERROR(INDEX('Bank Schedule'!G:G, SMALL(IF('Bank Schedule'!$K$2:$K$825="Vacant", ROW('Bank Schedule'!$K$2:$K$825)), ROW(3:3))), "")} | H6: {=IFERROR(INDEX('Bank Schedule'!H:H, SMALL(IF('Bank Schedule'!$K$2:$K$825="Vacant", ROW('Bank Schedule'!$K$2:$K$825)), ROW(3:3))), "")} | I6: {=IFERROR(INDEX('Bank Schedule'!I:I, SMALL(IF('Bank Schedule'!$K$2:$K$825="Vacant", ROW('Bank Schedule'!$K$2:$K$825)), ROW(3:3))), "")} | J6: {=IFERROR(INDEX('Bank Schedule'!K:K, SMALL(IF('Bank Schedule'!$K$2:$K$825="Vacant", ROW('Bank Schedule'!$K$2:$K$825)), ROW(3:3))), "")} | K6: {=IFERROR(INDEX('Bank Schedule'!L:L, SMALL(IF('Bank Schedule'!$K$2:$K$825="Vacant", ROW('Bank Schedule'!$K$2:$K$825)), ROW(3:3))), "")} | L6: {=IFERROR(INDEX('Bank Schedule'!M:M, SMALL(IF('Bank Schedule'!$K$2:$K$825="Vacant", ROW('Bank Schedule'!$K$2:$K$825)), ROW(3:3))), "")} | M6: {=IFERROR(INDEX('Bank Schedule'!N:N, SMALL(IF('Bank Schedule'!$K$2:$K$825="Vacant", ROW('Bank Schedule'!$K$2:$K$825)), ROW(3:3))), "")} | N6: {=IFERROR(INDEX('Bank Schedule'!O:O, SMALL(IF('Bank Schedule'!$K$2:$K$825="Vacant", ROW('Bank Schedule'!$K$2:$K$825)), ROW(3:3))), "")} | O6: {=IFERROR(INDEX('Bank Schedule'!P:P, SMALL(IF('Bank Schedule'!$K$2:$K$825="Vacant", ROW('Bank Schedule'!$K$2:$K$825)), ROW(3:3))), "")} | P6: {=IFERROR(INDEX('Bank Schedule'!Q:Q, SMALL(IF('Bank Schedule'!$K$2:$K$825="Vacant", ROW('Bank Schedule'!$K$2:$K$825)), ROW(3:3))), "")} | Q6: {=IFERROR(INDEX('Bank Schedule'!R:R, SMALL(IF('Bank Schedule'!$K$2:$K$825="Vacant", ROW('Bank Schedule'!$K$2:$K$825)), ROW(3:3))), "")} | R6: {=IFERROR(INDEX('Bank Schedule'!S:S, SMALL(IF('Bank Schedule'!$K$2:$K$825="Vacant", ROW('Bank Schedule'!$K$2:$K$825)), ROW(3:3))), "")} | S6: {=IFERROR(INDEX('Bank Schedule'!T:T, SMALL(IF('Bank Schedule'!$K$2:$K$825="Vacant", ROW('Bank Schedule'!$K$2:$K$825)), ROW(3:3))), "")} | T6: {=IFERROR(INDEX('Bank Schedule'!U:U, SMALL(IF('Bank Schedule'!$K$2:$K$825="Vacant", ROW('Bank Schedule'!$K$2:$K$825)), ROW(3:3))), "")} | U6: {=IFERROR(INDEX('Bank Schedule'!V:V, SMALL(IF('Bank Schedule'!$K$2:$K$825="Vacant", ROW('Bank Schedule'!$K$2:$K$825)), ROW(3:3))), "")} | V6: {=IFERROR(INDEX('Bank Schedule'!W:W, SMALL(IF('Bank Schedule'!$K$2:$K$825="Vacant", ROW('Bank Schedule'!$K$2:$K$825)), ROW(3:3))), "")} | W6: {=IFERROR(INDEX('Bank Schedule'!X:X, SMALL(IF('Bank Schedule'!$K$2:$K$825="Vacant", ROW('Bank Schedule'!$K$2:$K$825)), ROW(3:3))), "")} | X6: {=IFERROR(INDEX('Bank Schedule'!Y:Y, SMALL(IF('Bank Schedule'!$K$2:$K$825="Vacant", ROW('Bank Schedule'!$K$2:$K$825)), ROW(3:3))), "")} | Y6: {=IFERROR(INDEX('Bank Schedule'!Z:Z, SMALL(IF('Bank Schedule'!$K$2:$K$825="Vacant", ROW('Bank Schedule'!$K$2:$K$825)), ROW(3:3))), "")} | Z6: {=IFERROR(INDEX('Bank Schedule'!AA:AA, SMALL(IF('Bank Schedule'!$K$2:$K$825="Vacant", ROW('Bank Schedule'!$K$2:$K$825)), ROW(3:3))), "")} | AA6: {=IFERROR(INDEX('Bank Schedule'!AB:AB, SMALL(IF('Bank Schedule'!$K$2:$K$825="Vacant", ROW('Bank Schedule'!$K$2:$K$825)), ROW(3:3))), "")} | AB6: {=IFERROR(INDEX('Bank Schedule'!AC:AC, SMALL(IF('Bank Schedule'!$K$2:$K$825="Vacant", ROW('Bank Schedule'!$K$2:$K$825)), ROW(3:3))), "")} | AC6: {=IFERROR(INDEX('Bank Schedule'!AD:AD, SMALL(IF('Bank Schedule'!$K$2:$K$825="Vacant", ROW('Bank Schedule'!$K$2:$K$825)), ROW(3:3))), "")} | AD6: {=IFERROR(INDEX('Bank Schedule'!AE:AE, SMALL(IF('Bank Schedule'!$K$2:$K$825="Vacant", ROW('Bank Schedule'!$K$2:$K$825)), ROW(3:3))), "")} | AE6: {=IFERROR(INDEX('Bank Schedule'!AF:AF, SMALL(IF('Bank Schedule'!$K$2:$K$825="Vacant", ROW('Bank Schedule'!$K$2:$K$825)), ROW(3:3))), "")}
A7: {=IFERROR(INDEX('Bank Schedule'!A:A, SMALL(IF('Bank Schedule'!$K$2:$K$825="Vacant", ROW('Bank Schedule'!$K$2:$K$825)), ROW(4:4))), "")} | B7: {=IFERROR(INDEX('Bank Schedule'!B:B, SMALL(IF('Bank Schedule'!$K$2:$K$825="Vacant", ROW('Bank Schedule'!$K$2:$K$825)), ROW(4:4))), "")} | C7: {=IFERROR(INDEX('Bank Schedule'!C:C, SMALL(IF('Bank Schedule'!$K$2:$K$825="Vacant", ROW('Bank Schedule'!$K$2:$K$825)), ROW(4:4))), "")} | D7: {=IFERROR(INDEX('Bank Schedule'!D:D, SMALL(IF('Bank Schedule'!$K$2:$K$825="Vacant", ROW('Bank Schedule'!$K$2:$K$825)), ROW(4:4))), "")} | E7: {=IFERROR(INDEX('Bank Schedule'!E:E, SMALL(IF('Bank Schedule'!$K$2:$K$825="Vacant", ROW('Bank Schedule'!$K$2:$K$825)), ROW(4:4))), "")} | F7: {=IFERROR(INDEX('Bank Schedule'!F:F, SMALL(IF('Bank Schedule'!$K$2:$K$825="Vacant", ROW('Bank Schedule'!$K$2:$K$825)), ROW(4:4))), "")} | G7: {=IFERROR(INDEX('Bank Schedule'!G:G, SMALL(IF('Bank Schedule'!$K$2:$K$825="Vacant", ROW('Bank Schedule'!$K$2:$K$825)), ROW(4:4))), "")} | H7: {=IFERROR(INDEX('Bank Schedule'!H:H, SMALL(IF('Bank Schedule'!$K$2:$K$825="Vacant", ROW('Bank Schedule'!$K$2:$K$825)), ROW(4:4))), "")} | I7: {=IFERROR(INDEX('Bank Schedule'!I:I, SMALL(IF('Bank Schedule'!$K$2:$K$825="Vacant", ROW('Bank Schedule'!$K$2:$K$825)), ROW(4:4))), "")} | J7: {=IFERROR(INDEX('Bank Schedule'!K:K, SMALL(IF('Bank Schedule'!$K$2:$K$825="Vacant", ROW('Bank Schedule'!$K$2:$K$825)), ROW(4:4))), "")} | K7: {=IFERROR(INDEX('Bank Schedule'!L:L, SMALL(IF('Bank Schedule'!$K$2:$K$825="Vacant", ROW('Bank Schedule'!$K$2:$K$825)), ROW(4:4))), "")} | L7: {=IFERROR(INDEX('Bank Schedule'!M:M, SMALL(IF('Bank Schedule'!$K$2:$K$825="Vacant", ROW('Bank Schedule'!$K$2:$K$825)), ROW(4:4))), "")} | M7: {=IFERROR(INDEX('Bank Schedule'!N:N, SMALL(IF('Bank Schedule'!$K$2:$K$825="Vacant", ROW('Bank Schedule'!$K$2:$K$825)), ROW(4:4))), "")} | N7: {=IFERROR(INDEX('Bank Schedule'!O:O, SMALL(IF('Bank Schedule'!$K$2:$K$825="Vacant", ROW('Bank Schedule'!$K$2:$K$825)), ROW(4:4))), "")} | O7: {=IFERROR(INDEX('Bank Schedule'!P:P, SMALL(IF('Bank Schedule'!$K$2:$K$825="Vacant", ROW('Bank Schedule'!$K$2:$K$825)), ROW(4:4))), "")} | P7: {=IFERROR(INDEX('Bank Schedule'!Q:Q, SMALL(IF('Bank Schedule'!$K$2:$K$825="Vacant", ROW('Bank Schedule'!$K$2:$K$825)), ROW(4:4))), "")} | Q7: {=IFERROR(INDEX('Bank Schedule'!R:R, SMALL(IF('Bank Schedule'!$K$2:$K$825="Vacant", ROW('Bank Schedule'!$K$2:$K$825)), ROW(4:4))), "")} | R7: {=IFERROR(INDEX('Bank Schedule'!S:S, SMALL(IF('Bank Schedule'!$K$2:$K$825="Vacant", ROW('Bank Schedule'!$K$2:$K$825)), ROW(4:4))), "")} | S7: {=IFERROR(INDEX('Bank Schedule'!T:T, SMALL(IF('Bank Schedule'!$K$2:$K$825="Vacant", ROW('Bank Schedule'!$K$2:$K$825)), ROW(4:4))), "")} | T7: {=IFERROR(INDEX('Bank Schedule'!U:U, SMALL(IF('Bank Schedule'!$K$2:$K$825="Vacant", ROW('Bank Schedule'!$K$2:$K$825)), ROW(4:4))), "")} | U7: {=IFERROR(INDEX('Bank Schedule'!V:V, SMALL(IF('Bank Schedule'!$K$2:$K$825="Vacant", ROW('Bank Schedule'!$K$2:$K$825)), ROW(4:4))), "")} | V7: {=IFERROR(INDEX('Bank Schedule'!W:W, SMALL(IF('Bank Schedule'!$K$2:$K$825="Vacant", ROW('Bank Schedule'!$K$2:$K$825)), ROW(4:4))), "")} | W7: {=IFERROR(INDEX('Bank Schedule'!X:X, SMALL(IF('Bank Schedule'!$K$2:$K$825="Vacant", ROW('Bank Schedule'!$K$2:$K$825)), ROW(4:4))), "")} | X7: {=IFERROR(INDEX('Bank Schedule'!Y:Y, SMALL(IF('Bank Schedule'!$K$2:$K$825="Vacant", ROW('Bank Schedule'!$K$2:$K$825)), ROW(4:4))), "")} | Y7: {=IFERROR(INDEX('Bank Schedule'!Z:Z, SMALL(IF('Bank Schedule'!$K$2:$K$825="Vacant", ROW('Bank Schedule'!$K$2:$K$825)), ROW(4:4))), "")} | Z7: {=IFERROR(INDEX('Bank Schedule'!AA:AA, SMALL(IF('Bank Schedule'!$K$2:$K$825="Vacant", ROW('Bank Schedule'!$K$2:$K$825)), ROW(4:4))), "")} | AA7: {=IFERROR(INDEX('Bank Schedule'!AB:AB, SMALL(IF('Bank Schedule'!$K$2:$K$825="Vacant", ROW('Bank Schedule'!$K$2:$K$825)), ROW(4:4))), "")} | AB7: {=IFERROR(INDEX('Bank Schedule'!AC:AC, SMALL(IF('Bank Schedule'!$K$2:$K$825="Vacant", ROW('Bank Schedule'!$K$2:$K$825)), ROW(4:4))), "")} | AC7: {=IFERROR(INDEX('Bank Schedule'!AD:AD, SMALL(IF('Bank Schedule'!$K$2:$K$825="Vacant", ROW('Bank Schedule'!$K$2:$K$825)), ROW(4:4))), "")} | AD7: {=IFERROR(INDEX('Bank Schedule'!AE:AE, SMALL(IF('Bank Schedule'!$K$2:$K$825="Vacant", ROW('Bank Schedule'!$K$2:$K$825)), ROW(4:4))), "")} | AE7: {=IFERROR(INDEX('Bank Schedule'!AF:AF, SMALL(IF('Bank Schedule'!$K$2:$K$825="Vacant", ROW('Bank Schedule'!$K$2:$K$825)), ROW(4:4))), "")} | AF7: {=IFERROR(INDEX('Bank Schedule'!AG:AG, SMALL(IF('Bank Schedule'!$K$2:$K$825="Vacant", ROW('Bank Schedule'!$K$2:$K$825)), ROW(4:4))), "")}
A8: {=IFERROR(INDEX('Bank Schedule'!A:A, SMALL(IF('Bank Schedule'!$K$2:$K$825="Vacant", ROW('Bank Schedule'!$K$2:$K$825)), ROW(5:5))), "")} | B8: {=IFERROR(INDEX('Bank Schedule'!B:B, SMALL(IF('Bank Schedule'!$K$2:$K$825="Vacant", ROW('Bank Schedule'!$K$2:$K$825)), ROW(5:5))), "")} | C8: {=IFERROR(INDEX('Bank Schedule'!C:C, SMALL(IF('Bank Schedule'!$K$2:$K$825="Vacant", ROW('Bank Schedule'!$K$2:$K$825)), ROW(5:5))), "")} | D8: {=IFERROR(INDEX('Bank Schedule'!D:D, SMALL(IF('Bank Schedule'!$K$2:$K$825="Vacant", ROW('Bank Schedule'!$K$2:$K$825)), ROW(5:5))), "")} | E8: {=IFERROR(INDEX('Bank Schedule'!E:E, SMALL(IF('Bank Schedule'!$K$2:$K$825="Vacant", ROW('Bank Schedule'!$K$2:$K$825)), ROW(5:5))), "")} | F8: {=IFERROR(INDEX('Bank Schedule'!F:F, SMALL(IF('Bank Schedule'!$K$2:$K$825="Vacant", ROW('Bank Schedule'!$K$2:$K$825)), ROW(5:5))), "")} | G8: {=IFERROR(INDEX('Bank Schedule'!G:G, SMALL(IF('Bank Schedule'!$K$2:$K$825="Vacant", ROW('Bank Schedule'!$K$2:$K$825)), ROW(5:5))), "")} | H8: {=IFERROR(INDEX('Bank Schedule'!H:H, SMALL(IF('Bank Schedule'!$K$2:$K$825="Vacant", ROW('Bank Schedule'!$K$2:$K$825)), ROW(5:5))), "")} | I8: {=IFERROR(INDEX('Bank Schedule'!I:I, SMALL(IF('Bank Schedule'!$K$2:$K$825="Vacant", ROW('Bank Schedule'!$K$2:$K$825)), ROW(5:5))), "")} | J8: {=IFERROR(INDEX('Bank Schedule'!K:K, SMALL(IF('Bank Schedule'!$K$2:$K$825="Vacant", ROW('Bank Schedule'!$K$2:$K$825)), ROW(5:5))), "")} | K8: {=IFERROR(INDEX('Bank Schedule'!L:L, SMALL(IF('Bank Schedule'!$K$2:$K$825="Vacant", ROW('Bank Schedule'!$K$2:$K$825)), ROW(5:5))), "")} | L8: {=IFERROR(INDEX('Bank Schedule'!M:M, SMALL(IF('Bank Schedule'!$K$2:$K$825="Vacant", ROW('Bank Schedule'!$K$2:$K$825)), ROW(5:5))), "")} | M8: {=IFERROR(INDEX('Bank Schedule'!N:N, SMALL(IF('Bank Schedule'!$K$2:$K$825="Vacant", ROW('Bank Schedule'!$K$2:$K$825)), ROW(5:5))), "")} | N8: {=IFERROR(INDEX('Bank Schedule'!O:O, SMALL(IF('Bank Schedule'!$K$2:$K$825="Vacant", ROW('Bank Schedule'!$K$2:$K$825)), ROW(5:5))), "")} | O8: {=IFERROR(INDEX('Bank Schedule'!P:P, SMALL(IF('Bank Schedule'!$K$2:$K$825="Vacant", ROW('Bank Schedule'!$K$2:$K$825)), ROW(5:5))), "")} | P8: {=IFERROR(INDEX('Bank Schedule'!Q:Q, SMALL(IF('Bank Schedule'!$K$2:$K$825="Vacant", ROW('Bank Schedule'!$K$2:$K$825)), ROW(5:5))), "")} | Q8: {=IFERROR(INDEX('Bank Schedule'!R:R, SMALL(IF('Bank Schedule'!$K$2:$K$825="Vacant", ROW('Bank Schedule'!$K$2:$K$825)), ROW(5:5))), "")} | R8: {=IFERROR(INDEX('Bank Schedule'!S:S, SMALL(IF('Bank Schedule'!$K$2:$K$825="Vacant", ROW('Bank Schedule'!$K$2:$K$825)), ROW(5:5))), "")} | S8: {=IFERROR(INDEX('Bank Schedule'!T:T, SMALL(IF('Bank Schedule'!$K$2:$K$825="Vacant", ROW('Bank Schedule'!$K$2:$K$825)), ROW(5:5))), "")} | T8: {=IFERROR(INDEX('Bank Schedule'!U:U, SMALL(IF('Bank Schedule'!$K$2:$K$825="Vacant", ROW('Bank Schedule'!$K$2:$K$825)), ROW(5:5))), "")} | U8: {=IFERROR(INDEX('Bank Schedule'!V:V, SMALL(IF('Bank Schedule'!$K$2:$K$825="Vacant", ROW('Bank Schedule'!$K$2:$K$825)), ROW(5:5))), "")} | V8: {=IFERROR(INDEX('Bank Schedule'!W:W, SMALL(IF('Bank Schedule'!$K$2:$K$825="Vacant", ROW('Bank Schedule'!$K$2:$K$825)), ROW(5:5))), "")} | W8: {=IFERROR(INDEX('Bank Schedule'!X:X, SMALL(IF('Bank Schedule'!$K$2:$K$825="Vacant", ROW('Bank Schedule'!$K$2:$K$825)), ROW(5:5))), "")} | X8: {=IFERROR(INDEX('Bank Schedule'!Y:Y, SMALL(IF('Bank Schedule'!$K$2:$K$825="Vacant", ROW('Bank Schedule'!$K$2:$K$825)), ROW(5:5))), "")} | Y8: {=IFERROR(INDEX('Bank Schedule'!Z:Z, SMALL(IF('Bank Schedule'!$K$2:$K$825="Vacant", ROW('Bank Schedule'!$K$2:$K$825)), ROW(5:5))), "")} | Z8: {=IFERROR(INDEX('Bank Schedule'!AA:AA, SMALL(IF('Bank Schedule'!$K$2:$K$825="Vacant", ROW('Bank Schedule'!$K$2:$K$825)), ROW(5:5))), "")} | AA8: {=IFERROR(INDEX('Bank Schedule'!AB:AB, SMALL(IF('Bank Schedule'!$K$2:$K$825="Vacant", ROW('Bank Schedule'!$K$2:$K$825)), ROW(5:5))), "")} | AB8: {=IFERROR(INDEX('Bank Schedule'!AC:AC, SMALL(IF('Bank Schedule'!$K$2:$K$825="Vacant", ROW('Bank Schedule'!$K$2:$K$825)), ROW(5:5))), "")} | AC8: {=IFERROR(INDEX('Bank Schedule'!AD:AD, SMALL(IF('Bank Schedule'!$K$2:$K$825="Vacant", ROW('Bank Schedule'!$K$2:$K$825)), ROW(5:5))), "")} | AD8: {=IFERROR(INDEX('Bank Schedule'!AE:AE, SMALL(IF('Bank Schedule'!$K$2:$K$825="Vacant", ROW('Bank Schedule'!$K$2:$K$825)), ROW(5:5))), "")} | AE8: {=IFERROR(INDEX('Bank Schedule'!AF:AF, SMALL(IF('Bank Schedule'!$K$2:$K$825="Vacant", ROW('Bank Schedule'!$K$2:$K$825)), ROW(5:5))), "")}
A9: {=IFERROR(INDEX('Bank Schedule'!A:A, SMALL(IF('Bank Schedule'!$K$2:$K$825="Vacant", ROW('Bank Schedule'!$K$2:$K$825)), ROW(6:6))), "")} | B9: {=IFERROR(INDEX('Bank Schedule'!B:B, SMALL(IF('Bank Schedule'!$K$2:$K$825="Vacant", ROW('Bank Schedule'!$K$2:$K$825)), ROW(6:6))), "")} | C9: {=IFERROR(INDEX('Bank Schedule'!C:C, SMALL(IF('Bank Schedule'!$K$2:$K$825="Vacant", ROW('Bank Schedule'!$K$2:$K$825)), ROW(6:6))), "")} | D9: {=IFERROR(INDEX('Bank Schedule'!D:D, SMALL(IF('Bank Schedule'!$K$2:$K$825="Vacant", ROW('Bank Schedule'!$K$2:$K$825)), ROW(6:6))), "")} | E9: {=IFERROR(INDEX('Bank Schedule'!E:E, SMALL(IF('Bank Schedule'!$K$2:$K$825="Vacant", ROW('Bank Schedule'!$K$2:$K$825)), ROW(6:6))), "")} | F9: {=IFERROR(INDEX('Bank Schedule'!F:F, SMALL(IF('Bank Schedule'!$K$2:$K$825="Vacant", ROW('Bank Schedule'!$K$2:$K$825)), ROW(6:6))), "")} | G9: {=IFERROR(INDEX('Bank Schedule'!G:G, SMALL(IF('Bank Schedule'!$K$2:$K$825="Vacant", ROW('Bank Schedule'!$K$2:$K$825)), ROW(6:6))), "")} | H9: {=IFERROR(INDEX('Bank Schedule'!H:H, SMALL(IF('Bank Schedule'!$K$2:$K$825="Vacant", ROW('Bank Schedule'!$K$2:$K$825)), ROW(6:6))), "")} | I9: {=IFERROR(INDEX('Bank Schedule'!I:I, SMALL(IF('Bank Schedule'!$K$2:$K$825="Vacant", ROW('Bank Schedule'!$K$2:$K$825)), ROW(6:6))), "")} | J9: {=IFERROR(INDEX('Bank Schedule'!K:K, SMALL(IF('Bank Schedule'!$K$2:$K$825="Vacant", ROW('Bank Schedule'!$K$2:$K$825)), ROW(6:6))), "")} | K9: {=IFERROR(INDEX('Bank Schedule'!L:L, SMALL(IF('Bank Schedule'!$K$2:$K$825="Vacant", ROW('Bank Schedule'!$K$2:$K$825)), ROW(6:6))), "")} | L9: {=IFERROR(INDEX('Bank Schedule'!M:M, SMALL(IF('Bank Schedule'!$K$2:$K$825="Vacant", ROW('Bank Schedule'!$K$2:$K$825)), ROW(6:6))), "")} | M9: {=IFERROR(INDEX('Bank Schedule'!N:N, SMALL(IF('Bank Schedule'!$K$2:$K$825="Vacant", ROW('Bank Schedule'!$K$2:$K$825)), ROW(6:6))), "")} | N9: {=IFERROR(INDEX('Bank Schedule'!O:O, SMALL(IF('Bank Schedule'!$K$2:$K$825="Vacant", ROW('Bank Schedule'!$K$2:$K$825)), ROW(6:6))), "")} | O9: {=IFERROR(INDEX('Bank Schedule'!P:P, SMALL(IF('Bank Schedule'!$K$2:$K$825="Vacant", ROW('Bank Schedule'!$K$2:$K$825)), ROW(6:6))), "")} | P9: {=IFERROR(INDEX('Bank Schedule'!Q:Q, SMALL(IF('Bank Schedule'!$K$2:$K$825="Vacant", ROW('Bank Schedule'!$K$2:$K$825)), ROW(6:6))), "")} | Q9: {=IFERROR(INDEX('Bank Schedule'!R:R, SMALL(IF('Bank Schedule'!$K$2:$K$825="Vacant", ROW('Bank Schedule'!$K$2:$K$825)), ROW(6:6))), "")} | R9: {=IFERROR(INDEX('Bank Schedule'!S:S, SMALL(IF('Bank Schedule'!$K$2:$K$825="Vacant", ROW('Bank Schedule'!$K$2:$K$825)), ROW(6:6))), "")} | S9: {=IFERROR(INDEX('Bank Schedule'!T:T, SMALL(IF('Bank Schedule'!$K$2:$K$825="Vacant", ROW('Bank Schedule'!$K$2:$K$825)), ROW(6:6))), "")} | T9: {=IFERROR(INDEX('Bank Schedule'!U:U, SMALL(IF('Bank Schedule'!$K$2:$K$825="Vacant", ROW('Bank Schedule'!$K$2:$K$825)), ROW(6:6))), "")} | U9: {=IFERROR(INDEX('Bank Schedule'!V:V, SMALL(IF('Bank Schedule'!$K$2:$K$825="Vacant", ROW('Bank Schedule'!$K$2:$K$825)), ROW(6:6))), "")} | V9: {=IFERROR(INDEX('Bank Schedule'!W:W, SMALL(IF('Bank Schedule'!$K$2:$K$825="Vacant", ROW('Bank Schedule'!$K$2:$K$825)), ROW(6:6))), "")} | W9: {=IFERROR(INDEX('Bank Schedule'!X:X, SMALL(IF('Bank Schedule'!$K$2:$K$825="Vacant", ROW('Bank Schedule'!$K$2:$K$825)), ROW(6:6))), "")} | X9: {=IFERROR(INDEX('Bank Schedule'!Y:Y, SMALL(IF('Bank Schedule'!$K$2:$K$825="Vacant", ROW('Bank Schedule'!$K$2:$K$825)), ROW(6:6))), "")} | Y9: {=IFERROR(INDEX('Bank Schedule'!Z:Z, SMALL(IF('Bank Schedule'!$K$2:$K$825="Vacant", ROW('Bank Schedule'!$K$2:$K$825)), ROW(6:6))), "")} | Z9: {=IFERROR(INDEX('Bank Schedule'!AA:AA, SMALL(IF('Bank Schedule'!$K$2:$K$825="Vacant", ROW('Bank Schedule'!$K$2:$K$825)), ROW(6:6))), "")} | AA9: {=IFERROR(INDEX('Bank Schedule'!AB:AB, SMALL(IF('Bank Schedule'!$K$2:$K$825="Vacant", ROW('Bank Schedule'!$K$2:$K$825)), ROW(6:6))), "")} | AB9: {=IFERROR(INDEX('Bank Schedule'!AC:AC, SMALL(IF('Bank Schedule'!$K$2:$K$825="Vacant", ROW('Bank Schedule'!$K$2:$K$825)), ROW(6:6))), "")} | AC9: {=IFERROR(INDEX('Bank Schedule'!AD:AD, SMALL(IF('Bank Schedule'!$K$2:$K$825="Vacant", ROW('Bank Schedule'!$K$2:$K$825)), ROW(6:6))), "")} | AD9: {=IFERROR(INDEX('Bank Schedule'!AE:AE, SMALL(IF('Bank Schedule'!$K$2:$K$825="Vacant", ROW('Bank Schedule'!$K$2:$K$825)), ROW(6:6))), "")} | AE9: {=IFERROR(INDEX('Bank Schedule'!AF:AF, SMALL(IF('Bank Schedule'!$K$2:$K$825="Vacant", ROW('Bank Schedule'!$K$2:$K$825)), ROW(6:6))), "")}
A10: {=IFERROR(INDEX('Bank Schedule'!A:A, SMALL(IF('Bank Schedule'!$K$2:$K$825="Vacant", ROW('Bank Schedule'!$K$2:$K$825)), ROW(7:7))), "")} | B10: {=IFERROR(INDEX('Bank Schedule'!B:B, SMALL(IF('Bank Schedule'!$K$2:$K$825="Vacant", ROW('Bank Schedule'!$K$2:$K$825)), ROW(7:7))), "")} | C10: {=IFERROR(INDEX('Bank Schedule'!C:C, SMALL(IF('Bank Schedule'!$K$2:$K$825="Vacant", ROW('Bank Schedule'!$K$2:$K$825)), ROW(7:7))), "")} | D10: {=IFERROR(INDEX('Bank Schedule'!D:D, SMALL(IF('Bank Schedule'!$K$2:$K$825="Vacant", ROW('Bank Schedule'!$K$2:$K$825)), ROW(7:7))), "")} | E10: {=IFERROR(INDEX('Bank Schedule'!E:E, SMALL(IF('Bank Schedule'!$K$2:$K$825="Vacant", ROW('Bank Schedule'!$K$2:$K$825)), ROW(7:7))), "")} | F10: {=IFERROR(INDEX('Bank Schedule'!F:F, SMALL(IF('Bank Schedule'!$K$2:$K$825="Vacant", ROW('Bank Schedule'!$K$2:$K$825)), ROW(7:7))), "")} | G10: {=IFERROR(INDEX('Bank Schedule'!G:G, SMALL(IF('Bank Schedule'!$K$2:$K$825="Vacant", ROW('Bank Schedule'!$K$2:$K$825)), ROW(7:7))), "")} | H10: {=IFERROR(INDEX('Bank Schedule'!H:H, SMALL(IF('Bank Schedule'!$K$2:$K$825="Vacant", ROW('Bank Schedule'!$K$2:$K$825)), ROW(7:7))), "")} | I10: {=IFERROR(INDEX('Bank Schedule'!I:I, SMALL(IF('Bank Schedule'!$K$2:$K$825="Vacant", ROW('Bank Schedule'!$K$2:$K$825)), ROW(7:7))), "")} | J10: {=IFERROR(INDEX('Bank Schedule'!K:K, SMALL(IF('Bank Schedule'!$K$2:$K$825="Vacant", ROW('Bank Schedule'!$K$2:$K$825)), ROW(7:7))), "")} | K10: {=IFERROR(INDEX('Bank Schedule'!L:L, SMALL(IF('Bank Schedule'!$K$2:$K$825="Vacant", ROW('Bank Schedule'!$K$2:$K$825)), ROW(7:7))), "")} | L10: {=IFERROR(INDEX('Bank Schedule'!M:M, SMALL(IF('Bank Schedule'!$K$2:$K$825="Vacant", ROW('Bank Schedule'!$K$2:$K$825)), ROW(7:7))), "")} | M10: {=IFERROR(INDEX('Bank Schedule'!N:N, SMALL(IF('Bank Schedule'!$K$2:$K$825="Vacant", ROW('Bank Schedule'!$K$2:$K$825)), ROW(7:7))), "")} | N10: {=IFERROR(INDEX('Bank Schedule'!O:O, SMALL(IF('Bank Schedule'!$K$2:$K$825="Vacant", ROW('Bank Schedule'!$K$2:$K$825)), ROW(7:7))), "")} | O10: {=IFERROR(INDEX('Bank Schedule'!P:P, SMALL(IF('Bank Schedule'!$K$2:$K$825="Vacant", ROW('Bank Schedule'!$K$2:$K$825)), ROW(7:7))), "")} | P10: {=IFERROR(INDEX('Bank Schedule'!Q:Q, SMALL(IF('Bank Schedule'!$K$2:$K$825="Vacant", ROW('Bank Schedule'!$K$2:$K$825)), ROW(7:7))), "")} | Q10: {=IFERROR(INDEX('Bank Schedule'!R:R, SMALL(IF('Bank Schedule'!$K$2:$K$825="Vacant", ROW('Bank Schedule'!$K$2:$K$825)), ROW(7:7))), "")} | R10: {=IFERROR(INDEX('Bank Schedule'!S:S, SMALL(IF('Bank Schedule'!$K$2:$K$825="Vacant", ROW('Bank Schedule'!$K$2:$K$825)), ROW(7:7))), "")} | S10: {=IFERROR(INDEX('Bank Schedule'!T:T, SMALL(IF('Bank Schedule'!$K$2:$K$825="Vacant", ROW('Bank Schedule'!$K$2:$K$825)), ROW(7:7))), "")} | T10: {=IFERROR(INDEX('Bank Schedule'!U:U, SMALL(IF('Bank Schedule'!$K$2:$K$825="Vacant", ROW('Bank Schedule'!$K$2:$K$825)), ROW(7:7))), "")} | U10: {=IFERROR(INDEX('Bank Schedule'!V:V, SMALL(IF('Bank Schedule'!$K$2:$K$825="Vacant", ROW('Bank Schedule'!$K$2:$K$825)), ROW(7:7))), "")} | V10: {=IFERROR(INDEX('Bank Schedule'!W:W, SMALL(IF('Bank Schedule'!$K$2:$K$825="Vacant", ROW('Bank Schedule'!$K$2:$K$825)), ROW(7:7))), "")} | W10: {=IFERROR(INDEX('Bank Schedule'!X:X, SMALL(IF('Bank Schedule'!$K$2:$K$825="Vacant", ROW('Bank Schedule'!$K$2:$K$825)), ROW(7:7))), "")} | X10: {=IFERROR(INDEX('Bank Schedule'!Y:Y, SMALL(IF('Bank Schedule'!$K$2:$K$825="Vacant", ROW('Bank Schedule'!$K$2:$K$825)), ROW(7:7))), "")} | Y10: {=IFERROR(INDEX('Bank Schedule'!Z:Z, SMALL(IF('Bank Schedule'!$K$2:$K$825="Vacant", ROW('Bank Schedule'!$K$2:$K$825)), ROW(7:7))), "")} | Z10: {=IFERROR(INDEX('Bank Schedule'!AA:AA, SMALL(IF('Bank Schedule'!$K$2:$K$825="Vacant", ROW('Bank Schedule'!$K$2:$K$825)), ROW(7:7))), "")} | AA10: {=IFERROR(INDEX('Bank Schedule'!AB:AB, SMALL(IF('Bank Schedule'!$K$2:$K$825="Vacant", ROW('Bank Schedule'!$K$2:$K$825)), ROW(7:7))), "")} | AB10: {=IFERROR(INDEX('Bank Schedule'!AC:AC, SMALL(IF('Bank Schedule'!$K$2:$K$825="Vacant", ROW('Bank Schedule'!$K$2:$K$825)), ROW(7:7))), "")} | AC10: {=IFERROR(INDEX('Bank Schedule'!AD:AD, SMALL(IF('Bank Schedule'!$K$2:$K$825="Vacant", ROW('Bank Schedule'!$K$2:$K$825)), ROW(7:7))), "")} | AD10: {=IFERROR(INDEX('Bank Schedule'!AE:AE, SMALL(IF('Bank Schedule'!$K$2:$K$825="Vacant", ROW('Bank Schedule'!$K$2:$K$825)), ROW(7:7))), "")} | AE10: {=IFERROR(INDEX('Bank Schedule'!AF:AF, SMALL(IF('Bank Schedule'!$K$2:$K$825="Vacant", ROW('Bank Schedule'!$K$2:$K$825)), ROW(7:7))), "")} | AF10: {=IFERROR(INDEX('Bank Schedule'!AG:AG, SMALL(IF('Bank Schedule'!$K$2:$K$825="Vacant", ROW('Bank Schedule'!$K$2:$K$825)), ROW(7:7))), "")}
A11: {=IFERROR(INDEX('Bank Schedule'!A:A, SMALL(IF('Bank Schedule'!$K$2:$K$825="Vacant", ROW('Bank Schedule'!$K$2:$K$825)), ROW(8:8))), "")} | B11: {=IFERROR(INDEX('Bank Schedule'!B:B, SMALL(IF('Bank Schedule'!$K$2:$K$825="Vacant", ROW('Bank Schedule'!$K$2:$K$825)), ROW(8:8))), "")} | C11: {=IFERROR(INDEX('Bank Schedule'!C:C, SMALL(IF('Bank Schedule'!$K$2:$K$825="Vacant", ROW('Bank Schedule'!$K$2:$K$825)), ROW(8:8))), "")} | D11: {=IFERROR(INDEX('Bank Schedule'!D:D, SMALL(IF('Bank Schedule'!$K$2:$K$825="Vacant", ROW('Bank Schedule'!$K$2:$K$825)), ROW(8:8))), "")} | E11: {=IFERROR(INDEX('Bank Schedule'!E:E, SMALL(IF('Bank Schedule'!$K$2:$K$825="Vacant", ROW('Bank Schedule'!$K$2:$K$825)), ROW(8:8))), "")} | F11: {=IFERROR(INDEX('Bank Schedule'!F:F, SMALL(IF('Bank Schedule'!$K$2:$K$825="Vacant", ROW('Bank Schedule'!$K$2:$K$825)), ROW(8:8))), "")} | G11: {=IFERROR(INDEX('Bank Schedule'!G:G, SMALL(IF('Bank Schedule'!$K$2:$K$825="Vacant", ROW('Bank Schedule'!$K$2:$K$825)), ROW(8:8))), "")} | H11: {=IFERROR(INDEX('Bank Schedule'!H:H, SMALL(IF('Bank Schedule'!$K$2:$K$825="Vacant", ROW('Bank Schedule'!$K$2:$K$825)), ROW(8:8))), "")} | I11: {=IFERROR(INDEX('Bank Schedule'!I:I, SMALL(IF('Bank Schedule'!$K$2:$K$825="Vacant", ROW('Bank Schedule'!$K$2:$K$825)), ROW(8:8))), "")} | J11: {=IFERROR(INDEX('Bank Schedule'!K:K, SMALL(IF('Bank Schedule'!$K$2:$K$825="Vacant", ROW('Bank Schedule'!$K$2:$K$825)), ROW(8:8))), "")} | K11: {=IFERROR(INDEX('Bank Schedule'!L:L, SMALL(IF('Bank Schedule'!$K$2:$K$825="Vacant", ROW('Bank Schedule'!$K$2:$K$825)), ROW(8:8))), "")} | L11: {=IFERROR(INDEX('Bank Schedule'!M:M, SMALL(IF('Bank Schedule'!$K$2:$K$825="Vacant", ROW('Bank Schedule'!$K$2:$K$825)), ROW(8:8))), "")} | M11: {=IFERROR(INDEX('Bank Schedule'!N:N, SMALL(IF('Bank Schedule'!$K$2:$K$825="Vacant", ROW('Bank Schedule'!$K$2:$K$825)), ROW(8:8))), "")} | N11: {=IFERROR(INDEX('Bank Schedule'!O:O, SMALL(IF('Bank Schedule'!$K$2:$K$825="Vacant", ROW('Bank Schedule'!$K$2:$K$825)), ROW(8:8))), "")} | O11: {=IFERROR(INDEX('Bank Schedule'!P:P, SMALL(IF('Bank Schedule'!$K$2:$K$825="Vacant", ROW('Bank Schedule'!$K$2:$K$825)), ROW(8:8))), "")} | P11: {=IFERROR(INDEX('Bank Schedule'!Q:Q, SMALL(IF('Bank Schedule'!$K$2:$K$825="Vacant", ROW('Bank Schedule'!$K$2:$K$825)), ROW(8:8))), "")} | Q11: {=IFERROR(INDEX('Bank Schedule'!R:R, SMALL(IF('Bank Schedule'!$K$2:$K$825="Vacant", ROW('Bank Schedule'!$K$2:$K$825)), ROW(8:8))), "")} | R11: {=IFERROR(INDEX('Bank Schedule'!S:S, SMALL(IF('Bank Schedule'!$K$2:$K$825="Vacant", ROW('Bank Schedule'!$K$2:$K$825)), ROW(8:8))), "")} | S11: {=IFERROR(INDEX('Bank Schedule'!T:T, SMALL(IF('Bank Schedule'!$K$2:$K$825="Vacant", ROW('Bank Schedule'!$K$2:$K$825)), ROW(8:8))), "")} | T11: {=IFERROR(INDEX('Bank Schedule'!U:U, SMALL(IF('Bank Schedule'!$K$2:$K$825="Vacant", ROW('Bank Schedule'!$K$2:$K$825)), ROW(8:8))), "")} | U11: {=IFERROR(INDEX('Bank Schedule'!V:V, SMALL(IF('Bank Schedule'!$K$2:$K$825="Vacant", ROW('Bank Schedule'!$K$2:$K$825)), ROW(8:8))), "")} | V11: {=IFERROR(INDEX('Bank Schedule'!W:W, SMALL(IF('Bank Schedule'!$K$2:$K$825="Vacant", ROW('Bank Schedule'!$K$2:$K$825)), ROW(8:8))), "")} | W11: {=IFERROR(INDEX('Bank Schedule'!X:X, SMALL(IF('Bank Schedule'!$K$2:$K$825="Vacant", ROW('Bank Schedule'!$K$2:$K$825)), ROW(8:8))), "")} | X11: {=IFERROR(INDEX('Bank Schedule'!Y:Y, SMALL(IF('Bank Schedule'!$K$2:$K$825="Vacant", ROW('Bank Schedule'!$K$2:$K$825)), ROW(8:8))), "")} | Y11: {=IFERROR(INDEX('Bank Schedule'!Z:Z, SMALL(IF('Bank Schedule'!$K$2:$K$825="Vacant", ROW('Bank Schedule'!$K$2:$K$825)), ROW(8:8))), "")} | Z11: {=IFERROR(INDEX('Bank Schedule'!AA:AA, SMALL(IF('Bank Schedule'!$K$2:$K$825="Vacant", ROW('Bank Schedule'!$K$2:$K$825)), ROW(8:8))), "")} | AA11: {=IFERROR(INDEX('Bank Schedule'!AB:AB, SMALL(IF('Bank Schedule'!$K$2:$K$825="Vacant", ROW('Bank Schedule'!$K$2:$K$825)), ROW(8:8))), "")} | AB11: {=IFERROR(INDEX('Bank Schedule'!AC:AC, SMALL(IF('Bank Schedule'!$K$2:$K$825="Vacant", ROW('Bank Schedule'!$K$2:$K$825)), ROW(8:8))), "")} | AC11: {=IFERROR(INDEX('Bank Schedule'!AD:AD, SMALL(IF('Bank Schedule'!$K$2:$K$825="Vacant", ROW('Bank Schedule'!$K$2:$K$825)), ROW(8:8))), "")} | AD11: {=IFERROR(INDEX('Bank Schedule'!AE:AE, SMALL(IF('Bank Schedule'!$K$2:$K$825="Vacant", ROW('Bank Schedule'!$K$2:$K$825)), ROW(8:8))), "")} | AE11: {=IFERROR(INDEX('Bank Schedule'!AF:AF, SMALL(IF('Bank Schedule'!$K$2:$K$825="Vacant", ROW('Bank Schedule'!$K$2:$K$825)), ROW(8:8))), "")}
