Workbook

Sheet Bank Schedule
C1: Hide | D1: Hide | E1: Hide
C2: Hide | D2: Hide | E2: Hide | I2: Hide | J2: Hide | R2: Hide | S2: Hide | U2: Hide | W2: Hide | AE2: Hide | AF2: Hide | AG2: Hide | AH2: Hide
B3: Surveyor | C3: Client | D3: Property Number | E3: Property | F3: Unit Demise | G3: Unit Type | H3: Net Area | I3: . | J3: Agency Area group | K3: Tenant Name | L3: Start Date | M3: Expiry Date | N3: Vacant Since? | O3: RRs | P3: Break Date | Q3: Rent PA (£) | R3: check 1 | S3: check 2 | T3: 2023 ERV (£) | U3: check 3 | V3: 2024 ERV (£) | W3: check 4 | X3: ERV 2024 £.Sq.ft | Y3: ERV Variation | Z3: EPC | AA3: * | AB3: 2024 Cap Valn. (£) | AC3: 1954 Act Protected | AD3: Remarks | AE3: Agency Quoting Rent £.sq.ft | AF3: Monthly Viewings | AG3: Total Viewings | AH3: Marketing Agent | AI3: NEW COLUMN | AJ3: other column
AI4: 1 | AJ4: 44026
G5: 5-6 Bywell Place
AI6: 1
B7: JM | C7: MEL | D7: 550020 | E7: 5-6 Bywell Place | F7: Whole Building | G7: Office | H7: 2011 | I7: =H7 -> 2011 | J7: 2000 | K7: 111 Skin Limited | L7: 45365 | M7: 47190 | P7: 46459 | Q7: 115500 | R7: =Q7 -> 115500 | S7: =R7 -> 115500 | T7: 100600 | U7: =T7 -> 100600 | V7: 115000 | W7: =V7 -> 115000 | X7: =V7/H7 -> 57.18548 | Y7: =SUM(V7-T7)/T7 -> 0.14314115 | Z7: C | AB7: 1825000 | AC7: No | AD7: Tenant break on 6 months notice. Break penalty of £28,875 if exercised.
F8: 5/6 Bywell Place | H8: =SUM(H7) -> 2011 | AI8: 2
G9: 22 and 23-25 Eastcastle Street
B11: SH | C11: MEL | D11: 550910 | E11: 22 and 23-25 Eastcastle Street | F11: Lower Ground & Ground (22) | G11: Retail | H11: 2333 | I11: =H11 -> 2333 | J11: 2000 | K11: Top Bridal Ltd | L11: 45736 | M11: 47561 | P11: 46831 | Q11: 128000 | R11: =Q11 -> 128000 | T11: 110000 | U11: =T11 -> 110000 | V11: 108100 | W11: =V11 -> 108100 | X11: =V11/H11 -> 46.335191 | Y11: =SUM(V11-T11)/T11 -> -0.017272727 | Z11: C | AC11: No | AD11: Stepped rent increasing to £130,000 wef 20/03/27. Tenant break on 6 months notice. | AF11: 1 | AG11: 3 | AI11: 4
B12: SH | C12: MEL | D12: 550910 | E12: 22 and 23-25 Eastcastle Street | F12: Lower Ground & Ground (23-25) | G12: Gallery | H12: 6092 | I12: =H12 -> 6092 | J12: 6000 | K12: Sisters Grimm Ltd | L12: 45712 | M12: 47537 | P12: 46806 | Q12: 325000 | R12: =Q12 -> 325000 | T12: 225000 | U12: =T12 -> 225000 | V12: 226100 | W12: =V12 -> 226100 | X12: =V12/H12 -> 37.114248 | Y12: =SUM(V12-T12)/T12 -> 0.0048888889 | Z12: B | AC12: No | AD12: Tenant break on 6 months notice. 1 month rent free from 24/02/28 if break not excerised. | AG12: 3 | AH12: LEM
B13: SH | C13: MEL | D13: 550910 | E13: 22 and 23-25 Eastcastle Street | F13: First Floor (22) | G13: Office | H13: 1063 | I13: =H13 -> 1063 | J13: 1000 | K13: Peter Alexander UK Ltd | L13: 45551 | M13: 47376 | P13: 46645 | Q13: 61425 | R13: =Q13 -> 61425 | T13: 55700 | U13: =T13 -> 55700 | V13: 61100 | W13: =V13 -> 61100 | X13: =V13/H13 -> 57.478833 | Y13: =SUM(V13-T13)/T13 -> 0.096947935 | Z13: D | AC13: No | AD13: Tenant break on 3 months notice. Additional 3 months rent free if not exercised. | AH13: LEM
B14: SH | C14: MEL | D14: 550910 | E14: 22 and 23-25 Eastcastle Street | F14: First Floor (23-25) | G14: Office | H14: 2220 | I14: =H14 -> 2220 | J14: 2000 | K14: Cord Technologies Ltd | L14: 45086 | M14: 46181 | Q14: 131400 | R14: =Q14 -> 131400 | T14: 131100 | U14: =T14 -> 131100 | V14: 133200 | W14: =V14 -> 133200 | X14: =V14/H14 -> 60 | Y14: =SUM(V14-T14)/T14 -> 0.016018307 | Z14: D | AC14: No | AD14: Tenant break passed.
B15: SH | C15: MEL | D15: 550910 | E15: 22 and 23-25 Eastcastle Street | F15: Second Floor (22) | G15: Office | H15: 1124 | I15: =H15 -> 1124 | J15: 1000 | K15: Cord Technologies Ltd | L15: 45614 | M15: 46181 | Q15: 71875 | R15: =Q15 -> 71875 | T15: 60400 | U15: =T15 -> 60400 | V15: 61800 | W15: =V15 -> 61800 | X15: =V15/H15 -> 54.982206 | Y15: =SUM(V15-T15)/T15 -> 0.023178808 | Z15: B | AC15: No | AD15: Tenant break passed.
B16: SH | C16: MEL | D16: 550910 | E16: 22 and 23-25 Eastcastle Street | F16: Second Floor (23-25) | G16: Office | H16: 2238 | I16: =H16 -> 2238 | J16: 2000 | K16: Vacant | N16: 45636 | Q16: 0 | R16: =Q16 -> 0 | T16: 134300 | U16: =T16 -> 134300 | V16: 134300 | W16: =V16 -> 134300 | X16: =V16/H16 -> 60.008937 | Y16: =SUM(V16-T16)/T16 -> 0 | Z16: D | AC16: No | AD16: LEM marketing. | AF16: 2 | AG16: 2
B17: SH | C17: MEL | D17: 550910 | E17: 22 and 23-25 Eastcastle Street | F17: Third Floor (22) | G17: Office | H17: 400 | I17: =H17 -> 400 | J17: 500 | K17: Vacant | N17: 45771 | Q17: 0 | R17: =Q17 -> 0 | T17: 20600 | U17: =T17 -> 20600 | V17: 23000 | W17: =V17 -> 23000 | X17: =V17/H17 -> 57.5 | Y17: =SUM(V17-T17)/T17 -> 0.11650485 | Z17: D | AC17: No | AD17: LEM marketing. | AF17: 1 | AG17: 1
B18: SH | C18: MEL | D18: 550910 | E18: 22 and 23-25 Eastcastle Street | F18: Third Floor (23-25) | G18: Office | H18: 1938 | I18: =H18 -> 1938 | J18: 2000 | K18: Vacant | N18: 45217 | Q18: 0 | R18: =Q18 -> 0 | T18: 109000 | U18: =T18 -> 109000 | V18: 111400 | W18: =V18 -> 111400 | X18: =V18/H18 -> 57.48194 | Y18: =SUM(V18-T18)/T18 -> 0.022018349 | Z18: D | AC18: No | AD18: LEM marketing. | AE18: 65 | AF18: 2 | AG18: 4
B19: SH | C19: MEL | D19: 550910 | E19: 22 and 23-25 Eastcastle Street | F19: Fourth Floor (22) | G19: Office | H19: 419 | I19: =H19 -> 419 | J19: 500 | K19: Element Pictures UK Ltd. | L19: 44539 | M19: 46364 | Q19: 23940 | R19: =Q19 -> 23940 | T19: 21000 | U19: =T19 -> 21000 | V19: 24100 | W19: =V19 -> 24100 | X19: =V19/H19 -> 57.5179 | Y19: =SUM(V19-T19)/T19 -> 0.14761905 | Z19: D | AC19: No | AF19: 1 | AG19: 1
B20: SH | C20: MEL | D20: 550910 | E20: 22 and 23-25 Eastcastle Street | F20: Fourth Floor (23-25) | G20: Office | H20: 972 | I20: =H20 -> 972 | J20: 1000 | K20: Encore Search (Newburgh Street) Ltd. | L20: 45100 | M20: 46926 | P20: 46195 | Q20: 58560 | R20: =Q20 -> 58560 | T20: 49400 | U20: =T20 -> 49400 | V20: 58300 | W20: =V20 -> 58300 | X20: =V20/H20 -> 59.979424 | Y20: =SUM(V20-T20)/T20 -> 0.18016194 | Z20: D | AC20: No | AD20: Tenant break on 6 months notice. 3 months rent free if not exercised.
B21: SH | C21: MEL | D21: 550910 | E21: 22 and 23-25 Eastcastle Street | F21: Fifth Floor (23-25) | G21: Office | H21: 977 | I21: =H21 -> 977 | J21: 1000 | K21: Element Pictures UK Ltd. | L21: 45476 | M21: 47301 | P21: 46364 | Q21: 58496 | R21: =Q21 -> 58496 | T21: 47400 | U21: =T21 -> 47400 | V21: 58600 | W21: =V21 -> 58600 | X21: =V21/H21 -> 59.979529 | Y21: =SUM(V21-T21)/T21 -> 0.23628692 | Z21: B | AC21: No | AD21: Tenant break on 6 months notice.
B22: SH | C22: MEL | D22: 550910 | E22: 22 and 23-25 Eastcastle Street | F22: Sixth Floor (23-25) | G22: Office | H22: 744 | I22: =H22 -> 744 | J22: 750 | K22: Vacant | N22: 45182 | Q22: 0 | R22: =Q22 -> 0 | T22: 34400 | U22: =T22 -> 34400 | V22: 47000 | W22: =V22 -> 47000 | X22: =V22/H22 -> 63.172043 | Y22: =SUM(V22-T22)/T22 -> 0.36627907 | Z22: D | AC22: No | AD22: LEM marketing. | AE22: 63.5 | AF22: 2 | AG22: 4 | AH22: LEM
B23: SH | C23: MEL | D23: 550910 | E23: 22 and 23-25 Eastcastle Street | F23: Garage | G23: Parking | H23: 185 | I23: =H23 -> 185 | J23: 200 | K23: Vacant / Landlord | N23: N/A | Q23: 0 | R23: =Q23 -> 0 | T23: 3000 | U23: =T23 -> 3000 | V23: 4500 | W23: =V23 -> 4500 | X23: =V23/H23 -> 24.324324 | Y23: =SUM(V23-T23)/T23 -> 0.5 | AC23: No
C24: MEL
C25: MEL | F25: 22, 23 & 25 Eastcastle St | H25: =SUM(H11:H23) -> 20705 | Q25: =SUM(Q11:Q23) -> 858696 | S25: =SUM(R10:R23) -> 858696 | T25: =SUM(T11:T23) -> 1001300 | V25: =SUM(V11:V23) -> 1051500 | AB25: 14850000
C26: MEL
C27: MEL | G27: 26 Eastcastle Street
C28: MEL
B29: SH | C29: MEL | D29: 550920 | E29: 26 Eastcastle Street | F29: Lower Ground & Ground | G29: Showroom/ Offices | H29: 2940 | I29: =H29 -> 2940 | J29: 3000 | K29: Hela Brands Ltd | L29: 45649 | M29: 46743 | P29: 46013 | Q29: 132000 | R29: =Q29 -> 132000 | T29: 114600 | U29: =T29 -> 114600 | V29: 124500 | W29: =V29 -> 124500 | X29: =V29/H29 -> 42.346939 | Y29: =SUM(V29-T29)/T29 -> 0.086387435 | Z29: C | AC29: No | AD29: Tenant rolling break from 22/12/25 on 4 months notice.
B30: SH | C30: MEL | D30: 550920 | E30: 26 Eastcastle Street | F30: First Floor | G30: Offices | H30: 1398 | I30: =H30 -> 1398 | J30: 1000 | K30: Alternative Real Estate Advisors Ltd | L30: 45470 | M30: 47295 | P30: 46564 | Q30: 89833 | R30: =Q30 -> 89833 | T30: 76900 | U30: =T30 -> 76900 | V30: 97900 | W30: =V30 -> 97900 | X30: =V30/H30 -> 70.028612 | Y30: =SUM(V30-T30)/T30 -> 0.27308192 | Z30: D | AC30: No | AD30: Rent increases to £98,000 wef 27/06/27. Tenant break on 6 months notice.
B31: SH | C31: MEL | D31: 550920 | E31: 26 Eastcastle Street | F31: Second Floor | G31: Offices | H31: 1110 | I31: =H31 -> 1110 | J31: 1000 | K31: Vacant | N31: 43273 | Q31: 0 | R31: =Q31 -> 0 | T31: 61100 | U31: =T31 -> 61100 | V31: 69400 | W31: =V31 -> 69400 | X31: =V31/H31 -> 62.522523 | Y31: =SUM(V31-T31)/T31 -> 0.13584288 | Z31: C | AC31: No | AD31: LEM marketing. | AE31: 63.5 | AG31: 1
B32: SH | C32: MEL | D32: 550920 | E32: 26 Eastcastle Street | F32: Third Floor | G32: Offices | H32: 481 | I32: =H32 -> 481 | J32: 500 | K32: Mr. A. Park | L32: 45541 | M32: 47366 | P32: 46635 | Q32: 26000 | R32: =Q32 -> 26000 | T32: 25300 | U32: =T32 -> 25300 | V32: 25300 | W32: =V32 -> 25300 | X32: =V32/H32 -> 52.598753 | Y32: =SUM(V32-T32)/T32 -> 0 | Z32: D | AC32: No | AD32: Tenant break on 6 months notice.
C33: MEL
C34: MEL | F34: 26 Eastcastle Street | H34: =SUM(H29:H32) -> 5929 | Q34: =SUM(Q29:Q32) -> 247833 | S34: =SUM(R29:R32) -> 247833 | T34: =SUM(T29:T32) -> 277900 | V34: =SUM(V29:V32) -> 317100 | AB34: 4725000
C35: MEL
C36: MEL | G36: 27 - 28 Eastcastle Street
C37: MEL
B38: SH | C38: MEL | D38: 550930 | E38: 27 - 28 Eastcastle Street | F38: Lower Ground & Ground | G38: Showroom / Offices | H38: 3668 | I38: =H38 -> 3668 | J38: 3500 | K38: The London Hair Clinic Ltd | L38: 44757 | M38: 48409 | O38: 46583 | Q38: 170000 | R38: =Q38 -> 170000 | T38: 170000 | U38: =T38 -> 170000 | V38: 170000 | W38: =V38 -> 170000 | X38: =V38/H38 -> 46.346783 | Y38: =SUM(V38-T38)/T38 -> 0 | Z38: B | AC38: No
B39: SH | C39: MEL | D39: 550930 | E39: 27 - 28 Eastcastle Street | F39: First Floor | G39: Offices | H39: 1418 | I39: =H39 -> 1418 | J39: 1500 | K39: Feldberg Capital UK Limited | L39: 45231 | M39: 46326 | Q39: 174500 | R39: =Q39 -> 174500 | T39: 78000 | U39: =T39 -> 78000 | V39: 99300 | W39: =V39 -> 99300 | X39: =V39/H39 -> 70.028209 | Y39: =SUM(V39-T39)/T39 -> 0.27307692 | Z39: B | AC39: No | AD39: All inclusive including rates and furniture.
B40: SH | C40: MEL | D40: 550930 | E40: 27 - 28 Eastcastle Street | F40: Second Floor | G40: Offices | H40: 716 | I40: =H40 -> 716 | J40: 750 | K40: MSP Secretaries Ltd. | L40: 44384 | M40: 46209 | Q40: 41000 | R40: =Q40 -> 41000 | T40: 39400 | U40: =T40 -> 39400 | V40: 41200 | W40: =V40 -> 41200 | X40: =V40/H40 -> 57.541899 | Y40: =SUM(V40-T40)/T40 -> 0.045685279 | Z40: B | AC40: No
B41: SH | C41: MEL | D41: 550930 | E41: 27 - 28 Eastcastle Street | F41: Third Floor | G41: Offices | H41: 665 | I41: =H41 -> 665 | J41: 750 | K41: Principle Estate Management LLP | L41: 45617 | M41: 47442 | P41: 46527 | Q41: 41875 | R41: =Q41 -> 41875 | T41: 36600 | U41: =T41 -> 36600 | V41: 38200 | W41: =V41 -> 38200 | X41: =V41/H41 -> 57.443609 | Y41: =SUM(V41-T41)/T41 -> 0.043715847 | Z41: B | AC41: No | AD41: Tenant break on 6 months notice. 2 months rent free if break not exercised.
...

Sheet Voids Tab
B3: Surveyor | C3: Client | D3: Property Number | E3: Property | F3: Unit Demise | G3: Unit Type | H3: Net Area | I3: . | J3: Agency Area | K3: Tenant Name | L3: Start Date | M3: Expiry Date | N3: Vacant Since? | O3: RRs | P3: Break Date | Q3: Rent PA (£) | R3: check 1 | S3: check 2 | T3: 2023 ERV (£) | U3: check 3 | V3: 2024 ERV (£) | W3: check 4 | X3: ERV 2024 £.Sq.ft | Z3: EPC | AA3: * | AB3: 2024 Cap Valn. (£) | AC3: 1954 Act Protected | AD3: Remarks | AE3: Agency Quoting Rent £.sq.ft | AF3: Monthly Viewings | AG3: Total Viewings | AH3: Marketing Agent
A4: =IFERROR(INDEX('Bank Schedule'!A:A, SMALL(IF('Bank Schedule'!$K$2:$K$825="Vacant", ROW('Bank Schedule'!$K$2:$K$825)), ROW(1:1))), "") -> 0 | B4: {=IFERROR(INDEX('Bank Schedule'!B:B, SMALL(IF('Bank Schedule'!$K$2:$K$825="Vacant", ROW('Bank Schedule'!$K$2:$K$825)), ROW(1:1))), "")} -> SH | C4: {=IFERROR(INDEX('Bank Schedule'!C:C, SMALL(IF('Bank Schedule'!$K$2:$K$825="Vacant", ROW('Bank Schedule'!$K$2:$K$825)), ROW(1:1))), "")} -> MEL | D4: {=IFERROR(INDEX('Bank Schedule'!D:D, SMALL(IF('Bank Schedule'!$K$2:$K$825="Vacant", ROW('Bank Schedule'!$K$2:$K$825)), ROW(1:1))), "")} -> 550910 | E4: {=IFERROR(INDEX('Bank Schedule'!E:E, SMALL(IF('Bank Schedule'!$K$2:$K$825="Vacant", ROW('Bank Schedule'!$K$2:$K$825)), ROW(1:1))), "")} -> 22 and 23-25 Eastcastle Street | F4: {=IFERROR(INDEX('Bank Schedule'!F:F, SMALL(IF('Bank Schedule'!$K$2:$K$825="Vacant", ROW('Bank Schedule'!$K$2:$K$825)), ROW(1:1))), "")} -> Second Floor (23-25) | G4: {=IFERROR(INDEX('Bank Schedule'!G:G, SMALL(IF('Bank Schedule'!$K$2:$K$825="Vacant", ROW('Bank Schedule'!$K$2:$K$825)), ROW(1:1))), "")} -> Office | H4: {=IFERROR(INDEX('Bank Schedule'!H:H, SMALL(IF('Bank Schedule'!$K$2:$K$825="Vacant", ROW('Bank Schedule'!$K$2:$K$825)), ROW(1:1))), "")} -> 2238 | I4: {=IFERROR(INDEX('Bank Schedule'!I:I, SMALL(IF('Bank Schedule'!$K$2:$K$825="Vacant", ROW('Bank Schedule'!$K$2:$K$825)), ROW(1:1))), "")} -> 2238 | J4: {=IFERROR(INDEX('Bank Schedule'!J:J, SMALL(IF('Bank Schedule'!$K$2:$K$825="Vacant", ROW('Bank Schedule'!$K$2:$K$825)), ROW(1:1))), "")} -> 2000 | K4: {=IFERROR(INDEX('Bank Schedule'!K:K, SMALL(IF('Bank Schedule'!$K$2:$K$825="Vacant", ROW('Bank Schedule'!$K$2:$K$825)), ROW(1:1))), "")} -> Vacant | L4: =IFERROR(INDEX('Bank Schedule'!L:L, SMALL(IF('Bank Schedule'!$K$2:$K$825="Vacant", ROW('Bank Schedule'!$K$2:$K$825)), ROW(1:1))), "") -> 0 | M4: =IFERROR(INDEX('Bank Schedule'!M:M, SMALL(IF('Bank Schedule'!$K$2:$K$825="Vacant", ROW('Bank Schedule'!$K$2:$K$825)), ROW(1:1))), "") -> 0 | N4: {=IFERROR(INDEX('Bank Schedule'!N:N, SMALL(IF('Bank Schedule'!$K$2:$K$825="Vacant", ROW('Bank Schedule'!$K$2:$K$825)), ROW(1:1))), "")} -> 45636 | O4: =IFERROR(INDEX('Bank Schedule'!O:O, SMALL(IF('Bank Schedule'!$K$2:$K$825="Vacant", ROW('Bank Schedule'!$K$2:$K$825)), ROW(1:1))), "") -> 0 | P4: =IFERROR(INDEX('Bank Schedule'!P:P, SMALL(IF('Bank Schedule'!$K$2:$K$825="Vacant", ROW('Bank Schedule'!$K$2:$K$825)), ROW(1:1))), "") -> 0 | Q4: {=IFERROR(INDEX('Bank Schedule'!Q:Q, SMALL(IF('Bank Schedule'!$K$2:$K$825="Vacant", ROW('Bank Schedule'!$K$2:$K$825)), ROW(1:1))), "")} -> 0 | R4: {=IFERROR(INDEX('Bank Schedule'!R:R, SMALL(IF('Bank Schedule'!$K$2:$K$825="Vacant", ROW('Bank Schedule'!$K$2:$K$825)), ROW(1:1))), "")} -> 0 | S4: =IFERROR(INDEX('Bank Schedule'!S:S, SMALL(IF('Bank Schedule'!$K$2:$K$825="Vacant", ROW('Bank Schedule'!$K$2:$K$825)), ROW(1:1))), "") -> 0 | T4: {=IFERROR(INDEX('Bank Schedule'!T:T, SMALL(IF('Bank Schedule'!$K$2:$K$825="Vacant", ROW('Bank Schedule'!$K$2:$K$825)), ROW(1:1))), "")} -> 134300 | U4: {=IFERROR(INDEX('Bank Schedule'!U:U, SMALL(IF('Bank Schedule'!$K$2:$K$825="Vacant", ROW('Bank Schedule'!$K$2:$K$825)), ROW(1:1))), "")} -> 134300 | V4: {=IFERROR(INDEX('Bank Schedule'!V:V, SMALL(IF('Bank Schedule'!$K$2:$K$825="Vacant", ROW('Bank Schedule'!$K$2:$K$825)), ROW(1:1))), "")} -> 134300 | W4: {=IFERROR(INDEX('Bank Schedule'!W:W, SMALL(IF('Bank Schedule'!$K$2:$K$825="Vacant", ROW('Bank Schedule'!$K$2:$K$825)), ROW(1:1))), "")} -> 134300 | X4: {=IFERROR(INDEX('Bank Schedule'!X:X, SMALL(IF('Bank Schedule'!$K$2:$K$825="Vacant", ROW('Bank Schedule'!$K$2:$K$825)), ROW(1:1))), "")} -> 60.008937 | Y4: {=IFERROR(INDEX('Bank Schedule'!Y:Y, SMALL(IF('Bank Schedule'!$K$2:$K$825="Vacant", ROW('Bank Schedule'!$K$2:$K$825)), ROW(1:1))), "")} -> 0 | Z4: {=IFERROR(INDEX('Bank Schedule'!Z:Z, SMALL(IF('Bank Schedule'!$K$2:$K$825="Vacant", ROW('Bank Schedule'!$K$2:$K$825)), ROW(1:1))), "")} -> D | AA4: =IFERROR(INDEX('Bank Schedule'!AA:AA, SMALL(IF('Bank Schedule'!$K$2:$K$825="Vacant", ROW('Bank Schedule'!$K$2:$K$825)), ROW(1:1))), "") -> 0 | AB4: =IFERROR(INDEX('Bank Schedule'!AB:AB, SMALL(IF('Bank Schedule'!$K$2:$K$825="Vacant", ROW('Bank Schedule'!$K$2:$K$825)), ROW(1:1))), "") -> 0 | AC4: {=IFERROR(INDEX('Bank Schedule'!AC:AC, SMALL(IF('Bank Schedule'!$K$2:$K$825="Vacant", ROW('Bank Schedule'!$K$2:$K$825)), ROW(1:1))), "")} -> No | AD4: {=IFERROR(INDEX('Bank Schedule'!AD:AD, SMALL(IF('Bank Schedule'!$K$2:$K$825="Vacant", ROW('Bank Schedule'!$K$2:$K$825)), ROW(1:1))), "")} -> LEM marketing. | AE4: =IFERROR(INDEX('Bank Schedule'!AE:AE, SMALL(IF('Bank Schedule'!$K$2:$K$825="Vacant", ROW('Bank Schedule'!$K$2:$K$825)), ROW(1:1))), "") -> 0 | AF4: {=IFERROR(INDEX('Bank Schedule'!AF:AF, SMALL(IF('Bank Schedule'!$K$2:$K$825="Vacant", ROW('Bank Schedule'!$K$2:$K$825)), ROW(1:1))), "")} -> 2 | AG4: {=IFERROR(INDEX('Bank Schedule'!AG:AG, SMALL(IF('Bank Schedule'!$K$2:$K$825="Vacant", ROW('Bank Schedule'!$K$2:$K$825)), ROW(1:1))), "")} -> 2 | AH4: =IFERROR(INDEX('Bank Schedule'!AH:AH, SMALL(IF('Bank Schedule'!$K$2:$K$825="Vacant", ROW('Bank Schedule'!$K$2:$K$825)), ROW(1:1))), "") -> 0
A5: =IFERROR(INDEX('Bank Schedule'!A:A, SMALL(IF('Bank Schedule'!$K$2:$K$825="Vacant", ROW('Bank Schedule'!$K$2:$K$825)), ROW(2:2))), "") | B5: {=IFERROR(INDEX('Bank Schedule'!B:B, SMALL(IF('Bank Schedule'!$K$2:$K$825="Vacant", ROW('Bank Schedule'!$K$2:$K$825)), ROW(2:2))), "")} -> SH | C5: {=IFERROR(INDEX('Bank Schedule'!C:C, SMALL(IF('Bank Schedule'!$K$2:$K$825="Vacant", ROW('Bank Schedule'!$K$2:$K$825)), ROW(2:2))), "")} -> MEL | D5: {=IFERROR(INDEX('Bank Schedule'!D:D, SMALL(IF('Bank Schedule'!$K$2:$K$825="Vacant", ROW('Bank Schedule'!$K$2:$K$825)), ROW(2:2))), "")} -> 550910 | E5: {=IFERROR(INDEX('Bank Schedule'!E:E, SMALL(IF('Bank Schedule'!$K$2:$K$825="Vacant", ROW('Bank Schedule'!$K$2:$K$825)), ROW(2:2))), "")} -> 22 and 23-25 Eastcastle Street | F5: {=IFERROR(INDEX('Bank Schedule'!F:F, SMALL(IF('Bank Schedule'!$K$2:$K$825="Vacant", ROW('Bank Schedule'!$K$2:$K$825)), ROW(2:2))), "")} -> Third Floor (22) | G5: {=IFERROR(INDEX('Bank Schedule'!G:G, SMALL(IF('Bank Schedule'!$K$2:$K$825="Vacant", ROW('Bank Schedule'!$K$2:$K$825)), ROW(2:2))), "")} -> Office | H5: {=IFERROR(INDEX('Bank Schedule'!H:H, SMALL(IF('Bank Schedule'!$K$2:$K$825="Vacant", ROW('Bank Schedule'!$K$2:$K$825)), ROW(2:2))), "")} -> 400 | I5: {=IFERROR(INDEX('Bank Schedule'!I:I, SMALL(IF('Bank Schedule'!$K$2:$K$825="Vacant", ROW('Bank Schedule'!$K$2:$K$825)), ROW(2:2))), "")} -> 400 | J5: {=IFERROR(INDEX('Bank Schedule'!J:J, SMALL(IF('Bank Schedule'!$K$2:$K$825="Vacant", ROW('Bank Schedule'!$K$2:$K$825)), ROW(2:2))), "")} -> 500 | K5: {=IFERROR(INDEX('Bank Schedule'!K:K, SMALL(IF('Bank Schedule'!$K$2:$K$825="Vacant", ROW('Bank Schedule'!$K$2:$K$825)), ROW(2:2))), "")} -> Vacant | L5: =IFERROR(INDEX('Bank Schedule'!L:L, SMALL(IF('Bank Schedule'!$K$2:$K$825="Vacant", ROW('Bank Schedule'!$K$2:$K$825)), ROW(2:2))), "") | M5: =IFERROR(INDEX('Bank Schedule'!M:M, SMALL(IF('Bank Schedule'!$K$2:$K$825="Vacant", ROW('Bank Schedule'!$K$2:$K$825)), ROW(2:2))), "") | N5: {=IFERROR(INDEX('Bank Schedule'!N:N, SMALL(IF('Bank Schedule'!$K$2:$K$825="Vacant", ROW('Bank Schedule'!$K$2:$K$825)), ROW(2:2))), "")} -> 45771 | O5: =IFERROR(INDEX('Bank Schedule'!O:O, SMALL(IF('Bank Schedule'!$K$2:$K$825="Vacant", ROW('Bank Schedule'!$K$2:$K$825)), ROW(2:2))), "") | P5: =IFERROR(INDEX('Bank Schedule'!P:P, SMALL(IF('Bank Schedule'!$K$2:$K$825="Vacant", ROW('Bank Schedule'!$K$2:$K$825)), ROW(2:2))), "") | Q5: {=IFERROR(INDEX('Bank Schedule'!Q:Q, SMALL(IF('Bank Schedule'!$K$2:$K$825="Vacant", ROW('Bank Schedule'!$K$2:$K$825)), ROW(2:2))), "")} -> 0 | R5: {=IFERROR(INDEX('Bank Schedule'!R:R, SMALL(IF('Bank Schedule'!$K$2:$K$825="Vacant", ROW('Bank Schedule'!$K$2:$K$825)), ROW(2:2))), "")} -> 0 | S5: =IFERROR(INDEX('Bank Schedule'!S:S, SMALL(IF('Bank Schedule'!$K$2:$K$825="Vacant", ROW('Bank Schedule'!$K$2:$K$825)), ROW(2:2))), "") | T5: {=IFERROR(INDEX('Bank Schedule'!T:T, SMALL(IF('Bank Schedule'!$K$2:$K$825="Vacant", ROW('Bank Schedule'!$K$2:$K$825)), ROW(2:2))), "")} -> 20600 | U5: {=IFERROR(INDEX('Bank Schedule'!U:U, SMALL(IF('Bank Schedule'!$K$2:$K$825="Vacant", ROW('Bank Schedule'!$K$2:$K$825)), ROW(2:2))), "")} -> 20600 | V5: {=IFERROR(INDEX('Bank Schedule'!V:V, SMALL(IF('Bank Schedule'!$K$2:$K$825="Vacant", ROW('Bank Schedule'!$K$2:$K$825)), ROW(2:2))), "")} -> 23000 | W5: {=IFERROR(INDEX('Bank Schedule'!W:W, SMALL(IF('Bank Schedule'!$K$2:$K$825="Vacant", ROW('Bank Schedule'!$K$2:$K$825)), ROW(2:2))), "")} -> 23000 | X5: {=IFERROR(INDEX('Bank Schedule'!X:X, SMALL(IF('Bank Schedule'!$K$2:$K$825="Vacant", ROW('Bank Schedule'!$K$2:$K$825)), ROW(2:2))), "")} -> 57.5 | Y5: {=IFERROR(INDEX('Bank Schedule'!Y:Y, SMALL(IF('Bank Schedule'!$K$2:$K$825="Vacant", ROW('Bank Schedule'!$K$2:$K$825)), ROW(2:2))), "")} -> 0.11650485 | Z5: {=IFERROR(INDEX('Bank Schedule'!Z:Z, SMALL(IF('Bank Schedule'!$K$2:$K$825="Vacant", ROW('Bank Schedule'!$K$2:$K$825)), ROW(2:2))), "")} -> D | AA5: =IFERROR(INDEX('Bank Schedule'!AA:AA, SMALL(IF('Bank Schedule'!$K$2:$K$825="Vacant", ROW('Bank Schedule'!$K$2:$K$825)), ROW(2:2))), "") | AB5: =IFERROR(INDEX('Bank Schedule'!AB:AB, SMALL(IF('Bank Schedule'!$K$2:$K$825="Vacant", ROW('Bank Schedule'!$K$2:$K$825)), ROW(2:2))), "") | AC5: {=IFERROR(INDEX('Bank Schedule'!AC:AC, SMALL(IF('Bank Schedule'!$K$2:$K$825="Vacant", ROW('Bank Schedule'!$K$2:$K$825)), ROW(2:2))), "")} -> No | AD5: {=IFERROR(INDEX('Bank Schedule'!AD:AD, SMALL(IF('Bank Schedule'!$K$2:$K$825="Vacant", ROW('Bank Schedule'!$K$2:$K$825)), ROW(2:2))), "")} -> LEM marketing. | AE5: =IFERROR(INDEX('Bank Schedule'!AE:AE, SMALL(IF('Bank Schedule'!$K$2:$K$825="Vacant", ROW('Bank Schedule'!$K$2:$K$825)), ROW(2:2))), "") | AF5: {=IFERROR(INDEX('Bank Schedule'!AF:AF, SMALL(IF('Bank Schedule'!$K$2:$K$825="Vacant", ROW('Bank Schedule'!$K$2:$K$825)), ROW(2:2))), "")} -> 1 | AG5: {=IFERROR(INDEX('Bank Schedule'!AG:AG, SMALL(IF('Bank Schedule'!$K$2:$K$825="Vacant", ROW('Bank Schedule'!$K$2:$K$825)), ROW(2:2))), "")} -> 1 | AH5: =IFERROR(INDEX('Bank Schedule'!AH:AH, SMALL(IF('Bank Schedule'!$K$2:$K$825="Vacant", ROW('Bank Schedule'!$K$2:$K$825)), ROW(2:2))), "")
A6: =IFERROR(INDEX('Bank Schedule'!A:A, SMALL(IF('Bank Schedule'!$K$2:$K$825="Vacant", ROW('Bank Schedule'!$K$2:$K$825)), ROW(3:3))), "") | B6: {=IFERROR(INDEX('Bank Schedule'!B:B, SMALL(IF('Bank Schedule'!$K$2:$K$825="Vacant", ROW('Bank Schedule'!$K$2:$K$825)), ROW(3:3))), "")} -> SH | C6: {=IFERROR(INDEX('Bank Schedule'!C:C, SMALL(IF('Bank Schedule'!$K$2:$K$825="Vacant", ROW('Bank Schedule'!$K$2:$K$825)), ROW(3:3))), "")} -> MEL | D6: {=IFERROR(INDEX('Bank Schedule'!D:D, SMALL(IF('Bank Schedule'!$K$2:$K$825="Vacant", ROW('Bank Schedule'!$K$2:$K$825)), ROW(3:3))), "")} -> 550910 | E6: {=IFERROR(INDEX('Bank Schedule'!E:E, SMALL(IF('Bank Schedule'!$K$2:$K$825="Vacant", ROW('Bank Schedule'!$K$2:$K$825)), ROW(3:3))), "")} -> 22 and 23-25 Eastcastle Street | F6: {=IFERROR(INDEX('Bank Schedule'!F:F, SMALL(IF('Bank Schedule'!$K$2:$K$825="Vacant", ROW('Bank Schedule'!$K$2:$K$825)), ROW(3:3))), "")} -> Third Floor (23-25) | G6: {=IFERROR(INDEX('Bank Schedule'!G:G, SMALL(IF('Bank Schedule'!$K$2:$K$825="Vacant", ROW('Bank Schedule'!$K$2:$K$825)), ROW(3:3))), "")} -> Office | H6: {=IFERROR(INDEX('Bank Schedule'!H:H, SMALL(IF('Bank Schedule'!$K$2:$K$825="Vacant", ROW('Bank Schedule'!$K$2:$K$825)), ROW(3:3))), "")} -> 1938 | I6: {=IFERROR(INDEX('Bank Schedule'!I:I, SMALL(IF('Bank Schedule'!$K$2:$K$825="Vacant", ROW('Bank Schedule'!$K$2:$K$825)), ROW(3:3))), "")} -> 1938 | J6: {=IFERROR(INDEX('Bank Schedule'!J:J, SMALL(IF('Bank Schedule'!$K$2:$K$825="Vacant", ROW('Bank Schedule'!$K$2:$K$825)), ROW(3:3))), "")} -> 2000 | K6: {=IFERROR(INDEX('Bank Schedule'!K:K, SMALL(IF('Bank Schedule'!$K$2:$K$825="Vacant", ROW('Bank Schedule'!$K$2:$K$825)), ROW(3:3))), "")} -> Vacant | L6: =IFERROR(INDEX('Bank Schedule'!L:L, SMALL(IF('Bank Schedule'!$K$2:$K$825="Vacant", ROW('Bank Schedule'!$K$2:$K$825)), ROW(3:3))), "") | M6: =IFERROR(INDEX('Bank Schedule'!M:M, SMALL(IF('Bank Schedule'!$K$2:$K$825="Vacant", ROW('Bank Schedule'!$K$2:$K$825)), ROW(3:3))), "") | N6: {=IFERROR(INDEX('Bank Schedule'!N:N, SMALL(IF('Bank Schedule'!$K$2:$K$825="Vacant", ROW('Bank Schedule'!$K$2:$K$825)), ROW(3:3))), "")} -> 45217 | O6: =IFERROR(INDEX('Bank Schedule'!O:O, SMALL(IF('Bank Schedule'!$K$2:$K$825="Vacant", ROW('Bank Schedule'!$K$2:$K$825)), ROW(3:3))), "") | P6: =IFERROR(INDEX('Bank Schedule'!P:P, SMALL(IF('Bank Schedule'!$K$2:$K$825="Vacant", ROW('Bank Schedule'!$K$2:$K$825)), ROW(3:3))), "") | Q6: {=IFERROR(INDEX('Bank Schedule'!Q:Q, SMALL(IF('Bank Schedule'!$K$2:$K$825="Vacant", ROW('Bank Schedule'!$K$2:$K$825)), ROW(3:3))), "")} -> 0 | R6: {=IFERROR(INDEX('Bank Schedule'!R:R, SMALL(IF('Bank Schedule'!$K$2:$K$825="Vacant", ROW('Bank Schedule'!$K$2:$K$825)), ROW(3:3))), "")} -> 0 | S6: =IFERROR(INDEX('Bank Schedule'!S:S, SMALL(IF('Bank Schedule'!$K$2:$K$825="Vacant", ROW('Bank Schedule'!$K$2:$K$825)), ROW(3:3))), "") | T6: {=IFERROR(INDEX('Bank Schedule'!T:T, SMALL(IF('Bank Schedule'!$K$2:$K$825="Vacant", ROW('Bank Schedule'!$K$2:$K$825)), ROW(3:3))), "")} -> 109000 | U6: {=IFERROR(INDEX('Bank Schedule'!U:U, SMALL(IF('Bank Schedule'!$K$2:$K$825="Vacant", ROW('Bank Schedule'!$K$2:$K$825)), ROW(3:3))), "")} -> 109000 | V6: {=IFERROR(INDEX('Bank Schedule'!V:V, SMALL(IF('Bank Schedule'!$K$2:$K$825="Vacant", ROW('Bank Schedule'!$K$2:$K$825)), ROW(3:3))), "")} -> 111400 | W6: {=IFERROR(INDEX('Bank Schedule'!W:W, SMALL(IF('Bank Schedule'!$K$2:$K$825="Vacant", ROW('Bank Schedule'!$K$2:$K$825)), ROW(3:3))), "")} -> 111400 | X6: {=IFERROR(INDEX('Bank Schedule'!X:X, SMALL(IF('Bank Schedule'!$K$2:$K$825="Vacant", ROW('Bank Schedule'!$K$2:$K$825)), ROW(3:3))), "")} -> 57.48194 | Y6: {=IFERROR(INDEX('Bank Schedule'!Y:Y, SMALL(IF('Bank Schedule'!$K$2:$K$825="Vacant", ROW('Bank Schedule'!$K$2:$K$825)), ROW(3:3))), "")} -> 0.022018349 | Z6: {=IFERROR(INDEX('Bank Schedule'!Z:Z, SMALL(IF('Bank Schedule'!$K$2:$K$825="Vacant", ROW('Bank Schedule'!$K$2:$K$825)), ROW(3:3))), "")} -> D | AA6: =IFERROR(INDEX('Bank Schedule'!AA:AA, SMALL(IF('Bank Schedule'!$K$2:$K$825="Vacant", ROW('Bank Schedule'!$K$2:$K$825)), ROW(3:3))), "") | AB6: =IFERROR(INDEX('Bank Schedule'!AB:AB, SMALL(IF('Bank Schedule'!$K$2:$K$825="Vacant", ROW('Bank Schedule'!$K$2:$K$825)), ROW(3:3))), "") | AC6: {=IFERROR(INDEX('Bank Schedule'!AC:AC, SMALL(IF('Bank Schedule'!$K$2:$K$825="Vacant", ROW('Bank Schedule'!$K$2:$K$825)), ROW(3:3))), "")} -> No | AD6: {=IFERROR(INDEX('Bank Schedule'!AD:AD, SMALL(IF('Bank Schedule'!$K$2:$K$825="Vacant", ROW('Bank Schedule'!$K$2:$K$825)), ROW(3:3))), "")} -> LEM marketing. | AE6: {=IFERROR(INDEX('Bank Schedule'!AE:AE, SMALL(IF('Bank Schedule'!$K$2:$K$825="Vacant", ROW('Bank Schedule'!$K$2:$K$825)), ROW(3:3))), "")} -> 65 | AF6: {=IFERROR(INDEX('Bank Schedule'!AF:AF, SMALL(IF('Bank Schedule'!$K$2:$K$825="Vacant", ROW('Bank Schedule'!$K$2:$K$825)), ROW(3:3))), "")} -> 2 | AG6: {=IFERROR(INDEX('Bank Schedule'!AG:AG, SMALL(IF('Bank Schedule'!$K$2:$K$825="Vacant", ROW('Bank Schedule'!$K$2:$K$825)), ROW(3:3))), "")} -> 4 | AH6: =IFERROR(INDEX('Bank Schedule'!AH:AH, SMALL(IF('Bank Schedule'!$K$2:$K$825="Vacant", ROW('Bank Schedule'!$K$2:$K$825)), ROW(3:3))), "")
A7: =IFERROR(INDEX('Bank Schedule'!A:A, SMALL(IF('Bank Schedule'!$K$2:$K$825="Vacant", ROW('Bank Schedule'!$K$2:$K$825)), ROW(4:4))), "") | B7: {=IFERROR(INDEX('Bank Schedule'!B:B, SMALL(IF('Bank Schedule'!$K$2:$K$825="Vacant", ROW('Bank Schedule'!$K$2:$K$825)), ROW(4:4))), "")} -> SH | C7: {=IFERROR(INDEX('Bank Schedule'!C:C, SMALL(IF('Bank Schedule'!$K$2:$K$825="Vacant", ROW('Bank Schedule'!$K$2:$K$825)), ROW(4:4))), "")} -> MEL | D7: {=IFERROR(INDEX('Bank Schedule'!D:D, SMALL(IF('Bank Schedule'!$K$2:$K$825="Vacant", ROW('Bank Schedule'!$K$2:$K$825)), ROW(4:4))), "")} -> 550910 | E7: {=IFERROR(INDEX('Bank Schedule'!E:E, SMALL(IF('Bank Schedule'!$K$2:$K$825="Vacant", ROW('Bank Schedule'!$K$2:$K$825)), ROW(4:4))), "")} -> 22 and 23-25 Eastcastle Street | F7: {=IFERROR(INDEX('Bank Schedule'!F:F, SMALL(IF('Bank Schedule'!$K$2:$K$825="Vacant", ROW('Bank Schedule'!$K$2:$K$825)), ROW(4:4))), "")} -> Sixth Floor (23-25) | G7: {=IFERROR(INDEX('Bank Schedule'!G:G, SMALL(IF('Bank Schedule'!$K$2:$K$825="Vacant", ROW('Bank Schedule'!$K$2:$K$825)), ROW(4:4))), "")} -> Office | H7: {=IFERROR(INDEX('Bank Schedule'!H:H, SMALL(IF('Bank Schedule'!$K$2:$K$825="Vacant", ROW('Bank Schedule'!$K$2:$K$825)), ROW(4:4))), "")} -> 744 | I7: {=IFERROR(INDEX('Bank Schedule'!I:I, SMALL(IF('Bank Schedule'!$K$2:$K$825="Vacant", ROW('Bank Schedule'!$K$2:$K$825)), ROW(4:4))), "")} -> 744 | J7: {=IFERROR(INDEX('Bank Schedule'!J:J, SMALL(IF('Bank Schedule'!$K$2:$K$825="Vacant", ROW('Bank Schedule'!$K$2:$K$825)), ROW(4:4))), "")} -> 750 | K7: {=IFERROR(INDEX('Bank Schedule'!K:K, SMALL(IF('Bank Schedule'!$K$2:$K$825="Vacant", ROW('Bank Schedule'!$K$2:$K$825)), ROW(4:4))), "")} -> Vacant | L7: =IFERROR(INDEX('Bank Schedule'!L:L, SMALL(IF('Bank Schedule'!$K$2:$K$825="Vacant", ROW('Bank Schedule'!$K$2:$K$825)), ROW(4:4))), "") | M7: =IFERROR(INDEX('Bank Schedule'!M:M, SMALL(IF('Bank Schedule'!$K$2:$K$825="Vacant", ROW('Bank Schedule'!$K$2:$K$825)), ROW(4:4))), "") | N7: {=IFERROR(INDEX('Bank Schedule'!N:N, SMALL(IF('Bank Schedule'!$K$2:$K$825="Vacant", ROW('Bank Schedule'!$K$2:$K$825)), ROW(4:4))), "")} -> 45182 | O7: =IFERROR(INDEX('Bank Schedule'!O:O, SMALL(IF('Bank Schedule'!$K$2:$K$825="Vacant", ROW('Bank Schedule'!$K$2:$K$825)), ROW(4:4))), "") | P7: =IFERROR(INDEX('Bank Schedule'!P:P, SMALL(IF('Bank Schedule'!$K$2:$K$825="Vacant", ROW('Bank Schedule'!$K$2:$K$825)), ROW(4:4))), "") | Q7: {=IFERROR(INDEX('Bank Schedule'!Q:Q, SMALL(IF('Bank Schedule'!$K$2:$K$825="Vacant", ROW('Bank Schedule'!$K$2:$K$825)), ROW(4:4))), "")} -> 0 | R7: {=IFERROR(INDEX('Bank Schedule'!R:R, SMALL(IF('Bank Schedule'!$K$2:$K$825="Vacant", ROW('Bank Schedule'!$K$2:$K$825)), ROW(4:4))), "")} -> 0 | S7: =IFERROR(INDEX('Bank Schedule'!S:S, SMALL(IF('Bank Schedule'!$K$2:$K$825="Vacant", ROW('Bank Schedule'!$K$2:$K$825)), ROW(4:4))), "") | T7: {=IFERROR(INDEX('Bank Schedule'!T:T, SMALL(IF('Bank Schedule'!$K$2:$K$825="Vacant", ROW('Bank Schedule'!$K$2:$K$825)), ROW(4:4))), "")} -> 34400 | U7: {=IFERROR(INDEX('Bank Schedule'!U:U, SMALL(IF('Bank Schedule'!$K$2:$K$825="Vacant", ROW('Bank Schedule'!$K$2:$K$825)), ROW(4:4))), "")} -> 34400 | V7: {=IFERROR(INDEX('Bank Schedule'!V:V, SMALL(IF('Bank Schedule'!$K$2:$K$825="Vacant", ROW('Bank Schedule'!$K$2:$K$825)), ROW(4:4))), "")} -> 47000 | W7: {=IFERROR(INDEX('Bank Schedule'!W:W, SMALL(IF('Bank Schedule'!$K$2:$K$825="Vacant", ROW('Bank Schedule'!$K$2:$K$825)), ROW(4:4))), "")} -> 47000 | X7: {=IFERROR(INDEX('Bank Schedule'!X:X, SMALL(IF('Bank Schedule'!$K$2:$K$825="Vacant", ROW('Bank Schedule'!$K$2:$K$825)), ROW(4:4))), "")} -> 63.172043 | Y7: {=IFERROR(INDEX('Bank Schedule'!Y:Y, SMALL(IF('Bank Schedule'!$K$2:$K$825="Vacant", ROW('Bank Schedule'!$K$2:$K$825)), ROW(4:4))), "")} -> 0.36627907 | Z7: {=IFERROR(INDEX('Bank Schedule'!Z:Z, SMALL(IF('Bank Schedule'!$K$2:$K$825="Vacant", ROW('Bank Schedule'!$K$2:$K$825)), ROW(4:4))), "")} -> D | AA7: =IFERROR(INDEX('Bank Schedule'!AA:AA, SMALL(IF('Bank Schedule'!$K$2:$K$825="Vacant", ROW('Bank Schedule'!$K$2:$K$825)), ROW(4:4))), "") | AB7: =IFERROR(INDEX('Bank Schedule'!AB:AB, SMALL(IF('Bank Schedule'!$K$2:$K$825="Vacant", ROW('Bank Schedule'!$K$2:$K$825)), ROW(4:4))), "") | AC7: {=IFERROR(INDEX('Bank Schedule'!AC:AC, SMALL(IF('Bank Schedule'!$K$2:$K$825="Vacant", ROW('Bank Schedule'!$K$2:$K$825)), ROW(4:4))), "")} -> No | AD7: {=IFERROR(INDEX('Bank Schedule'!AD:AD, SMALL(IF('Bank Schedule'!$K$2:$K$825="Vacant", ROW('Bank Schedule'!$K$2:$K$825)), ROW(4:4))), "")} -> LEM marketing. | AE7: {=IFERROR(INDEX('Bank Schedule'!AE:AE, SMALL(IF('Bank Schedule'!$K$2:$K$825="Vacant", ROW('Bank Schedule'!$K$2:$K$825)), ROW(4:4))), "")} -> 63.5 | AF7: {=IFERROR(INDEX('Bank Schedule'!AF:AF, SMALL(IF('Bank Schedule'!$K$2:$K$825="Vacant", ROW('Bank Schedule'!$K$2:$K$825)), ROW(4:4))), "")} -> 2 | AG7: {=IFERROR(INDEX('Bank Schedule'!AG:AG, SMALL(IF('Bank Schedule'!$K$2:$K$825="Vacant", ROW('Bank Schedule'!$K$2:$K$825)), ROW(4:4))), "")} -> 4 | AH7: {=IFERROR(INDEX('Bank Schedule'!AH:AH, SMALL(IF('Bank Schedule'!$K$2:$K$825="Vacant", ROW('Bank Schedule'!$K$2:$K$825)), ROW(4:4))), "")} -> LEM
A8: =IFERROR(INDEX('Bank Schedule'!A:A, SMALL(IF('Bank Schedule'!$K$2:$K$825="Vacant", ROW('Bank Schedule'!$K$2:$K$825)), ROW(5:5))), "") | B8: {=IFERROR(INDEX('Bank Schedule'!B:B, SMALL(IF('Bank Schedule'!$K$2:$K$825="Vacant", ROW('Bank Schedule'!$K$2:$K$825)), ROW(5:5))), "")} -> SH | C8: {=IFERROR(INDEX('Bank Schedule'!C:C, SMALL(IF('Bank Schedule'!$K$2:$K$825="Vacant", ROW('Bank Schedule'!$K$2:$K$825)), ROW(5:5))), "")} -> MEL | D8: {=IFERROR(INDEX('Bank Schedule'!D:D, SMALL(IF('Bank Schedule'!$K$2:$K$825="Vacant", ROW('Bank Schedule'!$K$2:$K$825)), ROW(5:5))), "")} -> 550920 | E8: {=IFERROR(INDEX('Bank Schedule'!E:E, SMALL(IF('Bank Schedule'!$K$2:$K$825="Vacant", ROW('Bank Schedule'!$K$2:$K$825)), ROW(5:5))), "")} -> 26 Eastcastle Street | F8: {=IFERROR(INDEX('Bank Schedule'!F:F, SMALL(IF('Bank Schedule'!$K$2:$K$825="Vacant", ROW('Bank Schedule'!$K$2:$K$825)), ROW(5:5))), "")} -> Second Floor | G8: {=IFERROR(INDEX('Bank Schedule'!G:G, SMALL(IF('Bank Schedule'!$K$2:$K$825="Vacant", ROW('Bank Schedule'!$K$2:$K$825)), ROW(5:5))), "")} -> Offices | H8: {=IFERROR(INDEX('Bank Schedule'!H:H, SMALL(IF('Bank Schedule'!$K$2:$K$825="Vacant", ROW('Bank Schedule'!$K$2:$K$825)), ROW(5:5))), "")} -> 1110 | I8: {=IFERROR(INDEX('Bank Schedule'!I:I, SMALL(IF('Bank Schedule'!$K$2:$K$825="Vacant", ROW('Bank Schedule'!$K$2:$K$825)), ROW(5:5))), "")} -> 1110 | J8: {=IFERROR(INDEX('Bank Schedule'!J:J, SMALL(IF('Bank Schedule'!$K$2:$K$825="Vacant", ROW('Bank Schedule'!$K$2:$K$825)), ROW(5:5))), "")} -> 1000 | K8: {=IFERROR(INDEX('Bank Schedule'!K:K, SMALL(IF('Bank Schedule'!$K$2:$K$825="Vacant", ROW('Bank Schedule'!$K$2:$K$825)), ROW(5:5))), "")} -> Vacant | L8: =IFERROR(INDEX('Bank Schedule'!L:L, SMALL(IF('Bank Schedule'!$K$2:$K$825="Vacant", ROW('Bank Schedule'!$K$2:$K$825)), ROW(5:5))), "") | M8: =IFERROR(INDEX('Bank Schedule'!M:M, SMALL(IF('Bank Schedule'!$K$2:$K$825="Vacant", ROW('Bank Schedule'!$K$2:$K$825)), ROW(5:5))), "") | N8: {=IFERROR(INDEX('Bank Schedule'!N:N, SMALL(IF('Bank Schedule'!$K$2:$K$825="Vacant", ROW('Bank Schedule'!$K$2:$K$825)), ROW(5:5))), "")} -> 43273 | O8: =IFERROR(INDEX('Bank Schedule'!O:O, SMALL(IF('Bank Schedule'!$K$2:$K$825="Vacant", ROW('Bank Schedule'!$K$2:$K$825)), ROW(5:5))), "") | P8: =IFERROR(INDEX('Bank Schedule'!P:P, SMALL(IF('Bank Schedule'!$K$2:$K$825="Vacant", ROW('Bank Schedule'!$K$2:$K$825)), ROW(5:5))), "") | Q8: {=IFERROR(INDEX('Bank Schedule'!Q:Q, SMALL(IF('Bank Schedule'!$K$2:$K$825="Vacant", ROW('Bank Schedule'!$K$2:$K$825)), ROW(5:5))), "")} -> 0 | R8: {=IFERROR(INDEX('Bank Schedule'!R:R, SMALL(IF('Bank Schedule'!$K$2:$K$825="Vacant", ROW('Bank Schedule'!$K$2:$K$825)), ROW(5:5))), "")} -> 0 | S8: =IFERROR(INDEX('Bank Schedule'!S:S, SMALL(IF('Bank Schedule'!$K$2:$K$825="Vacant", ROW('Bank Schedule'!$K$2:$K$825)), ROW(5:5))), "") | T8: {=IFERROR(INDEX('Bank Schedule'!T:T, SMALL(IF('Bank Schedule'!$K$2:$K$825="Vacant", ROW('Bank Schedule'!$K$2:$K$825)), ROW(5:5))), "")} -> 61100 | U8: {=IFERROR(INDEX('Bank Schedule'!U:U, SMALL(IF('Bank Schedule'!$K$2:$K$825="Vacant", ROW('Bank Schedule'!$K$2:$K$825)), ROW(5:5))), "")} -> 61100 | V8: {=IFERROR(INDEX('Bank Schedule'!V:V, SMALL(IF('Bank Schedule'!$K$2:$K$825="Vacant", ROW('Bank Schedule'!$K$2:$K$825)), ROW(5:5))), "")} -> 69400 | W8: {=IFERROR(INDEX('Bank Schedule'!W:W, SMALL(IF('Bank Schedule'!$K$2:$K$825="Vacant", ROW('Bank Schedule'!$K$2:$K$825)), ROW(5:5))), "")} -> 69400 | X8: {=IFERROR(INDEX('Bank Schedule'!X:X, SMALL(IF('Bank Schedule'!$K$2:$K$825="Vacant", ROW('Bank Schedule'!$K$2:$K$825)), ROW(5:5))), "")} -> 62.522523 | Y8: {=IFERROR(INDEX('Bank Schedule'!Y:Y, SMALL(IF('Bank Schedule'!$K$2:$K$825="Vacant", ROW('Bank Schedule'!$K$2:$K$825)), ROW(5:5))), "")} -> 0.13584288 | Z8: {=IFERROR(INDEX('Bank Schedule'!Z:Z, SMALL(IF('Bank Schedule'!$K$2:$K$825="Vacant", ROW('Bank Schedule'!$K$2:$K$825)), ROW(5:5))), "")} -> C | AA8: =IFERROR(INDEX('Bank Schedule'!AA:AA, SMALL(IF('Bank Schedule'!$K$2:$K$825="Vacant", ROW('Bank Schedule'!$K$2:$K$825)), ROW(5:5))), "") | AB8: =IFERROR(INDEX('Bank Schedule'!AB:AB, SMALL(IF('Bank Schedule'!$K$2:$K$825="Vacant", ROW('Bank Schedule'!$K$2:$K$825)), ROW(5:5))), "") | AC8: {=IFERROR(INDEX('Bank Schedule'!AC:AC, SMALL(IF('Bank Schedule'!$K$2:$K$825="Vacant", ROW('Bank Schedule'!$K$2:$K$825)), ROW(5:5))), "")} -> No | AD8: {=IFERROR(INDEX('Bank Schedule'!AD:AD, SMALL(IF('Bank Schedule'!$K$2:$K$825="Vacant", ROW('Bank Schedule'!$K$2:$K$825)), ROW(5:5))), "")} -> LEM marketing. | AE8: {=IFERROR(INDEX('Bank Schedule'!AE:AE, SMALL(IF('Bank Schedule'!$K$2:$K$825="Vacant", ROW('Bank Schedule'!$K$2:$K$825)), ROW(5:5))), "")} -> 63.5 | AF8: =IFERROR(INDEX('Bank Schedule'!AF:AF, SMALL(IF('Bank Schedule'!$K$2:$K$825="Vacant", ROW('Bank Schedule'!$K$2:$K$825)), ROW(5:5))), "") | AG8: {=IFERROR(INDEX('Bank Schedule'!AG:AG, SMALL(IF('Bank Schedule'!$K$2:$K$825="Vacant", ROW('Bank Schedule'!$K$2:$K$825)), ROW(5:5))), "")} -> 1 | AH8: =IFERROR(INDEX('Bank Schedule'!AH:AH, SMALL(IF('Bank Schedule'!$K$2:$K$825="Vacant", ROW('Bank Schedule'!$K$2:$K$825)), ROW(5:5))), "")
A9: =IFERROR(INDEX('Bank Schedule'!A:A, SMALL(IF('Bank Schedule'!$K$2:$K$825="Vacant", ROW('Bank Schedule'!$K$2:$K$825)), ROW(6:6))), "") | B9: {=IFERROR(INDEX('Bank Schedule'!B:B, SMALL(IF('Bank Schedule'!$K$2:$K$825="Vacant", ROW('Bank Schedule'!$K$2:$K$825)), ROW(6:6))), "")} -> SH | C9: {=IFERROR(INDEX('Bank Schedule'!C:C, SMALL(IF('Bank Schedule'!$K$2:$K$825="Vacant", ROW('Bank Schedule'!$K$2:$K$825)), ROW(6:6))), "")} -> MEL | D9: {=IFERROR(INDEX('Bank Schedule'!D:D, SMALL(IF('Bank Schedule'!$K$2:$K$825="Vacant", ROW('Bank Schedule'!$K$2:$K$825)), ROW(6:6))), "")} -> 550070 | E9: {=IFERROR(INDEX('Bank Schedule'!E:E, SMALL(IF('Bank Schedule'!$K$2:$K$825="Vacant", ROW('Bank Schedule'!$K$2:$K$825)), ROW(6:6))), "")} -> Windsor House, 40-41 Great Castle Street | F9: {=IFERROR(INDEX('Bank Schedule'!F:F, SMALL(IF('Bank Schedule'!$K$2:$K$825="Vacant", ROW('Bank Schedule'!$K$2:$K$825)), ROW(6:6))), "")} -> Basement & Ground Floor | G9: {=IFERROR(INDEX('Bank Schedule'!G:G, SMALL(IF('Bank Schedule'!$K$2:$K$825="Vacant", ROW('Bank Schedule'!$K$2:$K$825)), ROW(6:6))), "")} -> Retail/Café | H9: {=IFERROR(INDEX('Bank Schedule'!H:H, SMALL(IF('Bank Schedule'!$K$2:$K$825="Vacant", ROW('Bank Schedule'!$K$2:$K$825)), ROW(6:6))), "")} -> 2235 | I9: {=IFERROR(INDEX('Bank Schedule'!I:I, SMALL(IF('Bank Schedule'!$K$2:$K$825="Vacant", ROW('Bank Schedule'!$K$2:$K$825)), ROW(6:6))), "")} -> 2235 | J9: {=IFERROR(INDEX('Bank Schedule'!J:J, SMALL(IF('Bank Schedule'!$K$2:$K$825="Vacant", ROW('Bank Schedule'!$K$2:$K$825)), ROW(6:6))), "")} -> 2000 | K9: {=IFERROR(INDEX('Bank Schedule'!K:K, SMALL(IF('Bank Schedule'!$K$2:$K$825="Vacant", ROW('Bank Schedule'!$K$2:$K$825)), ROW(6:6))), "")} -> Vacant | L9: =IFERROR(INDEX('Bank Schedule'!L:L, SMALL(IF('Bank Schedule'!$K$2:$K$825="Vacant", ROW('Bank Schedule'!$K$2:$K$825)), ROW(6:6))), "") | M9: =IFERROR(INDEX('Bank Schedule'!M:M, SMALL(IF('Bank Schedule'!$K$2:$K$825="Vacant", ROW('Bank Schedule'!$K$2:$K$825)), ROW(6:6))), "") | N9: {=IFERROR(INDEX('Bank Schedule'!N:N, SMALL(IF('Bank Schedule'!$K$2:$K$825="Vacant", ROW('Bank Schedule'!$K$2:$K$825)), ROW(6:6))), "")} -> 45754 | O9: =IFERROR(INDEX('Bank Schedule'!O:O, SMALL(IF('Bank Schedule'!$K$2:$K$825="Vacant", ROW('Bank Schedule'!$K$2:$K$825)), ROW(6:6))), "") | P9: =IFERROR(INDEX('Bank Schedule'!P:P, SMALL(IF('Bank Schedule'!$K$2:$K$825="Vacant", ROW('Bank Schedule'!$K$2:$K$825)), ROW(6:6))), "") | Q9: {=IFERROR(INDEX('Bank Schedule'!Q:Q, SMALL(IF('Bank Schedule'!$K$2:$K$825="Vacant", ROW('Bank Schedule'!$K$2:$K$825)), ROW(6:6))), "")} -> 0 | R9: {=IFERROR(INDEX('Bank Schedule'!R:R, SMALL(IF('Bank Schedule'!$K$2:$K$825="Vacant", ROW('Bank Schedule'!$K$2:$K$825)), ROW(6:6))), "")} -> 0 | S9: =IFERROR(INDEX('Bank Schedule'!S:S, SMALL(IF('Bank Schedule'!$K$2:$K$825="Vacant", ROW('Bank Schedule'!$K$2:$K$825)), ROW(6:6))), "") | T9: {=IFERROR(INDEX('Bank Schedule'!T:T, SMALL(IF('Bank Schedule'!$K$2:$K$825="Vacant", ROW('Bank Schedule'!$K$2:$K$825)), ROW(6:6))), "")} -> 143000 | U9: {=IFERROR(INDEX('Bank Schedule'!U:U, SMALL(IF('Bank Schedule'!$K$2:$K$825="Vacant", ROW('Bank Schedule'!$K$2:$K$825)), ROW(6:6))), "")} -> 143000 | V9: {=IFERROR(INDEX('Bank Schedule'!V:V, SMALL(IF('Bank Schedule'!$K$2:$K$825="Vacant", ROW('Bank Schedule'!$K$2:$K$825)), ROW(6:6))), "")} -> 145000 | W9: {=IFERROR(INDEX('Bank Schedule'!W:W, SMALL(IF('Bank Schedule'!$K$2:$K$825="Vacant", ROW('Bank Schedule'!$K$2:$K$825)), ROW(6:6))), "")} -> 145000 | X9: {=IFERROR(INDEX('Bank Schedule'!X:X, SMALL(IF('Bank Schedule'!$K$2:$K$825="Vacant", ROW('Bank Schedule'!$K$2:$K$825)), ROW(6:6))), "")} -> 64.876957 | Y9: {=IFERROR(INDEX('Bank Schedule'!Y:Y, SMALL(IF('Bank Schedule'!$K$2:$K$825="Vacant", ROW('Bank Schedule'!$K$2:$K$825)), ROW(6:6))), "")} -> 0.013986014 | Z9: {=IFERROR(INDEX('Bank Schedule'!Z:Z, SMALL(IF('Bank Schedule'!$K$2:$K$825="Vacant", ROW('Bank Schedule'!$K$2:$K$825)), ROW(6:6))), "")} -> D | AA9: =IFERROR(INDEX('Bank Schedule'!AA:AA, SMALL(IF('Bank Schedule'!$K$2:$K$825="Vacant", ROW('Bank Schedule'!$K$2:$K$825)), ROW(6:6))), "") | AB9: =IFERROR(INDEX('Bank Schedule'!AB:AB, SMALL(IF('Bank Schedule'!$K$2:$K$825="Vacant", ROW('Bank Schedule'!$K$2:$K$825)), ROW(6:6))), "") | AC9: {=IFERROR(INDEX('Bank Schedule'!AC:AC, SMALL(IF('Bank Schedule'!$K$2:$K$825="Vacant", ROW('Bank Schedule'!$K$2:$K$825)), ROW(6:6))), "")} -> No | AD9: {=IFERROR(INDEX('Bank Schedule'!AD:AD, SMALL(IF('Bank Schedule'!$K$2:$K$825="Vacant", ROW('Bank Schedule'!$K$2:$K$825)), ROW(6:6))), "")} -> LEM Marketing. | AE9: =IFERROR(INDEX('Bank Schedule'!AE:AE, SMALL(IF('Bank Schedule'!$K$2:$K$825="Vacant", ROW('Bank Schedule'!$K$2:$K$825)), ROW(6:6))), "") | AF9: {=IFERROR(INDEX('Bank Schedule'!AF:AF, SMALL(IF('Bank Schedule'!$K$2:$K$825="Vacant", ROW('Bank Schedule'!$K$2:$K$825)), ROW(6:6))), "")} -> 15 | AG9: {=IFERROR(INDEX('Bank Schedule'!AG:AG, SMALL(IF('Bank Schedule'!$K$2:$K$825="Vacant", ROW('Bank Schedule'!$K$2:$K$825)), ROW(6:6))), "")} -> 15 | AH9: =IFERROR(INDEX('Bank Schedule'!AH:AH, SMALL(IF('Bank Schedule'!$K$2:$K$825="Vacant", ROW('Bank Schedule'!$K$2:$K$825)), ROW(6:6))), "")
A10: =IFERROR(INDEX('Bank Schedule'!A:A, SMALL(IF('Bank Schedule'!$K$2:$K$825="Vacant", ROW('Bank Schedule'!$K$2:$K$825)), ROW(7:7))), "") | B10: {=IFERROR(INDEX('Bank Schedule'!B:B, SMALL(IF('Bank Schedule'!$K$2:$K$825="Vacant", ROW('Bank Schedule'!$K$2:$K$825)), ROW(7:7))), "")} -> SH | C10: {=IFERROR(INDEX('Bank Schedule'!C:C, SMALL(IF('Bank Schedule'!$K$2:$K$825="Vacant", ROW('Bank Schedule'!$K$2:$K$825)), ROW(7:7))), "")} -> MEL | D10: {=IFERROR(INDEX('Bank Schedule'!D:D, SMALL(IF('Bank Schedule'!$K$2:$K$825="Vacant", ROW('Bank Schedule'!$K$2:$K$825)), ROW(7:7))), "")} -> 550070 | E10: {=IFERROR(INDEX('Bank Schedule'!E:E, SMALL(IF('Bank Schedule'!$K$2:$K$825="Vacant", ROW('Bank Schedule'!$K$2:$K$825)), ROW(7:7))), "")} -> Windsor House, 40-41 Great Castle Street | F10: {=IFERROR(INDEX('Bank Schedule'!F:F, SMALL(IF('Bank Schedule'!$K$2:$K$825="Vacant", ROW('Bank Schedule'!$K$2:$K$825)), ROW(7:7))), "")} -> Fourth Floor | G10: {=IFERROR(INDEX('Bank Schedule'!G:G, SMALL(IF('Bank Schedule'!$K$2:$K$825="Vacant", ROW('Bank Schedule'!$K$2:$K$825)), ROW(7:7))), "")} -> Office | H10: {=IFERROR(INDEX('Bank Schedule'!H:H, SMALL(IF('Bank Schedule'!$K$2:$K$825="Vacant", ROW('Bank Schedule'!$K$2:$K$825)), ROW(7:7))), "")} -> 400 | I10: {=IFERROR(INDEX('Bank Schedule'!I:I, SMALL(IF('Bank Schedule'!$K$2:$K$825="Vacant", ROW('Bank Schedule'!$K$2:$K$825)), ROW(7:7))), "")} -> 400 | J10: {=IFERROR(INDEX('Bank Schedule'!J:J, SMALL(IF('Bank Schedule'!$K$2:$K$825="Vacant", ROW('Bank Schedule'!$K$2:$K$825)), ROW(7:7))), "")} -> 500 | K10: {=IFERROR(INDEX('Bank Schedule'!K:K, SMALL(IF('Bank Schedule'!$K$2:$K$825="Vacant", ROW('Bank Schedule'!$K$2:$K$825)), ROW(7:7))), "")} -> Vacant | L10: =IFERROR(INDEX('Bank Schedule'!L:L, SMALL(IF('Bank Schedule'!$K$2:$K$825="Vacant", ROW('Bank Schedule'!$K$2:$K$825)), ROW(7:7))), "") | M10: =IFERROR(INDEX('Bank Schedule'!M:M, SMALL(IF('Bank Schedule'!$K$2:$K$825="Vacant", ROW('Bank Schedule'!$K$2:$K$825)), ROW(7:7))), "") | N10: {=IFERROR(INDEX('Bank Schedule'!N:N, SMALL(IF('Bank Schedule'!$K$2:$K$825="Vacant", ROW('Bank Schedule'!$K$2:$K$825)), ROW(7:7))), "")} -> 44168 | O10: =IFERROR(INDEX('Bank Schedule'!O:O, SMALL(IF('Bank Schedule'!$K$2:$K$825="Vacant", ROW('Bank Schedule'!$K$2:$K$825)), ROW(7:7))), "") | P10: =IFERROR(INDEX('Bank Schedule'!P:P, SMALL(IF('Bank Schedule'!$K$2:$K$825="Vacant", ROW('Bank Schedule'!$K$2:$K$825)), ROW(7:7))), "") | Q10: {=IFERROR(INDEX('Bank Schedule'!Q:Q, SMALL(IF('Bank Schedule'!$K$2:$K$825="Vacant", ROW('Bank Schedule'!$K$2:$K$825)), ROW(7:7))), "")} -> 0 | R10: {=IFERROR(INDEX('Bank Schedule'!R:R, SMALL(IF('Bank Schedule'!$K$2:$K$825="Vacant", ROW('Bank Schedule'!$K$2:$K$825)), ROW(7:7))), "")} -> 0 | S10: =IFERROR(INDEX('Bank Schedule'!S:S, SMALL(IF('Bank Schedule'!$K$2:$K$825="Vacant", ROW('Bank Schedule'!$K$2:$K$825)), ROW(7:7))), "") | T10: {=IFERROR(INDEX('Bank Schedule'!T:T, SMALL(IF('Bank Schedule'!$K$2:$K$825="Vacant", ROW('Bank Schedule'!$K$2:$K$825)), ROW(7:7))), "")} -> 21600 | U10: {=IFERROR(INDEX('Bank Schedule'!U:U, SMALL(IF('Bank Schedule'!$K$2:$K$825="Vacant", ROW('Bank Schedule'!$K$2:$K$825)), ROW(7:7))), "")} -> 21600 | V10: {=IFERROR(INDEX('Bank Schedule'!V:V, SMALL(IF('Bank Schedule'!$K$2:$K$825="Vacant", ROW('Bank Schedule'!$K$2:$K$825)), ROW(7:7))), "")} -> 22000 | W10: {=IFERROR(INDEX('Bank Schedule'!W:W, SMALL(IF('Bank Schedule'!$K$2:$K$825="Vacant", ROW('Bank Schedule'!$K$2:$K$825)), ROW(7:7))), "")} -> 22000 | X10: {=IFERROR(INDEX('Bank Schedule'!X:X, SMALL(IF('Bank Schedule'!$K$2:$K$825="Vacant", ROW('Bank Schedule'!$K$2:$K$825)), ROW(7:7))), "")} -> 55 | Y10: {=IFERROR(INDEX('Bank Schedule'!Y:Y, SMALL(IF('Bank Schedule'!$K$2:$K$825="Vacant", ROW('Bank Schedule'!$K$2:$K$825)), ROW(7:7))), "")} -> 0.018518519 | Z10: {=IFERROR(INDEX('Bank Schedule'!Z:Z, SMALL(IF('Bank Schedule'!$K$2:$K$825="Vacant", ROW('Bank Schedule'!$K$2:$K$825)), ROW(7:7))), "")} -> D | AA10: =IFERROR(INDEX('Bank Schedule'!AA:AA, SMALL(IF('Bank Schedule'!$K$2:$K$825="Vacant", ROW('Bank Schedule'!$K$2:$K$825)), ROW(7:7))), "") | AB10: =IFERROR(INDEX('Bank Schedule'!AB:AB, SMALL(IF('Bank Schedule'!$K$2:$K$825="Vacant", ROW('Bank Schedule'!$K$2:$K$825)), ROW(7:7))), "") | AC10: {=IFERROR(INDEX('Bank Schedule'!AC:AC, SMALL(IF('Bank Schedule'!$K$2:$K$825="Vacant", ROW('Bank Schedule'!$K$2:$K$825)), ROW(7:7))), "")} -> No | AD10: {=IFERROR(INDEX('Bank Schedule'!AD:AD, SMALL(IF('Bank Schedule'!$K$2:$K$825="Vacant", ROW('Bank Schedule'!$K$2:$K$825)), ROW(7:7))), "")} -> To be refurbished. | AE10: =IFERROR(INDEX('Bank Schedule'!AE:AE, SMALL(IF('Bank Schedule'!$K$2:$K$825="Vacant", ROW('Bank Schedule'!$K$2:$K$825)), ROW(7:7))), "") | AF10: =IFERROR(INDEX('Bank Schedule'!AF:AF, SMALL(IF('Bank Schedule'!$K$2:$K$825="Vacant", ROW('Bank Schedule'!$K$2:$K$825)), ROW(7:7))), "") | AG10: =IFERROR(INDEX('Bank Schedule'!AG:AG, SMALL(IF('Bank Schedule'!$K$2:$K$825="Vacant", ROW('Bank Schedule'!$K$2:$K$825)), ROW(7:7))), "") | AH10: =IFERROR(INDEX('Bank Schedule'!AH:AH, SMALL(IF('Bank Schedule'!$K$2:$K$825="Vacant", ROW('Bank Schedule'!$K$2:$K$825)), ROW(7:7))), "")
A11: =IFERROR(INDEX('Bank Schedule'!A:A, SMALL(IF('Bank Schedule'!$K$2:$K$825="Vacant", ROW('Bank Schedule'!$K$2:$K$825)), ROW(8:8))), "") | B11: {=IFERROR(INDEX('Bank Schedule'!B:B, SMALL(IF('Bank Schedule'!$K$2:$K$825="Vacant", ROW('Bank Schedule'!$K$2:$K$825)), ROW(8:8))), "")} -> SH | C11: {=IFERROR(INDEX('Bank Schedule'!C:C, SMALL(IF('Bank Schedule'!$K$2:$K$825="Vacant", ROW('Bank Schedule'!$K$2:$K$825)), ROW(8:8))), "")} -> MEL | D11: {=IFERROR(INDEX('Bank Schedule'!D:D, SMALL(IF('Bank Schedule'!$K$2:$K$825="Vacant", ROW('Bank Schedule'!$K$2:$K$825)), ROW(8:8))), "")} -> 550470 | E11: {=IFERROR(INDEX('Bank Schedule'!E:E, SMALL(IF('Bank Schedule'!$K$2:$K$825="Vacant", ROW('Bank Schedule'!$K$2:$K$825)), ROW(8:8))), "")} -> Portland House, 4 Great Portland Street | F11: {=IFERROR(INDEX('Bank Schedule'!F:F, SMALL(IF('Bank Schedule'!$K$2:$K$825="Vacant", ROW('Bank Schedule'!$K$2:$K$825)), ROW(8:8))), "")} -> Second Floor (West) | G11: {=IFERROR(INDEX('Bank Schedule'!G:G, SMALL(IF('Bank Schedule'!$K$2:$K$825="Vacant", ROW('Bank Schedule'!$K$2:$K$825)), ROW(8:8))), "")} -> Office | H11: {=IFERROR(INDEX('Bank Schedule'!H:H, SMALL(IF('Bank Schedule'!$K$2:$K$825="Vacant", ROW('Bank Schedule'!$K$2:$K$825)), ROW(8:8))), "")} -> 1796 | I11: {=IFERROR(INDEX('Bank Schedule'!I:I, SMALL(IF('Bank Schedule'!$K$2:$K$825="Vacant", ROW('Bank Schedule'!$K$2:$K$825)), ROW(8:8))), "")} -> 1796 | J11: {=IFERROR(INDEX('Bank Schedule'!J:J, SMALL(IF('Bank Schedule'!$K$2:$K$825="Vacant", ROW('Bank Schedule'!$K$2:$K$825)), ROW(8:8))), "")} -> 1750 | K11: {=IFERROR(INDEX('Bank Schedule'!K:K, SMALL(IF('Bank Schedule'!$K$2:$K$825="Vacant", ROW('Bank Schedule'!$K$2:$K$825)), ROW(8:8))), "")} -> Vacant | L11: =IFERROR(INDEX('Bank Schedule'!L:L, SMALL(IF('Bank Schedule'!$K$2:$K$825="Vacant", ROW('Bank Schedule'!$K$2:$K$825)), ROW(8:8))), "") | M11: =IFERROR(INDEX('Bank Schedule'!M:M, SMALL(IF('Bank Schedule'!$K$2:$K$825="Vacant", ROW('Bank Schedule'!$K$2:$K$825)), ROW(8:8))), "") | N11: {=IFERROR(INDEX('Bank Schedule'!N:N, SMALL(IF('Bank Schedule'!$K$2:$K$825="Vacant", ROW('Bank Schedule'!$K$2:$K$825)), ROW(8:8))), "")} -> 45051 | O11: =IFERROR(INDEX('Bank Schedule'!O:O, SMALL(IF('Bank Schedule'!$K$2:$K$825="Vacant", ROW('Bank Schedule'!$K$2:$K$825)), ROW(8:8))), "") | P11: =IFERROR(INDEX('Bank Schedule'!P:P, SMALL(IF('Bank Schedule'!$K$2:$K$825="Vacant", ROW('Bank Schedule'!$K$2:$K$825)), ROW(8:8))), "") | Q11: {=IFERROR(INDEX('Bank Schedule'!Q:Q, SMALL(IF('Bank Schedule'!$K$2:$K$825="Vacant", ROW('Bank Schedule'!$K$2:$K$825)), ROW(8:8))), "")} -> 0 | R11: {=IFERROR(INDEX('Bank Schedule'!R:R, SMALL(IF('Bank Schedule'!$K$2:$K$825="Vacant", ROW('Bank Schedule'!$K$2:$K$825)), ROW(8:8))), "")} -> 0 | S11: =IFERROR(INDEX('Bank Schedule'!S:S, SMALL(IF('Bank Schedule'!$K$2:$K$825="Vacant", ROW('Bank Schedule'!$K$2:$K$825)), ROW(8:8))), "") | T11: {=IFERROR(INDEX('Bank Schedule'!T:T, SMALL(IF('Bank Schedule'!$K$2:$K$825="Vacant", ROW('Bank Schedule'!$K$2:$K$825)), ROW(8:8))), "")} -> 87300 | U11: {=IFERROR(INDEX('Bank Schedule'!U:U, SMALL(IF('Bank Schedule'!$K$2:$K$825="Vacant", ROW('Bank Schedule'!$K$2:$K$825)), ROW(8:8))), "")} -> 87300 | V11: {=IFERROR(INDEX('Bank Schedule'!V:V, SMALL(IF('Bank Schedule'!$K$2:$K$825="Vacant", ROW('Bank Schedule'!$K$2:$K$825)), ROW(8:8))), "")} -> 121240 | W11: {=IFERROR(INDEX('Bank Schedule'!W:W, SMALL(IF('Bank Schedule'!$K$2:$K$825="Vacant", ROW('Bank Schedule'!$K$2:$K$825)), ROW(8:8))), "")} -> 121240 | X11: {=IFERROR(INDEX('Bank Schedule'!X:X, SMALL(IF('Bank Schedule'!$K$2:$K$825="Vacant", ROW('Bank Schedule'!$K$2:$K$825)), ROW(8:8))), "")} -> 67.505568 | Y11: {=IFERROR(INDEX('Bank Schedule'!Y:Y, SMALL(IF('Bank Schedule'!$K$2:$K$825="Vacant", ROW('Bank Schedule'!$K$2:$K$825)), ROW(8:8))), "")} -> 0.38877434 | Z11: {=IFERROR(INDEX('Bank Schedule'!Z:Z, SMALL(IF('Bank Schedule'!$K$2:$K$825="Vacant", ROW('Bank Schedule'!$K$2:$K$825)), ROW(8:8))), "")} -> B | AA11: =IFERROR(INDEX('Bank Schedule'!AA:AA, SMALL(IF('Bank Schedule'!$K$2:$K$825="Vacant", ROW('Bank Schedule'!$K$2:$K$825)), ROW(8:8))), "") | AB11: =IFERROR(INDEX('Bank Schedule'!AB:AB, SMALL(IF('Bank Schedule'!$K$2:$K$825="Vacant", ROW('Bank Schedule'!$K$2:$K$825)), ROW(8:8))), "") | AC11: {=IFERROR(INDEX('Bank Schedule'!AC:AC, SMALL(IF('Bank Schedule'!$K$2:$K$825="Vacant", ROW('Bank Schedule'!$K$2:$K$825)), ROW(8:8))), "")} -> No | AD11: {=IFERROR(INDEX('Bank Schedule'!AD:AD, SMALL(IF('Bank Schedule'!$K$2:$K$825="Vacant", ROW('Bank Schedule'!$K$2:$K$825)), ROW(8:8))), "")} -> LEM marketing. | AE11: {=IFERROR(INDEX('Bank Schedule'!AE:AE, SMALL(IF('Bank Schedule'!$K$2:$K$825="Vacant", ROW('Bank Schedule'!$K$2:$K$825)), ROW(8:8))), "")} -> 72.5 | AF11: {=IFERROR(INDEX('Bank Schedule'!AF:AF, SMALL(IF('Bank Schedule'!$K$2:$K$825="Vacant", ROW('Bank Schedule'!$K$2:$K$825)), ROW(8:8))), "")} -> 3 | AG11: {=IFERROR(INDEX('Bank Schedule'!AG:AG, SMALL(IF('Bank Schedule'!$K$2:$K$825="Vacant", ROW('Bank Schedule'!$K$2:$K$825)), ROW(8:8))), "")} -> 13 | AH11: {=IFERROR(INDEX('Bank Schedule'!AH:AH, SMALL(IF('Bank Schedule'!$K$2:$K$825="Vacant", ROW('Bank Schedule'!$K$2:$K$825)), ROW(8:8))), "")} -> LEM/LDG
A12: =IFERROR(INDEX('Bank Schedule'!A:A, SMALL(IF('Bank Schedule'!$K$2:$K$825="Vacant", ROW('Bank Schedule'!$K$2:$K$825)), ROW(9:9))), "") | B12: {=IFERROR(INDEX('Bank Schedule'!B:B, SMALL(IF('Bank Schedule'!$K$2:$K$825="Vacant", ROW('Bank Schedule'!$K$2:$K$825)), ROW(9:9))), "")} -> SH | C12: {=IFERROR(INDEX('Bank Schedule'!C:C, SMALL(IF('Bank Schedule'!$K$2:$K$825="Vacant", ROW('Bank Schedule'!$K$2:$K$825)), ROW(9:9))), "")} -> MEL | D12: {=IFERROR(INDEX('Bank Schedule'!D:D, SMALL(IF('Bank Schedule'!$K$2:$K$825="Vacant", ROW('Bank Schedule'!$K$2:$K$825)), ROW(9:9))), "")} -> 550470 | E12: {=IFERROR(INDEX('Bank Schedule'!E:E, SMALL(IF('Bank Schedule'!$K$2:$K$825="Vacant", ROW('Bank Schedule'!$K$2:$K$825)), ROW(9:9))), "")} -> Portland House, 4 Great Portland Street | F12: {=IFERROR(INDEX('Bank Schedule'!F:F, SMALL(IF('Bank Schedule'!$K$2:$K$825="Vacant", ROW('Bank Schedule'!$K$2:$K$825)), ROW(9:9))), "")} -> Sixth Floor (East) | G12: {=IFERROR(INDEX('Bank Schedule'!G:G, SMALL(IF('Bank Schedule'!$K$2:$K$825="Vacant", ROW('Bank Schedule'!$K$2:$K$825)), ROW(9:9))), "")} -> Office | H12: {=IFERROR(INDEX('Bank Schedule'!H:H, SMALL(IF('Bank Schedule'!$K$2:$K$825="Vacant", ROW('Bank Schedule'!$K$2:$K$825)), ROW(9:9))), "")} -> 859 | I12: {=IFERROR(INDEX('Bank Schedule'!I:I, SMALL(IF('Bank Schedule'!$K$2:$K$825="Vacant", ROW('Bank Schedule'!$K$2:$K$825)), ROW(9:9))), "")} -> 859 | J12: {=IFERROR(INDEX('Bank Schedule'!J:J, SMALL(IF('Bank Schedule'!$K$2:$K$825="Vacant", ROW('Bank Schedule'!$K$2:$K$825)), ROW(9:9))), "")} -> 1000 | K12: {=IFERROR(INDEX('Bank Schedule'!K:K, SMALL(IF('Bank Schedule'!$K$2:$K$825="Vacant", ROW('Bank Schedule'!$K$2:$K$825)), ROW(9:9))), "")} -> Vacant | L12: =IFERROR(INDEX('Bank Schedule'!L:L, SMALL(IF('Bank Schedule'!$K$2:$K$825="Vacant", ROW('Bank Schedule'!$K$2:$K$825)), ROW(9:9))), "") | M12: =IFERROR(INDEX('Bank Schedule'!M:M, SMALL(IF('Bank Schedule'!$K$2:$K$825="Vacant", ROW('Bank Schedule'!$K$2:$K$825)), ROW(9:9))), "") | N12: {=IFERROR(INDEX('Bank Schedule'!N:N, SMALL(IF('Bank Schedule'!$K$2:$K$825="Vacant", ROW('Bank Schedule'!$K$2:$K$825)), ROW(9:9))), "")} -> 44609 | O12: =IFERROR(INDEX('Bank Schedule'!O:O, SMALL(IF('Bank Schedule'!$K$2:$K$825="Vacant", ROW('Bank Schedule'!$K$2:$K$825)), ROW(9:9))), "") | P12: =IFERROR(INDEX('Bank Schedule'!P:P, SMALL(IF('Bank Schedule'!$K$2:$K$825="Vacant", ROW('Bank Schedule'!$K$2:$K$825)), ROW(9:9))), "") | Q12: {=IFERROR(INDEX('Bank Schedule'!Q:Q, SMALL(IF('Bank Schedule'!$K$2:$K$825="Vacant", ROW('Bank Schedule'!$K$2:$K$825)), ROW(9:9))), "")} -> 0 | R12: {=IFERROR(INDEX('Bank Schedule'!R:R, SMALL(IF('Bank Schedule'!$K$2:$K$825="Vacant", ROW('Bank Schedule'!$K$2:$K$825)), ROW(9:9))), "")} -> 0 | S12: =IFERROR(INDEX('Bank Schedule'!S:S, SMALL(IF('Bank Schedule'!$K$2:$K$825="Vacant", ROW('Bank Schedule'!$K$2:$K$825)), ROW(9:9))), "") | T12: {=IFERROR(INDEX('Bank Schedule'!T:T, SMALL(IF('Bank Schedule'!$K$2:$K$825="Vacant", ROW('Bank Schedule'!$K$2:$K$825)), ROW(9:9))), "")} -> 65750 | U12: {=IFERROR(INDEX('Bank Schedule'!U:U, SMALL(IF('Bank Schedule'!$K$2:$K$825="Vacant", ROW('Bank Schedule'!$K$2:$K$825)), ROW(9:9))), "")} -> 65750 | V12: {=IFERROR(INDEX('Bank Schedule'!V:V, SMALL(IF('Bank Schedule'!$K$2:$K$825="Vacant", ROW('Bank Schedule'!$K$2:$K$825)), ROW(9:9))), "")} -> 53700 | W12: {=IFERROR(INDEX('Bank Schedule'!W:W, SMALL(IF('Bank Schedule'!$K$2:$K$825="Vacant", ROW('Bank Schedule'!$K$2:$K$825)), ROW(9:9))), "")} -> 53700 | X12: {=IFERROR(INDEX('Bank Schedule'!X:X, SMALL(IF('Bank Schedule'!$K$2:$K$825="Vacant", ROW('Bank Schedule'!$K$2:$K$825)), ROW(9:9))), "")} -> 62.514552 | Y12: {=IFERROR(INDEX('Bank Schedule'!Y:Y, SMALL(IF('Bank Schedule'!$K$2:$K$825="Vacant", ROW('Bank Schedule'!$K$2:$K$825)), ROW(9:9))), "")} -> -0.18326996 | Z12: {=IFERROR(INDEX('Bank Schedule'!Z:Z, SMALL(IF('Bank Schedule'!$K$2:$K$825="Vacant", ROW('Bank Schedule'!$K$2:$K$825)), ROW(9:9))), "")} -> D | AA12: =IFERROR(INDEX('Bank Schedule'!AA:AA, SMALL(IF('Bank Schedule'!$K$2:$K$825="Vacant", ROW('Bank Schedule'!$K$2:$K$825)), ROW(9:9))), "") | AB12: =IFERROR(INDEX('Bank Schedule'!AB:AB, SMALL(IF('Bank Schedule'!$K$2:$K$825="Vacant", ROW('Bank Schedule'!$K$2:$K$825)), ROW(9:9))), "") | AC12: {=IFERROR(INDEX('Bank Schedule'!AC:AC, SMALL(IF('Bank Schedule'!$K$2:$K$825="Vacant", ROW('Bank Schedule'!$K$2:$K$825)), ROW(9:9))), "")} -> No | AD12: {=IFERROR(INDEX('Bank Schedule'!AD:AD, SMALL(IF('Bank Schedule'!$K$2:$K$825="Vacant", ROW('Bank Schedule'!$K$2:$K$825)), ROW(9:9))), "")} -> LEM marketing. | AE12: {=IFERROR(INDEX('Bank Schedule'!AE:AE, SMALL(IF('Bank Schedule'!$K$2:$K$825="Vacant", ROW('Bank Schedule'!$K$2:$K$825)), ROW(9:9))), "")} -> 63 | AF12: =IFERROR(INDEX('Bank Schedule'!AF:AF, SMALL(IF('Bank Schedule'!$K$2:$K$825="Vacant", ROW('Bank Schedule'!$K$2:$K$825)), ROW(9:9))), "") | AG12: {=IFERROR(INDEX('Bank Schedule'!AG:AG, SMALL(IF('Bank Schedule'!$K$2:$K$825="Vacant", ROW('Bank Schedule'!$K$2:$K$825)), ROW(9:9))), "")} -> 2 | AH12: =IFERROR(INDEX('Bank Schedule'!AH:AH, SMALL(IF('Bank Schedule'!$K$2:$K$825="Vacant", ROW('Bank Schedule'!$K$2:$K$825)), ROW(9:9))), "")
